Workbook
Name analysis_start: #REF!
Name market_rent: #REF!

Sheet Summary
B2: Land Residual Valuation
B3: Required Return | D3: 0.1
B4: Efficiency | D4: 0.7
B5: Vacancy | D5: 0.05
B6: Maximum Land Cost | D6: 0.01
B8: Market Rent | C8: / rsf | D8: 11
B9: Effective Rent | C9: / rsf | D9: =D8*(1-D5) -> 10.45
B10: Operating Costs | C10: / gsf | D10: =SUM('[2]Torrance Inputs'!H3:H6)/'[2]Torrance Inputs'!D9 -> 0.37501655
B11: Soft Costs | C11: / gsf | D11: =('[2]Torrance Inputs'!I36+'[2]Torrance Inputs'!I40)/'[2]Torrance Inputs'!D9 -> 5.0971356
B12: Hard Costs | C12: / gsf | D12: =SUM('[2]Torrance Inputs'!I37:I39)/'[2]Torrance Inputs'!D9 -> 23.677017
B14: Rental Revenue | C14: / gsf | D14: =D9*(D4) -> 7.315
B15: NOI | C15: / gsf | D15: =D14-D10 -> 6.9399835
B17: Maximum Land Cost | C17: / gsf | D17: =(D15-(SUM(D11:D12)*$D$3))/D3 -> 40.625682
B18: Maximum To Pay | C18: $ | D18: =D17*'[2]Torrance Inputs'!D9 -> 24707919

Sheet Rent Table
A1: Street Address | B1: City | C1: State | D1: Zip Code | E1: Market | F1: Sector | G1: Date As Of | H1: Zip Code Grade | I1: Size | J1: Size Type | K1: Effective Rent* ($/Size Type) | L1: Avg. Transaction Size | M1: Avg. Lease Terms (Months) | N1: Avg. Work Value ($/Size Type) | O1: Avg. Free Months | P1: Floors | Q1: Year Built | R1: Year Renovated | S1: Size (SF)
A2: 1000 Francisco Street | B2: Torrance | C2: CA | D2: 90502 | E2: Los Angeles | F2: Industrial | G2: 45566 | H2: A++ | I2: 298000 | J2: SF | K2: 25.5206 | L2: 298000 | M2: 63 | N2: 2.5 | O2: 3 | P2: 1 | Q2: 1975 | R2: - | S2: {=_xlfn.IFS(AND('Rent Table'!$I2>0,'Rent Table'!$I2<=50000),"0-50,000", AND('Rent Table'!$I2 > 50000, 'Rent Table'!$I2 <= 150000), "50,001-150,000", AND('Rent Table'!$I2 > 150000, 'Rent Table'!$I2 <= 250000), "150,001-250,000", AND('Rent Table'!$I2 > 250000, 'Rent Table'!$I2 <= 350000), "250,001-350,000", AND('Rent Table'!$I2 > 350000, 'Rent Table'!$I2 <= 450000), "350,001-450,000", AND('Rent Table'!$I2 > 450000, 'Rent Table'!$I2 <= 600000), "450,001-600,000", AND('Rent Table'!$I2 > 600000, 'Rent Table'!$I2 <= 750000), "600,001-750,000",'Rent Table'!$I2 > 750000, "750,000+", TRUE, "Undefined" )} -> 250,001-350,000
A3: 1000 West 190th Street | B3: Torrance | C3: CA | D3: 90502 | E3: Los Angeles | F3: Industrial | G3: 45566 | H3: A++ | I3: 129556 | J3: SF | K3: 22.0341 | L3: 129256 | M3: 120 | N3: - | O3: - | P3: 1 | Q3: 2000 | R3: - | S3: {=_xlfn.IFS(AND('Rent Table'!$I3>0,'Rent Table'!$I3<=50000),"0-50,000", AND('Rent Table'!$I3 > 50000, 'Rent Table'!$I3 <= 150000), "50,001-150,000", AND('Rent Table'!$I3 > 150000, 'Rent Table'!$I3 <= 250000), "150,001-250,000", AND('Rent Table'!$I3 > 250000, 'Rent Table'!$I3 <= 350000), "250,001-350,000", AND('Rent Table'!$I3 > 350000, 'Rent Table'!$I3 <= 450000), "350,001-450,000", AND('Rent Table'!$I3 > 450000, 'Rent Table'!$I3 <= 600000), "450,001-600,000", AND('Rent Table'!$I3 > 600000, 'Rent Table'!$I3 <= 750000), "600,001-750,000",'Rent Table'!$I3 > 750000, "750,000+", TRUE, "Undefined" )} -> 50,001-150,000
A4: 1001 Knox Street | B4: Torrance | C4: CA | D4: 90502 | E4: Los Angeles | F4: Industrial | G4: 45566 | H4: A++ | I4: 49112 | J4: SF | K4: 30.2333 | L4: 49112 | M4: 123 | N4: 20 | O4: 3 | P4: 1 | Q4: 1981 | R4: - | S4: {=_xlfn.IFS(AND('Rent Table'!$I4>0,'Rent Table'!$I4<=50000),"0-50,000", AND('Rent Table'!$I4 > 50000, 'Rent Table'!$I4 <= 150000), "50,001-150,000", AND('Rent Table'!$I4 > 150000, 'Rent Table'!$I4 <= 250000), "150,001-250,000", AND('Rent Table'!$I4 > 250000, 'Rent Table'!$I4 <= 350000), "250,001-350,000", AND('Rent Table'!$I4 > 350000, 'Rent Table'!$I4 <= 450000), "350,001-450,000", AND('Rent Table'!$I4 > 450000, 'Rent Table'!$I4 <= 600000), "450,001-600,000", AND('Rent Table'!$I4 > 600000, 'Rent Table'!$I4 <= 750000), "600,001-750,000",'Rent Table'!$I4 > 750000, "750,000+", TRUE, "Undefined" )} -> 0-50,000
A5: 1011 Francisco Street | B5: Torrance | C5: CA | D5: 90502 | E5: Los Angeles | F5: Industrial | G5: 45566 | H5: A++ | I5: 45550 | J5: SF | K5: 18.1314 | L5: 45550 | M5: 85 | N5: - | O5: 1 | P5: 1 | Q5: 1979 | R5: - | S5: {=_xlfn.IFS(AND('Rent Table'!$I5>0,'Rent Table'!$I5<=50000),"0-50,000", AND('Rent Table'!$I5 > 50000, 'Rent Table'!$I5 <= 150000), "50,001-150,000", AND('Rent Table'!$I5 > 150000, 'Rent Table'!$I5 <= 250000), "150,001-250,000", AND('Rent Table'!$I5 > 250000, 'Rent Table'!$I5 <= 350000), "250,001-350,000", AND('Rent Table'!$I5 > 350000, 'Rent Table'!$I5 <= 450000), "350,001-450,000", AND('Rent Table'!$I5 > 450000, 'Rent Table'!$I5 <= 600000), "450,001-600,000", AND('Rent Table'!$I5 > 600000, 'Rent Table'!$I5 <= 750000), "600,001-750,000",'Rent Table'!$I5 > 750000, "750,000+", TRUE, "Undefined" )} -> 0-50,000
A6: 1024 East Del Amo Boulevard | B6: Carson | C6: CA | D6: 90746 | E6: Los Angeles | F6: Industrial | G6: 45566 | H6: A+ | I6: 36580 | J6: SF | K6: 18.473 | L6: 18301 | M6: 62 | N6: - | O6: - | P6: 1 | Q6: 1977 | R6: - | S6: {=_xlfn.IFS(AND('Rent Table'!$I6>0,'Rent Table'!$I6<=50000),"0-50,000", AND('Rent Table'!$I6 > 50000, 'Rent Table'!$I6 <= 150000), "50,001-150,000", AND('Rent Table'!$I6 > 150000, 'Rent Table'!$I6 <= 250000), "150,001-250,000", AND('Rent Table'!$I6 > 250000, 'Rent Table'!$I6 <= 350000), "250,001-350,000", AND('Rent Table'!$I6 > 350000, 'Rent Table'!$I6 <= 450000), "350,001-450,000", AND('Rent Table'!$I6 > 450000, 'Rent Table'!$I6 <= 600000), "450,001-600,000", AND('Rent Table'!$I6 > 600000, 'Rent Table'!$I6 <= 750000), "600,001-750,000",'Rent Table'!$I6 > 750000, "750,000+", TRUE, "Undefined" )} -> 0-50,000
A7: 1048 East Burgrove Street | B7: Carson | C7: CA | D7: 90746 | E7: Los Angeles | F7: Industrial | G7: 45566 | H7: A+ | I7: 75194 | J7: SF | K7: 19.1764 | L7: 53474 | M7: 36 | N7: - | O7: - | P7: 1 | Q7: 1972 | R7: 1973 | S7: {=_xlfn.IFS(AND('Rent Table'!$I7>0,'Rent Table'!$I7<=50000),"0-50,000", AND('Rent Table'!$I7 > 50000, 'Rent Table'!$I7 <= 150000), "50,001-150,000", AND('Rent Table'!$I7 > 150000, 'Rent Table'!$I7 <= 250000), "150,001-250,000", AND('Rent Table'!$I7 > 250000, 'Rent Table'!$I7 <= 350000), "250,001-350,000", AND('Rent Table'!$I7 > 350000, 'Rent Table'!$I7 <= 450000), "350,001-450,000", AND('Rent Table'!$I7 > 450000, 'Rent Table'!$I7 <= 600000), "450,001-600,000", AND('Rent Table'!$I7 > 600000, 'Rent Table'!$I7 <= 750000), "600,001-750,000",'Rent Table'!$I7 > 750000, "750,000+", TRUE, "Undefined" )} -> 50,001-150,000
A8: 1062 East Del Amo Boulevard | B8: Carson | C8: CA | D8: 90746 | E8: Los Angeles | F8: Industrial | G8: 45566 | H8: A+ | I8: 121551 | J8: SF | K8: 14.9052 | L8: 33855 | M8: 61.5 | N8: 0.5 | O8: 2 | P8: 1 | Q8: 1972 | R8: - | S8: {=_xlfn.IFS(AND('Rent Table'!$I8>0,'Rent Table'!$I8<=50000),"0-50,000", AND('Rent Table'!$I8 > 50000, 'Rent Table'!$I8 <= 150000), "50,001-150,000", AND('Rent Table'!$I8 > 150000, 'Rent Table'!$I8 <= 250000), "150,001-250,000", AND('Rent Table'!$I8 > 250000, 'Rent Table'!$I8 <= 350000), "250,001-350,000", AND('Rent Table'!$I8 > 350000, 'Rent Table'!$I8 <= 450000), "350,001-450,000", AND('Rent Table'!$I8 > 450000, 'Rent Table'!$I8 <= 600000), "450,001-600,000", AND('Rent Table'!$I8 > 600000, 'Rent Table'!$I8 <= 750000), "600,001-750,000",'Rent Table'!$I8 > 750000, "750,000+", TRUE, "Undefined" )} -> 50,001-150,000
A9: 1227 Knox Street | B9: Torrance | C9: CA | D9: 90502 | E9: Los Angeles | F9: Industrial | G9: 45566 | H9: A++ | I9: 16000 | J9: SF | K9: 12.102 | L9: 16000 | M9: 36 | N9: - | O9: 1 | P9: 1 | Q9: 1974 | R9: - | S9: {=_xlfn.IFS(AND('Rent Table'!$I9>0,'Rent Table'!$I9<=50000),"0-50,000", AND('Rent Table'!$I9 > 50000, 'Rent Table'!$I9 <= 150000), "50,001-150,000", AND('Rent Table'!$I9 > 150000, 'Rent Table'!$I9 <= 250000), "150,001-250,000", AND('Rent Table'!$I9 > 250000, 'Rent Table'!$I9 <= 350000), "250,001-350,000", AND('Rent Table'!$I9 > 350000, 'Rent Table'!$I9 <= 450000), "350,001-450,000", AND('Rent Table'!$I9 > 450000, 'Rent Table'!$I9 <= 600000), "450,001-600,000", AND('Rent Table'!$I9 > 600000, 'Rent Table'!$I9 <= 750000), "600,001-750,000",'Rent Table'!$I9 > 750000, "750,000+", TRUE, "Undefined" )} -> 0-50,000
A10: 1234 Francisco Street | B10: Torrance | C10: CA | D10: 90502 | E10: Los Angeles | F10: Industrial | G10: 45566 | H10: A++ | I10: 14950 | J10: SF | K10: 15.3947 | L10: 14950 | M10: 61.5 | N10: - | O10: 3 | P10: 1 | Q10: 1964 | R10: - | S10: {=_xlfn.IFS(AND('Rent Table'!$I10>0,'Rent Table'!$I10<=50000),"0-50,000", AND('Rent Table'!$I10 > 50000, 'Rent Table'!$I10 <= 150000), "50,001-150,000", AND('Rent Table'!$I10 > 150000, 'Rent Table'!$I10 <= 250000), "150,001-250,000", AND('Rent Table'!$I10 > 250000, 'Rent Table'!$I10 <= 350000), "250,001-350,000", AND('Rent Table'!$I10 > 350000, 'Rent Table'!$I10 <= 450000), "350,001-450,000", AND('Rent Table'!$I10 > 450000, 'Rent Table'!$I10 <= 600000), "450,001-600,000", AND('Rent Table'!$I10 > 600000, 'Rent Table'!$I10 <= 750000), "600,001-750,000",'Rent Table'!$I10 > 750000, "750,000+", TRUE, "Undefined" )} -> 0-50,000
A11: 1380-1400 Charles Willard Street | B11: Carson | C11: CA | D11: 90746 | E11: Los Angeles | F11: Industrial | G11: 45566 | H11: A+ | I11: 250272 | J11: SF | K11: 20.28085 | L11: 148706 | M11: 36.75 | N11: - | O11: - | P11: 1 | Q11: 2003 | R11: - | S11: {=_xlfn.IFS(AND('Rent Table'!$I11>0,'Rent Table'!$I11<=50000),"0-50,000", AND('Rent Table'!$I11 > 50000, 'Rent Table'!$I11 <= 150000), "50,001-150,000", AND('Rent Table'!$I11 > 150000, 'Rent Table'!$I11 <= 250000), "150,001-250,000", AND('Rent Table'!$I11 > 250000, 'Rent Table'!$I11 <= 350000), "250,001-350,000", AND('Rent Table'!$I11 > 350000, 'Rent Table'!$I11 <= 450000), "350,001-450,000", AND('Rent Table'!$I11 > 450000, 'Rent Table'!$I11 <= 600000), "450,001-600,000", AND('Rent Table'!$I11 > 600000, 'Rent Table'!$I11 <= 750000), "600,001-750,000",'Rent Table'!$I11 > 750000, "750,000+", TRUE, "Undefined" )} -> 250,001-350,000
A12: 1450 Glenn Curtiss Street | B12: Carson | C12: CA | D12: 90746 | E12: Los Angeles | F12: Industrial | G12: 45566 | H12: A+ | I12: 182554 | J12: SF | K12: 19.0129 | L12: 182554 | M12: 60 | N12: 1.1 | O12: - | P12: 1 | Q12: 2005 | R12: - | S12: {=_xlfn.IFS(AND('Rent Table'!$I12>0,'Rent Table'!$I12<=50000),"0-50,000", AND('Rent Table'!$I12 > 50000, 'Rent Table'!$I12 <= 150000), "50,001-150,000", AND('Rent Table'!$I12 > 150000, 'Rent Table'!$I12 <= 250000), "150,001-250,000", AND('Rent Table'!$I12 > 250000, 'Rent Table'!$I12 <= 350000), "250,001-350,000", AND('Rent Table'!$I12 > 350000, 'Rent Table'!$I12 <= 450000), "350,001-450,000", AND('Rent Table'!$I12 > 450000, 'Rent Table'!$I12 <= 600000), "450,001-600,000", AND('Rent Table'!$I12 > 600000, 'Rent Table'!$I12 <= 750000), "600,001-750,000",'Rent Table'!$I12 > 750000, "750,000+", TRUE, "Undefined" )} -> 150,001-250,000
A13: 1450-1480 Charles Willard Street | B13: Carson | C13: CA | D13: 90746 | E13: Los Angeles | F13: Industrial | G13: 45566 | H13: A+ | I13: 81893 | J13: SF | K13: 19.08 | L13: 81532 | M13: 59 | N13: - | O13: 1 | P13: 1 | Q13: 2007 | R13: - | S13: {=_xlfn.IFS(AND('Rent Table'!$I13>0,'Rent Table'!$I13<=50000),"0-50,000", AND('Rent Table'!$I13 > 50000, 'Rent Table'!$I13 <= 150000), "50,001-150,000", AND('Rent Table'!$I13 > 150000, 'Rent Table'!$I13 <= 250000), "150,001-250,000", AND('Rent Table'!$I13 > 250000, 'Rent Table'!$I13 <= 350000), "250,001-350,000", AND('Rent Table'!$I13 > 350000, 'Rent Table'!$I13 <= 450000), "350,001-450,000", AND('Rent Table'!$I13 > 450000, 'Rent Table'!$I13 <= 600000), "450,001-600,000", AND('Rent Table'!$I13 > 600000, 'Rent Table'!$I13 <= 750000), "600,001-750,000",'Rent Table'!$I13 > 750000, "750,000+", TRUE, "Undefined" )} -> 50,001-150,000
A14: 1451 West Knox Street | B14: Torrance | C14: CA | D14: 90501 | E14: Los Angeles | F14: Industrial | G14: 45566 | H14: A++ | I14: 153000 | J14: SF | K14: 27.9826 | L14: 152790 | M14: 65 | N14: 1 | O14: - | P14: 1 | Q14: 2005 | R14: - | S14: {=_xlfn.IFS(AND('Rent Table'!$I14>0,'Rent Table'!$I14<=50000),"0-50,000", AND('Rent Table'!$I14 > 50000, 'Rent Table'!$I14 <= 150000), "50,001-150,000", AND('Rent Table'!$I14 > 150000, 'Rent Table'!$I14 <= 250000), "150,001-250,000", AND('Rent Table'!$I14 > 250000, 'Rent Table'!$I14 <= 350000), "250,001-350,000", AND('Rent Table'!$I14 > 350000, 'Rent Table'!$I14 <= 450000), "350,001-450,000", AND('Rent Table'!$I14 > 450000, 'Rent Table'!$I14 <= 600000), "450,001-600,000", AND('Rent Table'!$I14 > 600000, 'Rent Table'!$I14 <= 750000), "600,001-750,000",'Rent Table'!$I14 > 750000, "750,000+", TRUE, "Undefined" )} -> 150,001-250,000
A15: 1452 West Knox Street | B15: Torrance | C15: CA | D15: 90501 | E15: Los Angeles | F15: Industrial | G15: 45566 | H15: A++ | I15: 442550 | J15: SF | K15: 18.5248 | L15: 442550 | M15: 65 | N15: 2.82 | O15: 5.5 | P15: - | Q15: 2003 | R15: 2004 | S15: {=_xlfn.IFS(AND('Rent Table'!$I15>0,'Rent Table'!$I15<=50000),"0-50,000", AND('Rent Table'!$I15 > 50000, 'Rent Table'!$I15 <= 150000), "50,001-150,000", AND('Rent Table'!$I15 > 150000, 'Rent Table'!$I15 <= 250000), "150,001-250,000", AND('Rent Table'!$I15 > 250000, 'Rent Table'!$I15 <= 350000), "250,001-350,000", AND('Rent Table'!$I15 > 350000, 'Rent Table'!$I15 <= 450000), "350,001-450,000", AND('Rent Table'!$I15 > 450000, 'Rent Table'!$I15 <= 600000), "450,001-600,000", AND('Rent Table'!$I15 > 600000, 'Rent Table'!$I15 <= 750000), "600,001-750,000",'Rent Table'!$I15 > 750000, "750,000+", TRUE, "Undefined" )} -> 350,001-450,000
A16: 1457 Glenn Curtiss Street | B16: Carson | C16: CA | D16: 90746 | E16: Los Angeles | F16: Industrial | G16: 45566 | H16: A+ | I16: 76028 | J16: SF | K16: 16.8732 | L16: 76028 | M16: 48 | N16: 0.53 | O16: 1 | P16: 1 | Q16: 2006 | R16: - | S16: {=_xlfn.IFS(AND('Rent Table'!$I16>0,'Rent Table'!$I16<=50000),"0-50,000", AND('Rent Table'!$I16 > 50000, 'Rent Table'!$I16 <= 150000), "50,001-150,000", AND('Rent Table'!$I16 > 150000, 'Rent Table'!$I16 <= 250000), "150,001-250,000", AND('Rent Table'!$I16 > 250000, 'Rent Table'!$I16 <= 350000), "250,001-350,000", AND('Rent Table'!$I16 > 350000, 'Rent Table'!$I16 <= 450000), "350,001-450,000", AND('Rent Table'!$I16 > 450000, 'Rent Table'!$I16 <= 600000), "450,001-600,000", AND('Rent Table'!$I16 > 600000, 'Rent Table'!$I16 <= 750000), "600,001-750,000",'Rent Table'!$I16 > 750000, "750,000+", TRUE, "Undefined" )} -> 50,001-150,000
A17: 1460-1490 Beachey Place | B17: Carson | C17: CA | D17: 90746 | E17: Los Angeles | F17: Industrial | G17: 45566 | H17: A+ | I17: 185375 | J17: SF | K17: 18.03055 | L17: 40905 | M17: 61.5 | N17: 1 | O17: 1.5 | P17: 1 | Q17: 2005 | R17: - | S17: {=_xlfn.IFS(AND('Rent Table'!$I17>0,'Rent Table'!$I17<=50000),"0-50,000", AND('Rent Table'!$I17 > 50000, 'Rent Table'!$I17 <= 150000), "50,001-150,000", AND('Rent Table'!$I17 > 150000, 'Rent Table'!$I17 <= 250000), "150,001-250,000", AND('Rent Table'!$I17 > 250000, 'Rent Table'!$I17 <= 350000), "250,001-350,000", AND('Rent Table'!$I17 > 350000, 'Rent Table'!$I17 <= 450000), "350,001-450,000", AND('Rent Table'!$I17 > 450000, 'Rent Table'!$I17 <= 600000), "450,001-600,000", AND('Rent Table'!$I17 > 600000, 'Rent Table'!$I17 <= 750000), "600,001-750,000",'Rent Table'!$I17 > 750000, "750,000+", TRUE, "Undefined" )} -> 150,001-250,000
A18: 1500 Glenn Curtiss Street | B18: Carson | C18: CA | D18: 90746 | E18: Los Angeles | F18: Industrial | G18: 45566 | H18: A+ | I18: 242143 | J18: SF | K18: 21.1519 | L18: 48330 | M18: 64 | N18: - | O18: 4 | P18: 1 | Q18: 2002 | R18: - | S18: {=_xlfn.IFS(AND('Rent Table'!$I18>0,'Rent Table'!$I18<=50000),"0-50,000", AND('Rent Table'!$I18 > 50000, 'Rent Table'!$I18 <= 150000), "50,001-150,000", AND('Rent Table'!$I18 > 150000, 'Rent Table'!$I18 <= 250000), "150,001-250,000", AND('Rent Table'!$I18 > 250000, 'Rent Table'!$I18 <= 350000), "250,001-350,000", AND('Rent Table'!$I18 > 350000, 'Rent Table'!$I18 <= 450000), "350,001-450,000", AND('Rent Table'!$I18 > 450000, 'Rent Table'!$I18 <= 600000), "450,001-600,000", AND('Rent Table'!$I18 > 600000, 'Rent Table'!$I18 <= 750000), "600,001-750,000",'Rent Table'!$I18 > 750000, "750,000+", TRUE, "Undefined" )} -> 150,001-250,000
A19: 1521 Francisco Street | B19: Torrance | C19: CA | D19: 90501 | E19: Los Angeles | F19: Industrial | G19: 45566 | H19: A++ | I19: 46479 | J19: SF | K19: 20.3035 | L19: 23949 | M19: 35 | N19: - | O19: 1 | P19: - | Q19: 2011 | R19: 2012 | S19: {=_xlfn.IFS(AND('Rent Table'!$I19>0,'Rent Table'!$I19<=50000),"0-50,000", AND('Rent Table'!$I19 > 50000, 'Rent Table'!$I19 <= 150000), "50,001-150,000", AND('Rent Table'!$I19 > 150000, 'Rent Table'!$I19 <= 250000), "150,001-250,000", AND('Rent Table'!$I19 > 250000, 'Rent Table'!$I19 <= 350000), "250,001-350,000", AND('Rent Table'!$I19 > 350000, 'Rent Table'!$I19 <= 450000), "350,001-450,000", AND('Rent Table'!$I19 > 450000, 'Rent Table'!$I19 <= 600000), "450,001-600,000", AND('Rent Table'!$I19 > 600000, 'Rent Table'!$I19 <= 750000), "600,001-750,000",'Rent Table'!$I19 > 750000, "750,000+", TRUE, "Undefined" )} -> 0-50,000
A20: 1533-1543 East Del Amo Boulevard | B20: Carson | C20: CA | D20: 90746 | E20: Los Angeles | F20: Industrial | G20: 45566 | H20: A+ | I20: 35186 | J20: SF | K20: 12.4838 | L20: 17666 | M20: 36 | N20: - | O20: 0.5 | P20: 1 | Q20: 1971 | R20: - | S20: {=_xlfn.IFS(AND('Rent Table'!$I20>0,'Rent Table'!$I20<=50000),"0-50,000", AND('Rent Table'!$I20 > 50000, 'Rent Table'!$I20 <= 150000), "50,001-150,000", AND('Rent Table'!$I20 > 150000, 'Rent Table'!$I20 <= 250000), "150,001-250,000", AND('Rent Table'!$I20 > 250000, 'Rent Table'!$I20 <= 350000), "250,001-350,000", AND('Rent Table'!$I20 > 350000, 'Rent Table'!$I20 <= 450000), "350,001-450,000", AND('Rent Table'!$I20 > 450000, 'Rent Table'!$I20 <= 600000), "450,001-600,000", AND('Rent Table'!$I20 > 600000, 'Rent Table'!$I20 <= 750000), "600,001-750,000",'Rent Table'!$I20 > 750000, "750,000+", TRUE, "Undefined" )} -> 0-50,000
A21: 1540-1560 West 190th Street | B21: Torrance | C21: CA | D21: 90501 | E21: Los Angeles | F21: Industrial | G21: 45566 | H21: A++ | I21: 117460 | J21: SF | K21: 25.9481 | L21: 90133 | M21: 60 | N21: - | O21: - | P21: 1 | Q21: 2000 | R21: - | S21: {=_xlfn.IFS(AND('Rent Table'!$I21>0,'Rent Table'!$I21<=50000),"0-50,000", AND('Rent Table'!$I21 > 50000, 'Rent Table'!$I21 <= 150000), "50,001-150,000", AND('Rent Table'!$I21 > 150000, 'Rent Table'!$I21 <= 250000), "150,001-250,000", AND('Rent Table'!$I21 > 250000, 'Rent Table'!$I21 <= 350000), "250,001-350,000", AND('Rent Table'!$I21 > 350000, 'Rent Table'!$I21 <= 450000), "350,001-450,000", AND('Rent Table'!$I21 > 450000, 'Rent Table'!$I21 <= 600000), "450,001-600,000", AND('Rent Table'!$I21 > 600000, 'Rent Table'!$I21 <= 750000), "600,001-750,000",'Rent Table'!$I21 > 750000, "750,000+", TRUE, "Undefined" )} -> 50,001-150,000
A22: 1545 Francisco Street | B22: Torrance | C22: CA | D22: 90501 | E22: Los Angeles | F22: Industrial | G22: 45566 | H22: A++ | I22: 277000 | J22: SF | K22: 16.2203 | L22: 106898 | M22: 61 | N22: 1 | O22: 1 | P22: 2 | Q22: 2012 | R22: 2013 | S22: {=_xlfn.IFS(AND('Rent Table'!$I22>0,'Rent Table'!$I22<=50000),"0-50,000", AND('Rent Table'!$I22 > 50000, 'Rent Table'!$I22 <= 150000), "50,001-150,000", AND('Rent Table'!$I22 > 150000, 'Rent Table'!$I22 <= 250000), "150,001-250,000", AND('Rent Table'!$I22 > 250000, 'Rent Table'!$I22 <= 350000), "250,001-350,000", AND('Rent Table'!$I22 > 350000, 'Rent Table'!$I22 <= 450000), "350,001-450,000", AND('Rent Table'!$I22 > 450000, 'Rent Table'!$I22 <= 600000), "450,001-600,000", AND('Rent Table'!$I22 > 600000, 'Rent Table'!$I22 <= 750000), "600,001-750,000",'Rent Table'!$I22 > 750000, "750,000+", TRUE, "Undefined" )} -> 250,001-350,000
A23: 1550-1650 Charles Willard Street | B23: Carson | C23: CA | D23: 90746 | E23: Los Angeles | F23: Industrial | G23: 45566 | H23: A+ | I23: 210938 | J23: SF | K23: 21.9904 | L23: 107753 | M23: 64 | N23: 1.5 | O23: 1 | P23: 1 | Q23: 2000 | R23: 2005 | S23: {=_xlfn.IFS(AND('Rent Table'!$I23>0,'Rent Table'!$I23<=50000),"0-50,000", AND('Rent Table'!$I23 > 50000, 'Rent Table'!$I23 <= 150000), "50,001-150,000", AND('Rent Table'!$I23 > 150000, 'Rent Table'!$I23 <= 250000), "150,001-250,000", AND('Rent Table'!$I23 > 250000, 'Rent Table'!$I23 <= 350000), "250,001-350,000", AND('Rent Table'!$I23 > 350000, 'Rent Table'!$I23 <= 450000), "350,001-450,000", AND('Rent Table'!$I23 > 450000, 'Rent Table'!$I23 <= 600000), "450,001-600,000", AND('Rent Table'!$I23 > 600000, 'Rent Table'!$I23 <= 750000), "600,001-750,000",'Rent Table'!$I23 > 750000, "750,000+", TRUE, "Undefined" )} -> 150,001-250,000
A24: 1561 Beachey Place | B24: Carson | C24: CA | D24: 90746 | E24: Los Angeles | F24: Industrial | G24: 45566 | H24: A+ | I24: 108873 | J24: SF | K24: 21.6977 | L24: 107603 | M24: 60 | N24: - | O24: 2 | P24: 2 | Q24: 2004 | R24: 2005 | S24: {=_xlfn.IFS(AND('Rent Table'!$I24>0,'Rent Table'!$I24<=50000),"0-50,000", AND('Rent Table'!$I24 > 50000, 'Rent Table'!$I24 <= 150000), "50,001-150,000", AND('Rent Table'!$I24 > 150000, 'Rent Table'!$I24 <= 250000), "150,001-250,000", AND('Rent Table'!$I24 > 250000, 'Rent Table'!$I24 <= 350000), "250,001-350,000", AND('Rent Table'!$I24 > 350000, 'Rent Table'!$I24 <= 450000), "350,001-450,000", AND('Rent Table'!$I24 > 450000, 'Rent Table'!$I24 <= 600000), "450,001-600,000", AND('Rent Table'!$I24 > 600000, 'Rent Table'!$I24 <= 750000), "600,001-750,000",'Rent Table'!$I24 > 750000, "750,000+", TRUE, "Undefined" )} -> 50,001-150,000
A25: 1640 West 190th Street | B25: Torrance | C25: CA | D25: 90501 | E25: Los Angeles | F25: Industrial | G25: 45566 | H25: A++ | I25: 123345 | J25: SF | K25: 28.9685 | L25: 123345 | M25: 120 | N25: - | O25: 1.5 | P25: 1 | Q25: 2000 | R25: - | S25: {=_xlfn.IFS(AND('Rent Table'!$I25>0,'Rent Table'!$I25<=50000),"0-50,000", AND('Rent Table'!$I25 > 50000, 'Rent Table'!$I25 <= 150000), "50,001-150,000", AND('Rent Table'!$I25 > 150000, 'Rent Table'!$I25 <= 250000), "150,001-250,000", AND('Rent Table'!$I25 > 250000, 'Rent Table'!$I25 <= 350000), "250,001-350,000", AND('Rent Table'!$I25 > 350000, 'Rent Table'!$I25 <= 450000), "350,001-450,000", AND('Rent Table'!$I25 > 450000, 'Rent Table'!$I25 <= 600000), "450,001-600,000", AND('Rent Table'!$I25 > 600000, 'Rent Table'!$I25 <= 750000), "600,001-750,000",'Rent Table'!$I25 > 750000, "750,000+", TRUE, "Undefined" )} -> 50,001-150,000
A26: 1667 East Del Amo Boulevard | B26: Carson | C26: CA | D26: 90746 | E26: Los Angeles | F26: Industrial | G26: 45566 | H26: A+ | I26: 16863 | J26: SF | K26: 11.3567 | L26: 1752 | M26: 24 | N26: - | O26: - | P26: 1 | Q26: 1970 | R26: - | S26: {=_xlfn.IFS(AND('Rent Table'!$I26>0,'Rent Table'!$I26<=50000),"0-50,000", AND('Rent Table'!$I26 > 50000, 'Rent Table'!$I26 <= 150000), "50,001-150,000", AND('Rent Table'!$I26 > 150000, 'Rent Table'!$I26 <= 250000), "150,001-250,000", AND('Rent Table'!$I26 > 250000, 'Rent Table'!$I26 <= 350000), "250,001-350,000", AND('Rent Table'!$I26 > 350000, 'Rent Table'!$I26 <= 450000), "350,001-450,000", AND('Rent Table'!$I26 > 450000, 'Rent Table'!$I26 <= 600000), "450,001-600,000", AND('Rent Table'!$I26 > 600000, 'Rent Table'!$I26 <= 750000), "600,001-750,000",'Rent Table'!$I26 > 750000, "750,000+", TRUE, "Undefined" )} -> 0-50,000
A27: 1681 East Del Amo Boulevard | B27: Carson | C27: CA | D27: 90746 | E27: Los Angeles | F27: Industrial | G27: 45566 | H27: A+ | I27: 16862 | J27: SF | K27: 10.7525 | L27: 2592 | M27: 36 | N27: - | O27: - | P27: 1 | Q27: 1970 | R27: - | S27: {=_xlfn.IFS(AND('Rent Table'!$I27>0,'Rent Table'!$I27<=50000),"0-50,000", AND('Rent Table'!$I27 > 50000, 'Rent Table'!$I27 <= 150000), "50,001-150,000", AND('Rent Table'!$I27 > 150000, 'Rent Table'!$I27 <= 250000), "150,001-250,000", AND('Rent Table'!$I27 > 250000, 'Rent Table'!$I27 <= 350000), "250,001-350,000", AND('Rent Table'!$I27 > 350000, 'Rent Table'!$I27 <= 450000), "350,001-450,000", AND('Rent Table'!$I27 > 450000, 'Rent Table'!$I27 <= 600000), "450,001-600,000", AND('Rent Table'!$I27 > 600000, 'Rent Table'!$I27 <= 750000), "600,001-750,000",'Rent Table'!$I27 > 750000, "750,000+", TRUE, "Undefined" )} -> 0-50,000
A28: 1683 East Del Amo Boulevard | B28: Carson | C28: CA | D28: 90746 | E28: Los Angeles | F28: Industrial | G28: 45566 | H28: A+ | I28: 16882 | J28: SF | K28: 12.214405 | L28: 2555 | M28: 48.5 | N28: - | O28: 1 | P28: 1 | Q28: 1970 | R28: - | S28: {=_xlfn.IFS(AND('Rent Table'!$I28>0,'Rent Table'!$I28<=50000),"0-50,000", AND('Rent Table'!$I28 > 50000, 'Rent Table'!$I28 <= 150000), "50,001-150,000", AND('Rent Table'!$I28 > 150000, 'Rent Table'!$I28 <= 250000), "150,001-250,000", AND('Rent Table'!$I28 > 250000, 'Rent Table'!$I28 <= 350000), "250,001-350,000", AND('Rent Table'!$I28 > 350000, 'Rent Table'!$I28 <= 450000), "350,001-450,000", AND('Rent Table'!$I28 > 450000, 'Rent Table'!$I28 <= 600000), "450,001-600,000", AND('Rent Table'!$I28 > 600000, 'Rent Table'!$I28 <= 750000), "600,001-750,000",'Rent Table'!$I28 > 750000, "750,000+", TRUE, "Undefined" )} -> 0-50,000
A29: 1685 East Del Amo Boulevard | B29: Carson | C29: CA | D29: 90746 | E29: Los Angeles | F29: Industrial | G29: 45566 | H29: A+ | I29: 16862 | J29: SF | K29: 12.9391 | L29: 1752 | M29: 36 | N29: - | O29: - | P29: 1 | Q29: 1970 | R29: - | S29: {=_xlfn.IFS(AND('Rent Table'!$I29>0,'Rent Table'!$I29<=50000),"0-50,000", AND('Rent Table'!$I29 > 50000, 'Rent Table'!$I29 <= 150000), "50,001-150,000", AND('Rent Table'!$I29 > 150000, 'Rent Table'!$I29 <= 250000), "150,001-250,000", AND('Rent Table'!$I29 > 250000, 'Rent Table'!$I29 <= 350000), "250,001-350,000", AND('Rent Table'!$I29 > 350000, 'Rent Table'!$I29 <= 450000), "350,001-450,000", AND('Rent Table'!$I29 > 450000, 'Rent Table'!$I29 <= 600000), "450,001-600,000", AND('Rent Table'!$I29 > 600000, 'Rent Table'!$I29 <= 750000), "600,001-750,000",'Rent Table'!$I29 > 750000, "750,000+", TRUE, "Undefined" )} -> 0-50,000
A30: 1689 East Del Amo Boulevard | B30: Carson | C30: CA | D30: 90746 | E30: Los Angeles | F30: Industrial | G30: 45566 | H30: A+ | I30: 40332 | J30: SF | K30: 12.4644 | L30: 1752 | M30: 36 | N30: - | O30: - | P30: 1 | Q30: 1970 | R30: - | S30: {=_xlfn.IFS(AND('Rent Table'!$I30>0,'Rent Table'!$I30<=50000),"0-50,000", AND('Rent Table'!$I30 > 50000, 'Rent Table'!$I30 <= 150000), "50,001-150,000", AND('Rent Table'!$I30 > 150000, 'Rent Table'!$I30 <= 250000), "150,001-250,000", AND('Rent Table'!$I30 > 250000, 'Rent Table'!$I30 <= 350000), "250,001-350,000", AND('Rent Table'!$I30 > 350000, 'Rent Table'!$I30 <= 450000), "350,001-450,000", AND('Rent Table'!$I30 > 450000, 'Rent Table'!$I30 <= 600000), "450,001-600,000", AND('Rent Table'!$I30 > 600000, 'Rent Table'!$I30 <= 750000), "600,001-750,000",'Rent Table'!$I30 > 750000, "750,000+", TRUE, "Undefined" )} -> 0-50,000
A31: 1693 East Del Amo Boulevard | B31: Carson | C31: CA | D31: 90746 | E31: Los Angeles | F31: Industrial | G31: 45566 | H31: A+ | I31: 16863 | J31: SF | K31: 13.0156 | L31: 2336 | M31: 24 | N31: - | O31: - | P31: 1 | Q31: 1970 | R31: - | S31: {=_xlfn.IFS(AND('Rent Table'!$I31>0,'Rent Table'!$I31<=50000),"0-50,000", AND('Rent Table'!$I31 > 50000, 'Rent Table'!$I31 <= 150000), "50,001-150,000", AND('Rent Table'!$I31 > 150000, 'Rent Table'!$I31 <= 250000), "150,001-250,000", AND('Rent Table'!$I31 > 250000, 'Rent Table'!$I31 <= 350000), "250,001-350,000", AND('Rent Table'!$I31 > 350000, 'Rent Table'!$I31 <= 450000), "350,001-450,000", AND('Rent Table'!$I31 > 450000, 'Rent Table'!$I31 <= 600000), "450,001-600,000", AND('Rent Table'!$I31 > 600000, 'Rent Table'!$I31 <= 750000), "600,001-750,000",'Rent Table'!$I31 > 750000, "750,000+", TRUE, "Undefined" )} -> 0-50,000
A32: 1810 195th Street | B32: Torrance | C32: CA | D32: 90501 | E32: Los Angeles | F32: Industrial | G32: 45566 | H32: A++ | I32: 107140 | J32: SF | K32: 19.7753 | L32: 107140 | M32: 123 | N32: 3 | O32: 3 | P32: - | Q32: 2022 | R32: - | S32: {=_xlfn.IFS(AND('Rent Table'!$I32>0,'Rent Table'!$I32<=50000),"0-50,000", AND('Rent Table'!$I32 > 50000, 'Rent Table'!$I32 <= 150000), "50,001-150,000", AND('Rent Table'!$I32 > 150000, 'Rent Table'!$I32 <= 250000), "150,001-250,000", AND('Rent Table'!$I32 > 250000, 'Rent Table'!$I32 <= 350000), "250,001-350,000", AND('Rent Table'!$I32 > 350000, 'Rent Table'!$I32 <= 450000), "350,001-450,000", AND('Rent Table'!$I32 > 450000, 'Rent Table'!$I32 <= 600000), "450,001-600,000", AND('Rent Table'!$I32 > 600000, 'Rent Table'!$I32 <= 750000), "600,001-750,000",'Rent Table'!$I32 > 750000, "750,000+", TRUE, "Undefined" )} -> 50,001-150,000
A33: 1820 195th Street | B33: Torrance | C33: CA | D33: 90501 | E33: Los Angeles | F33: Industrial | G33: 45566 | H33: A++ | I33: 104544 | J33: SF | K33: 20.2742 | L33: 104544 | M33: 123 | N33: 3 | O33: 3 | P33: - | Q33: 2022 | R33: - | S33: {=_xlfn.IFS(AND('Rent Table'!$I33>0,'Rent Table'!$I33<=50000),"0-50,000", AND('Rent Table'!$I33 > 50000, 'Rent Table'!$I33 <= 150000), "50,001-150,000", AND('Rent Table'!$I33 > 150000, 'Rent Table'!$I33 <= 250000), "150,001-250,000", AND('Rent Table'!$I33 > 250000, 'Rent Table'!$I33 <= 350000), "250,001-350,000", AND('Rent Table'!$I33 > 350000, 'Rent Table'!$I33 <= 450000), "350,001-450,000", AND('Rent Table'!$I33 > 450000, 'Rent Table'!$I33 <= 600000), "450,001-600,000", AND('Rent Table'!$I33 > 600000, 'Rent Table'!$I33 <= 750000), "600,001-750,000",'Rent Table'!$I33 > 750000, "750,000+", TRUE, "Undefined" )} -> 50,001-150,000
A34: 1830 West 205th Street | B34: Torrance | C34: CA | D34: 90501 | E34: Los Angeles | F34: Industrial | G34: 45566 | H34: A++ | I34: 31505 | J34: SF | K34: 24.8275 | L34: 31505 | M34: 84 | N34: 7.94 | O34: 3 | P34: 1 | Q34: 1978 | R34: 1993 | S34: {=_xlfn.IFS(AND('Rent Table'!$I34>0,'Rent Table'!$I34<=50000),"0-50,000", AND('Rent Table'!$I34 > 50000, 'Rent Table'!$I34 <= 150000), "50,001-150,000", AND('Rent Table'!$I34 > 150000, 'Rent Table'!$I34 <= 250000), "150,001-250,000", AND('Rent Table'!$I34 > 250000, 'Rent Table'!$I34 <= 350000), "250,001-350,000", AND('Rent Table'!$I34 > 350000, 'Rent Table'!$I34 <= 450000), "350,001-450,000", AND('Rent Table'!$I34 > 450000, 'Rent Table'!$I34 <= 600000), "450,001-600,000", AND('Rent Table'!$I34 > 600000, 'Rent Table'!$I34 <= 750000), "600,001-750,000",'Rent Table'!$I34 > 750000, "750,000+", TRUE, "Undefined" )} -> 0-50,000
A35: 18300 Central Avenue | B35: Carson | C35: CA | D35: 90746 | E35: Los Angeles | F35: Industrial | G35: 45566 | H35: A+ | I35: 183473 | J35: SF | K35: 18.754 | L35: 183473 | M35: 120 | N35: - | O35: 1 | P35: 1 | Q35: 2000 | R35: - | S35: {=_xlfn.IFS(AND('Rent Table'!$I35>0,'Rent Table'!$I35<=50000),"0-50,000", AND('Rent Table'!$I35 > 50000, 'Rent Table'!$I35 <= 150000), "50,001-150,000", AND('Rent Table'!$I35 > 150000, 'Rent Table'!$I35 <= 250000), "150,001-250,000", AND('Rent Table'!$I35 > 250000, 'Rent Table'!$I35 <= 350000), "250,001-350,000", AND('Rent Table'!$I35 > 350000, 'Rent Table'!$I35 <= 450000), "350,001-450,000", AND('Rent Table'!$I35 > 450000, 'Rent Table'!$I35 <= 600000), "450,001-600,000", AND('Rent Table'!$I35 > 600000, 'Rent Table'!$I35 <= 750000), "600,001-750,000",'Rent Table'!$I35 > 750000, "750,000+", TRUE, "Undefined" )} -> 150,001-250,000
A36: 1845 West 205th Street | B36: Torrance | C36: CA | D36: 90501 | E36: Los Angeles | F36: Industrial | G36: 45566 | H36: A++ | I36: 34505 | J36: SF | K36: 24.277 | L36: 25301 | M36: 89 | N36: - | O36: 4.34 | P36: 1 | Q36: 1978 | R36: - | S36: {=_xlfn.IFS(AND('Rent Table'!$I36>0,'Rent Table'!$I36<=50000),"0-50,000", AND('Rent Table'!$I36 > 50000, 'Rent Table'!$I36 <= 150000), "50,001-150,000", AND('Rent Table'!$I36 > 150000, 'Rent Table'!$I36 <= 250000), "150,001-250,000", AND('Rent Table'!$I36 > 250000, 'Rent Table'!$I36 <= 350000), "250,001-350,000", AND('Rent Table'!$I36 > 350000, 'Rent Table'!$I36 <= 450000), "350,001-450,000", AND('Rent Table'!$I36 > 450000, 'Rent Table'!$I36 <= 600000), "450,001-600,000", AND('Rent Table'!$I36 > 600000, 'Rent Table'!$I36 <= 750000), "600,001-750,000",'Rent Table'!$I36 > 750000, "750,000+", TRUE, "Undefined" )} -> 0-50,000
A37: 18600 Crenshaw Boulevard | B37: Torrance | C37: CA | D37: 90504 | E37: Los Angeles | F37: Industrial | G37: 45566 | H37: A++ | I37: 77843 | J37: SF | K37: 16.7513 | L37: 29978 | M37: 120 | N37: - | O37: 4 | P37: 1 | Q37: 1974 | R37: - | S37: {=_xlfn.IFS(AND('Rent Table'!$I37>0,'Rent Table'!$I37<=50000),"0-50,000", AND('Rent Table'!$I37 > 50000, 'Rent Table'!$I37 <= 150000), "50,001-150,000", AND('Rent Table'!$I37 > 150000, 'Rent Table'!$I37 <= 250000), "150,001-250,000", AND('Rent Table'!$I37 > 250000, 'Rent Table'!$I37 <= 350000), "250,001-350,000", AND('Rent Table'!$I37 > 350000, 'Rent Table'!$I37 <= 450000), "350,001-450,000", AND('Rent Table'!$I37 > 450000, 'Rent Table'!$I37 <= 600000), "450,001-600,000", AND('Rent Table'!$I37 > 600000, 'Rent Table'!$I37 <= 750000), "600,001-750,000",'Rent Table'!$I37 > 750000, "750,000+", TRUE, "Undefined" )} -> 50,001-150,000
A38: 19000-19010 South Vermont Avenue | B38: Gardena | C38: CA | D38: 90248 | E38: Los Angeles | F38: Industrial | G38: 45505 | H38: A++ | I38: 45585 | J38: SF | K38: 25.7664 | L38: 20497 | M38: 120 | N38: - | O38: - | P38: 1 | Q38: 1970 | R38: 1982 | S38: {=_xlfn.IFS(AND('Rent Table'!$I38>0,'Rent Table'!$I38<=50000),"0-50,000", AND('Rent Table'!$I38 > 50000, 'Rent Table'!$I38 <= 150000), "50,001-150,000", AND('Rent Table'!$I38 > 150000, 'Rent Table'!$I38 <= 250000), "150,001-250,000", AND('Rent Table'!$I38 > 250000, 'Rent Table'!$I38 <= 350000), "250,001-350,000", AND('Rent Table'!$I38 > 350000, 'Rent Table'!$I38 <= 450000), "350,001-450,000", AND('Rent Table'!$I38 > 450000, 'Rent Table'!$I38 <= 600000), "450,001-600,000", AND('Rent Table'!$I38 > 600000, 'Rent Table'!$I38 <= 750000), "600,001-750,000",'Rent Table'!$I38 > 750000, "750,000+", TRUE, "Undefined" )} -> 0-50,000
A39: 19032 South Vermont Avenue | B39: Gardena | C39: CA | D39: 90248 | E39: Los Angeles | F39: Industrial | G39: 45566 | H39: A++ | I39: 100080 | J39: SF | K39: 11.7541 | L39: 33850 | M39: 24 | N39: - | O39: - | P39: 1 | Q39: 1970 | R39: 1972 | S39: {=_xlfn.IFS(AND('Rent Table'!$I39>0,'Rent Table'!$I39<=50000),"0-50,000", AND('Rent Table'!$I39 > 50000, 'Rent Table'!$I39 <= 150000), "50,001-150,000", AND('Rent Table'!$I39 > 150000, 'Rent Table'!$I39 <= 250000), "150,001-250,000", AND('Rent Table'!$I39 > 250000, 'Rent Table'!$I39 <= 350000), "250,001-350,000", AND('Rent Table'!$I39 > 350000, 'Rent Table'!$I39 <= 450000), "350,001-450,000", AND('Rent Table'!$I39 > 450000, 'Rent Table'!$I39 <= 600000), "450,001-600,000", AND('Rent Table'!$I39 > 600000, 'Rent Table'!$I39 <= 750000), "600,001-750,000",'Rent Table'!$I39 > 750000, "750,000+", TRUE, "Undefined" )} -> 50,001-150,000
A40: 19038 South Vermont Avenue | B40: Gardena | C40: CA | D40: 90248 | E40: Los Angeles | F40: Industrial | G40: 45566 | H40: A++ | I40: 100080 | J40: SF | K40: 22.5784 | L40: 49690 | M40: 120.5 | N40: - | O40: - | P40: 1 | Q40: 1970 | R40: 1972 | S40: {=_xlfn.IFS(AND('Rent Table'!$I40>0,'Rent Table'!$I40<=50000),"0-50,000", AND('Rent Table'!$I40 > 50000, 'Rent Table'!$I40 <= 150000), "50,001-150,000", AND('Rent Table'!$I40 > 150000, 'Rent Table'!$I40 <= 250000), "150,001-250,000", AND('Rent Table'!$I40 > 250000, 'Rent Table'!$I40 <= 350000), "250,001-350,000", AND('Rent Table'!$I40 > 350000, 'Rent Table'!$I40 <= 450000), "350,001-450,000", AND('Rent Table'!$I40 > 450000, 'Rent Table'!$I40 <= 600000), "450,001-600,000", AND('Rent Table'!$I40 > 600000, 'Rent Table'!$I40 <= 750000), "600,001-750,000",'Rent Table'!$I40 > 750000, "750,000+", TRUE, "Undefined" )} -> 50,001-150,000
...

Sheet Rent Summary
B2: Effective Rent Market Summary
E3: Count | F3: Min | G3: Max | H3: SD | I3: Average Effective Rent
B4: Inland Empire | E4: 50 | F4: 6.89242 | G4: 20.4175 | H4: 2.5608557 | I4: 11.74845
C5: Colton | E5: 1 | F5: 10.2039 | G5: 10.2039 | I5: 10.2039
D6: 250,001-350,000 | E6: 1 | F6: 10.2039 | G6: 10.2039 | I6: 10.2039
C7: Loma Linda | E7: 3 | F7: 13.0548 | G7: 14.1289 | H7: 0.54345147 | I7: 13.639867
D8: 250,001-350,000 | E8: 1 | F8: 13.7359 | G8: 13.7359 | I8: 13.7359
D9: 50,001-150,000 | E9: 2 | F9: 13.0548 | G9: 14.1289 | H9: 0.75950339 | I9: 13.59185
C10: Redlands | E10: 32 | F10: 6.89242 | G10: 20.4175 | H10: 2.6320308 | I10: 11.672032
D11: 0-50,000 | E11: 12 | F11: 9.07241 | G11: 20.4175 | H11: 2.9801098 | I11: 12.404307
D12: 150,001-250,000 | E12: 2 | F12: 9.18398 | G12: 14.9824 | H12: 4.1001021 | I12: 12.08319
D13: 250,001-350,000 | E13: 1 | F13: 12.901 | G13: 12.901 | I13: 12.901
D14: 350,001-450,000 | E14: 2 | F14: 10.0171 | G14: 13.1526 | H14: 2.2171333 | I14: 11.58485
D15: 450,001-600,000 | E15: 2 | F15: 10.0691 | G15: 13.67495 | H15: 2.549721 | I15: 11.872025
D16: 50,001-150,000 | E16: 9 | F16: 9.0859 | G16: 14.7399 | H16: 2.1684749 | I16: 11.803631
D17: 600,001-750,000 | E17: 2 | F17: 8.70586 | G17: 8.74871 | H17: 0.030299526 | I17: 8.727285
D18: 750,000+ | E18: 2 | F18: 6.89242 | G18: 10.09254 | H18: 2.2628266 | I18: 8.49248
C19: San Bernardino | E19: 14 | F19: 7.35182 | G19: 16.583 | H19: 2.6672912 | I19: 11.628142
D20: 0-50,000 | E20: 8 | F20: 8.32503 | G20: 15.5779 | H20: 2.1085725 | I20: 11.577487
D21: 250,001-350,000 | E21: 1 | F21: 8.39927 | G21: 8.39927 | I21: 8.39927
D22: 450,001-600,000 | E22: 1 | F22: 7.35182 | G22: 7.35182 | I22: 7.35182
D23: 50,001-150,000 | E23: 4 | F23: 11.1859 | G23: 16.583 | H23: 2.3796639 | I23: 13.60575
B24: Los Angeles | E24: 50 | F24: 10.7525 | G24: 30.2333 | H24: 4.7616267 | I24: 19.067257
C25: Carson | E25: 19 | F25: 10.7525 | G25: 21.9904 | H25: 3.8169864 | I25: 16.560663
D26: 0-50,000 | E26: 8 | F26: 10.7525 | G26: 18.473 | H26: 2.3564069 | I26: 12.962438
D27: 150,001-250,000 | E27: 5 | F27: 18.03055 | G27: 21.9904 | H27: 1.6933218 | I27: 19.78795
D28: 250,001-350,000 | E28: 1 | F28: 20.28085 | G28: 20.28085 | I28: 20.28085
D29: 50,001-150,000 | E29: 5 | F29: 14.9052 | G29: 21.6977 | H29: 2.5724724 | I29: 18.3465
C30: Gardena | E30: 3 | F30: 11.7541 | G30: 25.7664 | H30: 7.3447642 | I30: 20.032967
D31: 0-50,000 | E31: 1 | F31: 25.7664 | G31: 25.7664 | I31: 25.7664
D32: 50,001-150,000 | E32: 2 | F32: 11.7541 | G32: 22.5784 | H32: 7.6539359 | I32: 17.16625
C33: Torrance | E33: 28 | F33: 12.102 | G33: 30.2333 | H33: 4.5019173 | I33: 20.664691
D34: 0-50,000 | E34: 8 | F34: 12.102 | G34: 30.2333 | H34: 5.7697141 | I34: 20.502594
D35: 150,001-250,000 | E35: 3 | F35: 19.51805 | G35: 27.9826 | H35: 4.6589024 | I35: 22.625867
D36: 250,001-350,000 | E36: 5 | F36: 16.2203 | G36: 25.5206 | H36: 3.6797274 | I36: 19.08812
D37: 350,001-450,000 | E37: 1 | F37: 18.5248 | G37: 18.5248 | I37: 18.5248
D38: 50,001-150,000 | E38: 9 | F38: 16.7513 | G38: 28.9685 | H38: 4.1221069 | I38: 22.1494
D39: 600,001-750,000 | E39: 1 | F39: 16.1212 | G39: 16.1212 | I39: 16.1212
D40: 750,000+ | E40: 1 | F40: 17.2818 | G40: 17.2818 | I40: 17.2818

Sheet Sales Comp Summary
A2: City | B2: Sum of Sale Price Per (in Local Currency)
A3: Torrance | B3: 7180.68
A4: Redlands | B4: 2616.45
A5: Gardena | B5: 2320.64
A6: San Bernardino | B6: 1485.3
A7: Carson | B7: 894.51
A8: Colton | B8: 451.08
A9: Oxnard | B9: 161.66
A10: Grand Total | B10: 15110.32

Sheet Sales Table
A1: Appended Table
B4: Portfolio / Property Name | C4: Street Address | D4: City | E4: State | F4: Country | G4: Zip Code | H4: Sector | I4: Subsector | J4: Sector Attribute | K4: Part of Mixed Use Development | L4: Market | M4: Submarket | N4: Size | O4: Size Type | P4: Sale Date | Q4: Stake Sold | R4: Local Currency Sale Price (M) | S4: Local Currency Symbol | T4: Sale Price Per (in Local Currency) | U4: Selected Currency Sale Price ($) (M) | V4: Submarket Grade | W4: Property Cap Rate | X4: Property Cap Rate Type | Y4: Part of a Portfolio? | Z4: Buyer | AA4: Seller | AB4: Buyer Objective | AC4: To be demolished | AD4: Buyer Broker | AE4: Seller Broker | AF4: Land Area (acres) | AG4: Stories | AH4: Parking | AI4: Buildings | AJ4: Year Built | AK4: Year Renovated | AL4: Occupancy | AM4: Green Street Market Cap Rate | AN4: Submarket Cap Rate | AO4: Zip Code Cap Rate | AP4: Lender | AQ4: 1st Mortgage | AR4: Verified?
B5: 1971 Essex Court | C5: 1971 Essex Court, Redlands, CA 92373 | D5: Redlands | E5: CA | F5: United States | G5: 92373 | H5: Industrial | I5: Flex Industrial | K5: No | L5: Inland Empire | M5: IE-East Redlands | N5: 21228 | O5: SF | P5: 45295 | Q5: 1 | R5: 5.1 | S5: $ | T5: 240.25 | V5: A- | W5: 0.04052253 | X5: Green Street Market Estimate | Y5: No | Z5: CMJ Brother's Corp. | AC5: No | AF5: 1.183 | AG5: 1 | AI5: 1 | AJ5: 2001 | AM5: 0.047 | AN5: 0.0481871 | AO5: 0.04791285 | AP5: Rediger Investments | AQ5: 2550000 | AR5: Yes
B6: 1425 Cooley Court | C6: 1425 Cooley Court, San Bernardino, CA 92408 | D6: San Bernardino | E6: CA | F6: United States | G6: 92408 | H6: Industrial | I6: Warehouse | J6: Light Industrial | K6: No | L6: Inland Empire | M6: IE-East Redlands | N6: 78012 | O6: SF | P6: 45205 | Q6: 1 | R6: 11.1 | S6: $ | T6: 142.29 | V6: A- | W6: 0.0424211 | X6: Green Street Market Estimate | Y6: No | AC6: No | AF6: 2.81 | AG6: 2 | AI6: 1 | AJ6: 1988 | AM6: 0.047 | AN6: 0.0481871 | AO6: 0.04791285 | AP6: Symetra Financial | AQ6: 6400000 | AR6: Yes
B7: 1320 Riverview Drive | C7: 1320 Riverview Drive, San Bernardino, CA 92408 | D7: San Bernardino | E7: CA | F7: United States | G7: 92408 | H7: Industrial | I7: Warehouse | J7: Light Industrial | K7: No | L7: Inland Empire | M7: IE-East Redlands | N7: 23397 | O7: SF | P7: 45201 | Q7: 1 | R7: 5.62 | S7: $ | T7: 240.01 | V7: A- | W7: 0.0424211 | X7: Green Street Market Estimate | Y7: No | AA7: Rogina Family Living Trust | AC7: No | AF7: 1.24 | AG7: 2 | AI7: 1 | AJ7: 2004 | AM7: 0.047 | AN7: 0.0481871 | AO7: 0.04791285 | AP7: Wells Fargo Bank | AQ7: 3369200 | AR7: Yes
B8: 401 Alabama Street | C8: 401 Alabama Street, Redlands, CA 92373 | D8: Redlands | E8: CA | F8: United States | G8: 92373 | H8: Industrial | I8: Warehouse | J8: Light Industrial | K8: No | L8: Inland Empire | M8: IE-East Redlands | N8: 95500 | O8: SF | P8: 45051 | Q8: 1 | R8: 27.25 | S8: $ | T8: 285.34 | V8: A- | W8: 0.043 | X8: As Reported | Y8: No | Z8: General Investment & Development Cos. | AA8: Investment Building Group | AC8: No | AE8: CBRE Group | AF8: 4.526 | AG8: 1 | AI8: 1 | AJ8: 2017 | AL8: 1 | AM8: 0.047 | AN8: 0.0481871 | AO8: 0.04791285 | AR8: Yes
B9: Carnegie Business Center | C9: 720 East Carnegie Drive, San Bernardino, CA 92408 | D9: San Bernardino | E9: CA | F9: United States | G9: 92408 | H9: Industrial | I9: Warehouse | J9: Light Industrial | K9: No | L9: Inland Empire | M9: IE-East Redlands | N9: 51438 | O9: SF | P9: 44715 | Q9: 1 | R9: 11.02 | S9: $ | T9: 214.19 | V9: A- | W9: 0.0577 | X9: As Reported | Y9: No | AA9: Entrada Partners | AC9: No | AD9: CBRE Group | AE9: CBRE Group | AH9: 0 | AI9: 1 | AJ9: 1987 | AL9: 0.95 | AM9: 0.047 | AN9: 0.0481871 | AO9: 0.04791285 | AR9: Yes
B10: 1990 Riverview Drive | C10: 1990 Riverview Drive, San Bernardino, CA 92408 | D10: San Bernardino | E10: CA | F10: United States | G10: 92408 | H10: Industrial | I10: Warehouse | K10: No | L10: Inland Empire | M10: IE-East Redlands | N10: 20473 | O10: SF | P10: 44704 | Q10: 1 | R10: 24 | S10: $ | T10: 1,172.28 | V10: A- | W10: 0.03667045 | X10: Green Street Market Estimate | Y10: No | AC10: No | AD10: CBRE Group | AH10: 0 | AJ10: 1980 | AM10: 0.047 | AN10: 0.0481871 | AO10: 0.04791285 | AR10: Yes
B11: 1393 East San Bernardino Avenue | C11: 1393 East San Bernardino Avenue, San Bernardino, CA 92408 | D11: San Bernardino | E11: CA | F11: United States | G11: 92408 | H11: Industrial | I11: Warehouse | J11: Light Industrial | K11: No | L11: Inland Empire | M11: IE-East Redlands | N11: 117125 | O11: SF | P11: 44696 | Q11: 1 | R11: 20 | S11: $ | T11: 170.76 | V11: A- | W11: 0.03667045 | X11: Green Street Market Estimate | Y11: No | Z11: First Industrial Realty Trust (FR) | AC11: No | AM11: 0.047 | AN11: 0.0481871 | AO11: 0.04791285 | AR11: Yes
B12: 301 Tennessee Street | C12: 301 Tennessee Street, Redlands, CA 92373 | D12: Redlands | E12: CA | F12: United States | G12: 92373 | H12: Industrial | I12: Warehouse | J12: Manufacturing / Heavy Industrial | K12: No | L12: Inland Empire | M12: IE-East Redlands | N12: 193469 | O12: SF | P12: 44665 | Q12: 1 | R12: 18.25 | S12: $ | T12: 94.33 | V12: A- | W12: 0.03412073 | X12: Green Street Market Estimate | Y12: No | Z12: Stos Partners | AA12: ESRI | AC12: No | AE12: Savills | AH12: 0 | AM12: 0.047 | AN12: 0.0481871 | AO12: 0.04791285 | AR12: Yes
B13: 1939 West Park Avenue | C13: 1939 West Park Avenue, Redlands, CA 92373 | D13: Redlands | E13: CA | F13: United States | G13: 92373 | H13: Industrial | I13: Warehouse | K13: No | L13: Inland Empire | M13: IE-East Redlands | N13: 21612 | O13: SF | P13: 44651 | Q13: 1 | R13: 5.96 | S13: $ | T13: 275.77 | V13: A- | W13: 0.03162073 | X13: Green Street Market Estimate | Y13: No | Z13: Scott Barnes | AA13: John C. Steinmann | AC13: No | AD13: CBRE Group | AE13: CBRE Group | AG13: 1 | AH13: 0 | AJ13: 2007 | AM13: 0.047 | AN13: 0.0481871 | AO13: 0.04791285 | AR13: Yes
B14: I-215 Commerce Center | C14: 1648 Ashley Way, Colton, CA 92324 | D14: Colton | E14: CA | F14: United States | G14: 92324 | H14: Industrial | I14: Warehouse | K14: No | L14: Inland Empire | M14: IE-East Redlands | N14: 225353 | O14: SF | P14: 44439 | Q14: 1 | R14: 57.5 | S14: $ | T14: 255.16 | V14: A- | W14: 0.028 | X14: As Reported | Y14: No | Z14: Zurich Alternative Asset Management | AA14: Transwestern Development Company | AC14: No | AE14: CBRE Group | AH14: 0 | AJ14: 2021 | AL14: 1 | AM14: 0.047 | AN14: 0.0481871 | AO14: 0.04791285 | AR14: Yes
B15: Washington Commerce Center | C15: 998 South Washington Avenue, San Bernardino, CA 92408 | D15: San Bernardino | E15: CA | F15: United States | G15: 92408 | H15: Industrial | I15: Warehouse | K15: No | L15: Inland Empire | M15: IE-East Redlands | N15: 574984 | O15: SF | P15: 44423 | Q15: 1 | S15: $ | T15: 164.53 | V15: A- | Y15: Yes | Z15: PGIM | AA15: Crow Holdings | AC15: No | AE15: Eastdil Secured | AH15: 0 | AM15: 0.047 | AN15: 0.0481871 | AO15: 0.04791285 | AR15: Yes
B16: Washington Commerce Center, Building 3 | C16: 998 South Washington Avenue, San Bernardino, CA 92408 | D16: San Bernardino | E16: CA | F16: United States | G16: 92408 | H16: Industrial | I16: Warehouse | K16: No | L16: Inland Empire | M16: IE-East Redlands | N16: 146800 | O16: SF | P16: 44423 | Q16: 1 | V16: A- | Y16: Yes | Z16: PGIM | AA16: Crow Holdings | AC16: No | AE16: Eastdil Secured | AH16: 0 | AM16: 0.047 | AN16: 0.0481871 | AO16: 0.04791285 | AR16: Yes
B17: Washington Commerce Center, Building 2 | C17: 975 South Washington Avenue, San Bernardino, CA 92408 | D17: San Bernardino | E17: CA | F17: United States | G17: 92408 | H17: Industrial | I17: Warehouse | K17: No | L17: Inland Empire | M17: IE-East Redlands | N17: 179584 | O17: SF | P17: 44423 | Q17: 1 | V17: A- | Y17: Yes | Z17: PGIM | AA17: Crow Holdings | AC17: No | AE17: Eastdil Secured | AH17: 0 | AM17: 0.047 | AN17: 0.0481871 | AO17: 0.04791285 | AR17: Yes
B18: Dedeaux Business Park Redlands | C18: 509 Alabama Street, Redlands, CA 92373 | D18: Redlands | E18: CA | F18: United States | G18: 92373 | H18: Industrial | I18: Warehouse | K18: No | L18: Inland Empire | M18: IE-East Redlands | N18: 74000 | O18: SF | P18: 44320 | Q18: 1 | R18: 16.9 | S18: $ | T18: 228.38 | V18: A- | W18: 0.0371 | X18: As Reported | Y18: No | Z18: LBA Realty | AA18: Brasa Capital; Dedeaux Properties | AC18: No | AD18: Cushman & Wakefield | AE18: Cushman & Wakefield; Lee & Associates | AH18: 0 | AM18: 0.047 | AN18: 0.0481871 | AO18: 0.04791285 | AR18: Yes
B19: 1255 Research Drive | C19: 1255 Research Drive, Redlands, CA 92374 | D19: Redlands | E19: CA | F19: United States | G19: 92374 | H19: Industrial | I19: Warehouse | K19: No | L19: Inland Empire | M19: IE-East Redlands | N19: 118000 | O19: SF | P19: 44295 | Q19: 1 | R19: 18.38 | S19: $ | T19: 155.72 | V19: A- | W19: 0.03612073 | X19: Green Street Market Estimate | Y19: No | Z19: EQT Exeter | AA19: Garner Holt Productions Inc. | AC19: No | AE19: Colliers | AH19: 0 | AM19: 0.047 | AN19: 0.0481871 | AO19: 0.04791285 | AR19: Yes
B20: Crow Holdings Los Angeles Area Industrial Portfolio | C20: 1070 South Waterman Avenue, San Bernardino, CA 92408 | D20: San Bernardino | E20: CA | F20: United States | G20: 92408 | H20: Industrial | I20: Warehouse | K20: No | L20: Inland Empire | M20: IE-East Redlands | N20: 591000 | O20: SF | P20: 44276 | Q20: 1 | S20: $ | T20: 155.77 | V20: A- | Y20: Yes | Z20: Principal Real Estate Investors | AA20: Crow Holdings | AC20: No | AE20: CBRE Group; Eastdil Secured | AH20: 0 | AM20: 0.047 | AN20: 0.0481871 | AO20: 0.04791285 | AR20: Yes
B21: 1070 South Waterman Avenue | C21: 1070 South Waterman Avenue, San Bernardino, CA 92408 | D21: San Bernardino | E21: CA | F21: United States | G21: 92408 | H21: Industrial | I21: Warehouse | K21: No | L21: Inland Empire | M21: IE-East Redlands | N21: 392000 | O21: SF | P21: 44276 | Q21: 1 | V21: A- | Y21: Yes | Z21: Principal Real Estate Investors | AA21: Crow Holdings | AC21: No | AE21: CBRE Group; Eastdil Secured | AH21: 0 | AM21: 0.047 | AN21: 0.0481871 | AO21: 0.04791285 | AR21: Yes
B22: Redlands Corporate Center 1&2 | C22: 1289 Bryn Mawr Avenue, Redlands, CA 92374 | D22: Redlands | E22: CA | F22: United States | G22: 92374 | H22: Office | I22: Warehouse | K22: No | L22: Inland Empire | M22: IE-East Redlands | N22: 287000 | O22: SF | P22: 44215 | Q22: 1 | S22: $ | T22: 141.46 | V22: A- | Y22: Yes | Z22: Penwood Real Estate Investment Management | AA22: Stockbridge Capital Group | AC22: No | AE22: CBRE Group | AH22: 0 | AJ22: 2003 | AM22: 0.047 | AN22: 0.0481871 | AO22: 0.04791285 | AR22: Yes
B23: Redlands Corporate Center 2 | C23: 1289 Bryn Mawr Avenue, Redlands, CA 92374 | D23: Redlands | E23: CA | F23: United States | G23: 92374 | H23: Industrial | I23: Warehouse | K23: No | L23: Inland Empire | M23: IE-East Redlands | N23: 39000 | O23: SF | P23: 44215 | Q23: 1 | V23: A- | Y23: Yes | Z23: Penwood Real Estate Investment Management | AA23: Stockbridge Capital Group | AC23: No | AE23: CBRE Group | AH23: 0 | AJ23: 2003 | AM23: 0.047 | AN23: 0.0481871 | AO23: 0.04791285 | AR23: Yes
B24: Redlands Corporate Center 1 | C24: 1115 Research Drive, Redlands, CA 92374 | D24: Redlands | E24: CA | F24: United States | G24: 92374 | H24: Industrial | I24: Warehouse | K24: No | L24: Inland Empire | M24: IE-East Redlands | N24: 31000 | O24: SF | P24: 44215 | Q24: 1 | V24: A- | Y24: Yes | Z24: Penwood Real Estate Investment Management | AA24: Stockbridge Capital Group | AC24: No | AE24: CBRE Group | AH24: 0 | AJ24: 1991 | AM24: 0.047 | AN24: 0.0481871 | AO24: 0.04791285 | AR24: Yes
B25: Hillwood Development Multi-state Industrial Portfolio (B) | C25: 1494 South Waterman Avenue, San Bernardino, CA 92408 | F25: United States | G25: 92408 | H25: Industrial | I25: Warehouse | K25: No | L25: Inland Empire | M25: IE-East Redlands | N25: 4287000 | O25: SF | P25: 44167 | Q25: 1 | S25: $ | T25: 107.89 | V25: A- | Y25: Yes | Z25: Stockbridge Capital Group | AA25: Hillwood Investment Properties | AC25: No | AE25: CBRE Group | AH25: 0 | AJ25: 2019 | AM25: 0.047 | AN25: 0.0481871 | AO25: 0.04791285 | AR25: Yes
B26: 1494 South Waterman Avenue | C26: 1494 South Waterman Avenue, San Bernardino, CA 92408 | D26: San Bernardino | E26: CA | F26: United States | G26: 92408 | H26: Industrial | I26: Warehouse | K26: No | L26: Inland Empire | M26: IE-East Redlands | N26: 1066000 | O26: SF | P26: 44167 | Q26: 1 | R26: 132.81 | S26: $ | T26: 124.58 | V26: A- | Y26: Yes | Z26: Stockbridge Capital Group | AA26: Hillwood Investment Properties | AC26: No | AE26: CBRE Group | AH26: 0 | AJ26: 2019 | AM26: 0.047 | AN26: 0.0481871 | AO26: 0.04791285 | AR26: Yes
B27: 1601&1603 Steel Road | C27: 1603 East Steel Road, Colton, CA 92324 | D27: Colton | E27: CA | F27: United States | G27: 92324 | H27: Industrial | I27: Warehouse | K27: No | L27: Inland Empire | M27: IE-East Redlands | N27: 331000 | O27: SF | P27: 44152 | Q27: 1 | R27: 46 | S27: $ | T27: 138.97 | V27: A- | W27: 0.04067045 | X27: Green Street Market Estimate | Y27: No | Z27: Brookfield Property Group | AC27: No | AD27: CBRE Group | AF27: 8.99 | AH27: 0 | AI27: 1 | AM27: 0.047 | AN27: 0.0481871 | AO27: 0.04791285 | AR27: Yes
B28: Redlands Corporate Center | C28: 1251 Research Drive, Redlands, CA 92374 | D28: Redlands | E28: CA | F28: United States | G28: 92374 | H28: Industrial | I28: Warehouse | K28: No | L28: Inland Empire | M28: IE-East Redlands | N28: 118000 | O28: SF | P28: 43899 | Q28: 1 | R28: 10.5 | S28: $ | T28: 88.98 | V28: A- | W28: 0.03912073 | X28: Green Street Market Estimate | Y28: No | Z28: Garner Holt Productions Inc. | AA28: Stockbridge Real Estate | AC28: No | AE28: Cushman & Wakefield | AH28: 0 | AM28: 0.047 | AN28: 0.0481871 | AO28: 0.04791285 | AR28: Yes
B29: 301 Tennessee Street | C29: 301 Tennessee Street, Redlands, CA 92373 | D29: Redlands | E29: CA | F29: United States | G29: 92373 | H29: Industrial | I29: Warehouse | K29: No | L29: Inland Empire | M29: IE-East Redlands | N29: 193000 | O29: SF | P29: 43861 | Q29: 1 | R29: 11.5 | S29: $ | T29: 59.59 | V29: A- | W29: 0.03912073 | X29: Green Street Market Estimate | Y29: No | AA29: La-Z-Boy Inc. | AC29: No | AE29: Savills | AH29: 0 | AM29: 0.047 | AN29: 0.0481871 | AO29: 0.04791285 | AR29: Yes
B30: 1730 Marigold Avenue | C30: 1730 Marigold Avenue, Redlands, CA 92374 | D30: Redlands | E30: CA | F30: United States | G30: 92374 | H30: Industrial | I30: Warehouse | K30: No | L30: Inland Empire | M30: IE-East Redlands | N30: 328000 | O30: SF | P30: 43830 | Q30: 1 | R30: 39.7 | S30: $ | T30: 121.04 | V30: A- | W30: 0.04062073 | X30: Green Street Market Estimate | Y30: No | Z30: Black Creek Group | AA30: Kensington Realty Advisors | AC30: No | AE30: Cushman & Wakefield | AF30: 15.368 | AH30: 0 | AI30: 1 | AM30: 0.047 | AN30: 0.0481871 | AO30: 0.04791285 | AR30: Yes
B31: Los Angeles Area Industrial Portfolio | C31: Redlands, CA | D31: Redlands | E31: CA | F31: United States | H31: Industrial | I31: Warehouse | J31: Park | K31: No | L31: Other | N31: 257000 | O31: SF | P31: 43818 | Q31: 1 | R31: 24.8 | S31: $ | T31: 96.5 | Y31: Yes | AC31: No | AE31: CBRE Group | AH31: 0 | AR31: Yes
B32: 1445 South Tippacanoe Avenue | C32: 1445 South Tippecanoe Avenue, San Bernardino, CA 92408 | D32: San Bernardino | E32: CA | F32: United States | G32: 92408 | H32: Industrial | I32: Warehouse | K32: No | L32: Inland Empire | M32: IE-East Redlands | N32: 344000 | O32: SF | P32: 43663 | Q32: 1 | R32: 43.1 | S32: $ | T32: 125.29 | V32: A- | W32: 0.04317045 | X32: Green Street Market Estimate | Y32: No | Z32: Nuveen Real Estate | AA32: Rockefeller Group | AC32: No | AE32: Cushman & Wakefield | AF32: 14.886 | AH32: 0 | AI32: 1 | AM32: 0.047 | AN32: 0.0481871 | AO32: 0.04791285 | AR32: Yes
B33: 1898 Marigold Avenue | C33: 1898 Marigold Avenue, Redlands, CA 92374 | D33: Redlands | E33: CA | F33: United States | G33: 92374 | H33: Industrial | I33: Warehouse | K33: No | L33: Inland Empire | M33: IE-East Redlands | N33: 290000 | O33: SF | P33: 43508 | Q33: 1 | R33: 31.29 | S33: $ | T33: 107.88 | V33: A- | W33: 0.04212073 | X33: Green Street Market Estimate | Y33: No | Z33: Liberty Property Trust | AC33: No | AE33: CBRE Group | AF33: 16 | AH33: 0 | AI33: 1 | AM33: 0.047 | AN33: 0.0481871 | AO33: 0.04791285 | AR33: Yes
B34: Cabot Properties National Industrial Portfolio | C34: 1833 Riverview Drive, San Bernardino, CA 92408 | F34: United States | G34: 92408 | H34: Industrial | I34: Warehouse | K34: No | L34: Inland Empire | M34: IE-East Redlands | N34: 21719000 | O34: SF | P34: 43172 | Q34: 1 | S34: $ | T34: 83.11 | V34: A- | Y34: Yes | Z34: Blackstone Real Estate Income Trust | AA34: Cabot Properties | AC34: No | AE34: CBRE Group; Eastdil Secured | AH34: 0 | AM34: 0.047 | AN34: 0.0481871 | AO34: 0.04791285 | AR34: Yes
B35: 1833 Riverview Dr | C35: 1833 Riverview Drive, San Bernardino, CA 92408 | D35: San Bernardino | E35: CA | F35: United States | G35: 92408 | H35: Industrial | I35: Warehouse | K35: No | L35: Inland Empire | M35: IE-East Redlands | N35: 44000 | O35: SF | P35: 43172 | Q35: 1 | V35: A- | Y35: Yes | Z35: Blackstone Real Estate Income Trust | AA35: Cabot Properties | AC35: No | AE35: CBRE Group; Eastdil Secured | AH35: 0 | AM35: 0.047 | AN35: 0.0481871 | AO35: 0.04791285 | AR35: Yes
B36: 1817 Riverview Dr | C36: 1817 Riverview Drive, San Bernardino, CA 92408 | D36: San Bernardino | E36: CA | F36: United States | G36: 92408 | H36: Industrial | I36: Warehouse | K36: No | L36: Inland Empire | M36: IE-East Redlands | N36: 40000 | O36: SF | P36: 43172 | Q36: 1 | V36: A- | Y36: Yes | Z36: Blackstone Real Estate Income Trust | AA36: Cabot Properties | AC36: No | AE36: CBRE Group; Eastdil Secured | AH36: 0 | AM36: 0.047 | AN36: 0.0481871 | AO36: 0.04791285 | AR36: Yes
B37: 1811 Riverview Dr | C37: 1811 Riverview Drive, San Bernardino, CA 92408 | D37: San Bernardino | E37: CA | F37: United States | G37: 92408 | H37: Industrial | I37: Warehouse | K37: No | L37: Inland Empire | M37: IE-East Redlands | N37: 60000 | O37: SF | P37: 43172 | Q37: 1 | V37: A- | Y37: Yes | Z37: Blackstone Real Estate Income Trust | AA37: Cabot Properties | AC37: No | AE37: CBRE Group; Eastdil Secured | AH37: 0 | AM37: 0.047 | AN37: 0.0481871 | AO37: 0.04791285 | AR37: Yes
B38: 1445-1455 E Riverview Dr | C38: 1445 Riverview Drive, San Bernardino, CA 92408 | D38: San Bernardino | E38: CA | F38: United States | G38: 92408 | H38: Industrial | I38: Warehouse | K38: No | L38: Inland Empire | M38: IE-East Redlands | N38: 117000 | O38: SF | P38: 43172 | Q38: 1 | V38: A- | Y38: Yes | Z38: Blackstone Real Estate Income Trust | AA38: Cabot Properties | AC38: No | AE38: CBRE Group; Eastdil Secured | AH38: 0 | AM38: 0.047 | AN38: 0.0481871 | AO38: 0.04791285 | AR38: Yes
B39: Redlands Gateway Logistics Center | C39: 9712 Alabama Street, Redlands, CA 92374 | D39: Redlands | E39: CA | F39: United States | G39: 92374 | H39: Industrial | I39: Warehouse | K39: No | L39: Inland Empire | M39: IE-East Redlands | N39: 928000 | O39: SF | P39: 43158 | Q39: 1 | R39: 100.5 | S39: $ | T39: 108.3 | V39: A- | W39: 0.04362073 | X39: Green Street Market Estimate | Y39: No | Z39: Alere Property Group | AA39: Crow Holdings | AC39: No | AE39: CBRE Group | AH39: 0 | AM39: 0.047 | AN39: 0.0481871 | AO39: 0.04791285 | AR39: Yes
B40: Hillwood Investment National Industrial Portfolio | C40: 555 East Orange Show Road, San Bernardino, CA 92408 | F40: United States | G40: 92408 | H40: Industrial | I40: Warehouse | K40: No | L40: Inland Empire | M40: IE-East Redlands | N40: 9116000 | O40: SF | P40: 42723 | Q40: 1 | S40: $ | T40: 73.68 | V40: A- | Y40: Yes | Z40: GLP | AA40: Hillwood Investment Properties | AC40: No | AE40: CBRE Group; Eastdil Secured | AH40: 0 | AM40: 0.047 | AN40: 0.0481871 | AO40: 0.04791285 | AR40: Yes
B41: 555 Orange Show Road | C41: 555 East Orange Show Road, San Bernardino, CA 92408 | D41: San Bernardino | E41: CA | F41: United States | G41: 92408 | H41: Industrial | I41: Warehouse | K41: No | L41: Inland Empire | M41: IE-East Redlands | N41: 1103000 | O41: SF | P41: 42723 | Q41: 1 | R41: 98.9 | S41: $ | T41: 89.66 | V41: A- | Y41: Yes | Z41: GLP | AA41: Hillwood Investment Properties | AC41: No | AE41: CBRE Group; Eastdil Secured | AH41: 0 | AM41: 0.047 | AN41: 0.0481871 | AO41: 0.04791285 | AR41: Yes
B42: AREA Property Multi-State Industrial Portfolio | C42: 2200 West San Bernardino Avenue, Redlands, CA 92374 | F42: United States | G42: 92374 | H42: Industrial | I42: Warehouse | K42: No | L42: Inland Empire | M42: IE-East Redlands | N42: 2858000 | O42: SF | P42: 42528 | Q42: 1 | S42: $ | T42: 65.61 | V42: A- | Y42: Yes | Z42: Industrial Property Trust | AA42: AREA Property Partners | AC42: No | AH42: 0 | AI42: 1 | AM42: 0.047 | AN42: 0.0481871 | AO42: 0.04791285 | AR42: Yes
...
