Workbook
Name analysis_start: #REF!
Name analysis_start: 'Redlands Inputs'!$D$14
Name market_rent: #REF!
Name market_rent: 'Redlands Inputs'!$D$25

Sheet Annual Projections
C1: year 1-5 | D1: year 6-10
A2: Market Rent Inflation | C2: 0.03 | D2: 0.022
A3: Expense Inflation | C3: 0.025
A4: Cash Flow Projections
A5: Redlands Industrial Property
B7: Actuals | C7: Forecast | D7: Forecast | E7: Forecast | F7: Forecast | G7: Forecast | H7: Forecast | I7: Forecast | J7: Forecast | K7: Forecast | L7: Forecast | M7: Forecast
B8: =ROUNDUP(B$9/12,0) -> 0 | C8: 1 | D8: =C8+1 -> 2 | E8: =D8+1 -> 3 | F8: =E8+1 -> 4 | G8: =F8+1 -> 5 | H8: =G8+1 -> 6 | I8: =H8+1 -> 7 | J8: =I8+1 -> 8 | K8: =J8+1 -> 9 | ... M8: =L8+1 -> 11
A10: Months | B10: =EOMONTH(C10,-12) -> 45322 | C10: =EOMONTH('Redlands Inputs'!D14,0) -> 45688 | D10: =EOMONTH(C10,12) -> 46053 | E10: =EOMONTH(D10,12) -> 46418 | F10: =EOMONTH(E10,12) -> 46783 | G10: =EOMONTH(F10,12) -> 47149 | H10: =EOMONTH(G10,12) -> 47514 | I10: =EOMONTH(H10,12) -> 47879 | J10: =EOMONTH(I10,12) -> 48244 | K10: =EOMONTH(J10,12) -> 48610 | ... M10: =EOMONTH(L10,12) -> 49340
A12: Rental Revenue
A13: Base Rent / SF | B13: =SUMIF('Redlands Pro Forma'!$B$8:$ED$8,'Annual Projections'!B$8,'Redlands Pro Forma'!$B13:$ED13) -> 0 | C13: =SUMIF('Redlands Pro Forma'!$B$8:$ED$8,'Annual Projections'!C$8,'Redlands Pro Forma'!$B13:$ED13) -> 77.997314 | D13: =SUMIF('Redlands Pro Forma'!$B$8:$ED$8,'Annual Projections'!D$8,'Redlands Pro Forma'!$B13:$ED13) -> 79.55726 | E13: =SUMIF('Redlands Pro Forma'!$B$8:$ED$8,'Annual Projections'!E$8,'Redlands Pro Forma'!$B13:$ED13) -> 81.148406 | F13: =SUMIF('Redlands Pro Forma'!$B$8:$ED$8,'Annual Projections'!F$8,'Redlands Pro Forma'!$B13:$ED13) -> 82.771374 | G13: =SUMIF('Redlands Pro Forma'!$B$8:$ED$8,'Annual Projections'!G$8,'Redlands Pro Forma'!$B13:$ED13) -> 84.426801 | H13: =SUMIF('Redlands Pro Forma'!$B$8:$ED$8,'Annual Projections'!H$8,'Redlands Pro Forma'!$B13:$ED13) -> 86.115337 | I13: =SUMIF('Redlands Pro Forma'!$B$8:$ED$8,'Annual Projections'!I$8,'Redlands Pro Forma'!$B13:$ED13) -> 87.837644 | ... M13: =SUMIF('Redlands Pro Forma'!$B$8:$ED$8,'Annual Projections'!M$8,'Redlands Pro Forma'!$B13:$ED13) -> 138.24913
A14: Potential Base Rent | B14: =SUMIF('Redlands Pro Forma'!$B$8:$ED$8,'Annual Projections'!B$8,'Redlands Pro Forma'!$B14:$ED14) -> 0 | C14: =SUMIF('Redlands Pro Forma'!$B$8:$ED$8,'Annual Projections'!C$8,'Redlands Pro Forma'!$B14:$ED14) -> 3899865.7 | D14: =SUMIF('Redlands Pro Forma'!$B$8:$ED$8,'Annual Projections'!D$8,'Redlands Pro Forma'!$B14:$ED14) -> 3977863 | E14: =SUMIF('Redlands Pro Forma'!$B$8:$ED$8,'Annual Projections'!E$8,'Redlands Pro Forma'!$B14:$ED14) -> 4057420.3 | F14: =SUMIF('Redlands Pro Forma'!$B$8:$ED$8,'Annual Projections'!F$8,'Redlands Pro Forma'!$B14:$ED14) -> 4138568.7 | G14: =SUMIF('Redlands Pro Forma'!$B$8:$ED$8,'Annual Projections'!G$8,'Redlands Pro Forma'!$B14:$ED14) -> 4221340.1 | H14: =SUMIF('Redlands Pro Forma'!$B$8:$ED$8,'Annual Projections'!H$8,'Redlands Pro Forma'!$B14:$ED14) -> 4305766.9 | I14: =SUMIF('Redlands Pro Forma'!$B$8:$ED$8,'Annual Projections'!I$8,'Redlands Pro Forma'!$B14:$ED14) -> 4391882.2 | ... M14: =SUMIF('Redlands Pro Forma'!$B$8:$ED$8,'Annual Projections'!M$8,'Redlands Pro Forma'!$B14:$ED14) -> 6912456.5
A15: Vacancy & Turnover | C15: =SUMIF('Redlands Pro Forma'!$B$8:$ED$8,'Annual Projections'!C$8,'Redlands Pro Forma'!$B15:$ED15) -> 0 | D15: =SUMIF('Redlands Pro Forma'!$B$8:$ED$8,'Annual Projections'!D$8,'Redlands Pro Forma'!$B15:$ED15) -> 0 | E15: =SUMIF('Redlands Pro Forma'!$B$8:$ED$8,'Annual Projections'!E$8,'Redlands Pro Forma'!$B15:$ED15) -> 0 | F15: =SUMIF('Redlands Pro Forma'!$B$8:$ED$8,'Annual Projections'!F$8,'Redlands Pro Forma'!$B15:$ED15) -> 0 | G15: =SUMIF('Redlands Pro Forma'!$B$8:$ED$8,'Annual Projections'!G$8,'Redlands Pro Forma'!$B15:$ED15) -> 0 | H15: =SUMIF('Redlands Pro Forma'!$B$8:$ED$8,'Annual Projections'!H$8,'Redlands Pro Forma'!$B15:$ED15) -> 0 | I15: =SUMIF('Redlands Pro Forma'!$B$8:$ED$8,'Annual Projections'!I$8,'Redlands Pro Forma'!$B15:$ED15) -> 0 | J15: =SUMIF('Redlands Pro Forma'!$B$8:$ED$8,'Annual Projections'!J$8,'Redlands Pro Forma'!$B15:$ED15) -> 0 | ... M15: =SUMIF('Redlands Pro Forma'!$B$8:$ED$8,'Annual Projections'!M$8,'Redlands Pro Forma'!$B15:$ED15) -> 0
A16: Free Rent / Concessions | C16: =SUMIF('Redlands Pro Forma'!$B$8:$ED$8,'Annual Projections'!C$8,'Redlands Pro Forma'!$B16:$ED16) -> 0 | D16: =SUMIF('Redlands Pro Forma'!$B$8:$ED$8,'Annual Projections'!D$8,'Redlands Pro Forma'!$B16:$ED16) -> 0 | E16: =SUMIF('Redlands Pro Forma'!$B$8:$ED$8,'Annual Projections'!E$8,'Redlands Pro Forma'!$B16:$ED16) -> 0 | F16: =SUMIF('Redlands Pro Forma'!$B$8:$ED$8,'Annual Projections'!F$8,'Redlands Pro Forma'!$B16:$ED16) -> 0 | G16: =SUMIF('Redlands Pro Forma'!$B$8:$ED$8,'Annual Projections'!G$8,'Redlands Pro Forma'!$B16:$ED16) -> 0 | H16: =SUMIF('Redlands Pro Forma'!$B$8:$ED$8,'Annual Projections'!H$8,'Redlands Pro Forma'!$B16:$ED16) -> 0 | I16: =SUMIF('Redlands Pro Forma'!$B$8:$ED$8,'Annual Projections'!I$8,'Redlands Pro Forma'!$B16:$ED16) -> 0 | J16: =SUMIF('Redlands Pro Forma'!$B$8:$ED$8,'Annual Projections'!J$8,'Redlands Pro Forma'!$B16:$ED16) -> 0 | ... M16: =SUMIF('Redlands Pro Forma'!$B$8:$ED$8,'Annual Projections'!M$8,'Redlands Pro Forma'!$B16:$ED16) -> 0
A17: Total Base Rent | C17: =SUMIF('Redlands Pro Forma'!$B$8:$ED$8,'Annual Projections'!C$8,'Redlands Pro Forma'!$B17:$ED17) -> 3899865.7 | D17: =SUMIF('Redlands Pro Forma'!$B$8:$ED$8,'Annual Projections'!D$8,'Redlands Pro Forma'!$B17:$ED17) -> 3977863 | E17: =SUMIF('Redlands Pro Forma'!$B$8:$ED$8,'Annual Projections'!E$8,'Redlands Pro Forma'!$B17:$ED17) -> 4057420.3 | F17: =SUMIF('Redlands Pro Forma'!$B$8:$ED$8,'Annual Projections'!F$8,'Redlands Pro Forma'!$B17:$ED17) -> 4138568.7 | G17: =SUMIF('Redlands Pro Forma'!$B$8:$ED$8,'Annual Projections'!G$8,'Redlands Pro Forma'!$B17:$ED17) -> 4221340.1 | H17: =SUMIF('Redlands Pro Forma'!$B$8:$ED$8,'Annual Projections'!H$8,'Redlands Pro Forma'!$B17:$ED17) -> 4305766.9 | I17: =SUMIF('Redlands Pro Forma'!$B$8:$ED$8,'Annual Projections'!I$8,'Redlands Pro Forma'!$B17:$ED17) -> 4391882.2 | J17: =SUMIF('Redlands Pro Forma'!$B$8:$ED$8,'Annual Projections'!J$8,'Redlands Pro Forma'!$B17:$ED17) -> 6257304.5 | ... M17: =SUMIF('Redlands Pro Forma'!$B$8:$ED$8,'Annual Projections'!M$8,'Redlands Pro Forma'!$B17:$ED17) -> 6912456.5
A18: Total Rental Revenue | C18: =SUMIF('Redlands Pro Forma'!$B$8:$ED$8,'Annual Projections'!C$8,'Redlands Pro Forma'!$B18:$ED18) -> 3899865.7 | D18: =SUMIF('Redlands Pro Forma'!$B$8:$ED$8,'Annual Projections'!D$8,'Redlands Pro Forma'!$B18:$ED18) -> 3977863 | E18: =SUMIF('Redlands Pro Forma'!$B$8:$ED$8,'Annual Projections'!E$8,'Redlands Pro Forma'!$B18:$ED18) -> 4057420.3 | F18: =SUMIF('Redlands Pro Forma'!$B$8:$ED$8,'Annual Projections'!F$8,'Redlands Pro Forma'!$B18:$ED18) -> 4138568.7 | G18: =SUMIF('Redlands Pro Forma'!$B$8:$ED$8,'Annual Projections'!G$8,'Redlands Pro Forma'!$B18:$ED18) -> 4221340.1 | H18: =SUMIF('Redlands Pro Forma'!$B$8:$ED$8,'Annual Projections'!H$8,'Redlands Pro Forma'!$B18:$ED18) -> 4305766.9 | I18: =SUMIF('Redlands Pro Forma'!$B$8:$ED$8,'Annual Projections'!I$8,'Redlands Pro Forma'!$B18:$ED18) -> 4391882.2 | J18: =SUMIF('Redlands Pro Forma'!$B$8:$ED$8,'Annual Projections'!J$8,'Redlands Pro Forma'!$B18:$ED18) -> 6257304.5 | ... M18: =SUMIF('Redlands Pro Forma'!$B$8:$ED$8,'Annual Projections'!M$8,'Redlands Pro Forma'!$B18:$ED18) -> 6912456.5
A20: Other Tenant Revenue
A21: Utilities | C21: =SUMIF('Redlands Pro Forma'!$B$8:$ED$8,'Annual Projections'!C$8,'Redlands Pro Forma'!$B21:$ED21) -> 45000 | D21: =SUMIF('Redlands Pro Forma'!$B$8:$ED$8,'Annual Projections'!D$8,'Redlands Pro Forma'!$B21:$ED21) -> 45000 | E21: =SUMIF('Redlands Pro Forma'!$B$8:$ED$8,'Annual Projections'!E$8,'Redlands Pro Forma'!$B21:$ED21) -> 45000 | F21: =SUMIF('Redlands Pro Forma'!$B$8:$ED$8,'Annual Projections'!F$8,'Redlands Pro Forma'!$B21:$ED21) -> 45000 | G21: =SUMIF('Redlands Pro Forma'!$B$8:$ED$8,'Annual Projections'!G$8,'Redlands Pro Forma'!$B21:$ED21) -> 45000 | H21: =SUMIF('Redlands Pro Forma'!$B$8:$ED$8,'Annual Projections'!H$8,'Redlands Pro Forma'!$B21:$ED21) -> 45000 | I21: =SUMIF('Redlands Pro Forma'!$B$8:$ED$8,'Annual Projections'!I$8,'Redlands Pro Forma'!$B21:$ED21) -> 45000 | J21: =SUMIF('Redlands Pro Forma'!$B$8:$ED$8,'Annual Projections'!J$8,'Redlands Pro Forma'!$B21:$ED21) -> 45000 | ... M21: =SUMIF('Redlands Pro Forma'!$B$8:$ED$8,'Annual Projections'!M$8,'Redlands Pro Forma'!$B21:$ED21) -> 45000
A22: Repairs & Maintenance | C22: =SUMIF('Redlands Pro Forma'!$B$8:$ED$8,'Annual Projections'!C$8,'Redlands Pro Forma'!$B22:$ED22) -> 45000 | D22: =SUMIF('Redlands Pro Forma'!$B$8:$ED$8,'Annual Projections'!D$8,'Redlands Pro Forma'!$B22:$ED22) -> 45000 | E22: =SUMIF('Redlands Pro Forma'!$B$8:$ED$8,'Annual Projections'!E$8,'Redlands Pro Forma'!$B22:$ED22) -> 45000 | F22: =SUMIF('Redlands Pro Forma'!$B$8:$ED$8,'Annual Projections'!F$8,'Redlands Pro Forma'!$B22:$ED22) -> 45000 | G22: =SUMIF('Redlands Pro Forma'!$B$8:$ED$8,'Annual Projections'!G$8,'Redlands Pro Forma'!$B22:$ED22) -> 45000 | H22: =SUMIF('Redlands Pro Forma'!$B$8:$ED$8,'Annual Projections'!H$8,'Redlands Pro Forma'!$B22:$ED22) -> 45000 | I22: =SUMIF('Redlands Pro Forma'!$B$8:$ED$8,'Annual Projections'!I$8,'Redlands Pro Forma'!$B22:$ED22) -> 45000 | J22: =SUMIF('Redlands Pro Forma'!$B$8:$ED$8,'Annual Projections'!J$8,'Redlands Pro Forma'!$B22:$ED22) -> 45000 | ... M22: =SUMIF('Redlands Pro Forma'!$B$8:$ED$8,'Annual Projections'!M$8,'Redlands Pro Forma'!$B22:$ED22) -> 45000
A23: Insurance | C23: =SUMIF('Redlands Pro Forma'!$B$8:$ED$8,'Annual Projections'!C$8,'Redlands Pro Forma'!$B23:$ED23) -> 20000 | D23: =SUMIF('Redlands Pro Forma'!$B$8:$ED$8,'Annual Projections'!D$8,'Redlands Pro Forma'!$B23:$ED23) -> 20000 | E23: =SUMIF('Redlands Pro Forma'!$B$8:$ED$8,'Annual Projections'!E$8,'Redlands Pro Forma'!$B23:$ED23) -> 20000 | F23: =SUMIF('Redlands Pro Forma'!$B$8:$ED$8,'Annual Projections'!F$8,'Redlands Pro Forma'!$B23:$ED23) -> 20000 | G23: =SUMIF('Redlands Pro Forma'!$B$8:$ED$8,'Annual Projections'!G$8,'Redlands Pro Forma'!$B23:$ED23) -> 20000 | H23: =SUMIF('Redlands Pro Forma'!$B$8:$ED$8,'Annual Projections'!H$8,'Redlands Pro Forma'!$B23:$ED23) -> 20000 | I23: =SUMIF('Redlands Pro Forma'!$B$8:$ED$8,'Annual Projections'!I$8,'Redlands Pro Forma'!$B23:$ED23) -> 20000 | J23: =SUMIF('Redlands Pro Forma'!$B$8:$ED$8,'Annual Projections'!J$8,'Redlands Pro Forma'!$B23:$ED23) -> 20000 | ... M23: =SUMIF('Redlands Pro Forma'!$B$8:$ED$8,'Annual Projections'!M$8,'Redlands Pro Forma'!$B23:$ED23) -> 20000
A24: Property Taxes | C24: =SUMIF('Redlands Pro Forma'!$B$8:$ED$8,'Annual Projections'!C$8,'Redlands Pro Forma'!$B24:$ED24) -> 150000 | D24: =SUMIF('Redlands Pro Forma'!$B$8:$ED$8,'Annual Projections'!D$8,'Redlands Pro Forma'!$B24:$ED24) -> 153000 | E24: =SUMIF('Redlands Pro Forma'!$B$8:$ED$8,'Annual Projections'!E$8,'Redlands Pro Forma'!$B24:$ED24) -> 156060 | F24: =SUMIF('Redlands Pro Forma'!$B$8:$ED$8,'Annual Projections'!F$8,'Redlands Pro Forma'!$B24:$ED24) -> 159181.2 | G24: =SUMIF('Redlands Pro Forma'!$B$8:$ED$8,'Annual Projections'!G$8,'Redlands Pro Forma'!$B24:$ED24) -> 162364.82 | H24: =SUMIF('Redlands Pro Forma'!$B$8:$ED$8,'Annual Projections'!H$8,'Redlands Pro Forma'!$B24:$ED24) -> 165612.12 | I24: =SUMIF('Redlands Pro Forma'!$B$8:$ED$8,'Annual Projections'!I$8,'Redlands Pro Forma'!$B24:$ED24) -> 168924.36 | J24: =SUMIF('Redlands Pro Forma'!$B$8:$ED$8,'Annual Projections'!J$8,'Redlands Pro Forma'!$B24:$ED24) -> 850119.29 | ... M24: =SUMIF('Redlands Pro Forma'!$B$8:$ED$8,'Annual Projections'!M$8,'Redlands Pro Forma'!$B24:$ED24) -> 902153.39
A25: Total Expense Recoveries | C25: =SUMIF('Redlands Pro Forma'!$B$8:$ED$8,'Annual Projections'!C$8,'Redlands Pro Forma'!$B25:$ED25) -> 260000 | D25: =SUMIF('Redlands Pro Forma'!$B$8:$ED$8,'Annual Projections'!D$8,'Redlands Pro Forma'!$B25:$ED25) -> 263000 | E25: =SUMIF('Redlands Pro Forma'!$B$8:$ED$8,'Annual Projections'!E$8,'Redlands Pro Forma'!$B25:$ED25) -> 266060 | F25: =SUMIF('Redlands Pro Forma'!$B$8:$ED$8,'Annual Projections'!F$8,'Redlands Pro Forma'!$B25:$ED25) -> 269181.2 | G25: =SUMIF('Redlands Pro Forma'!$B$8:$ED$8,'Annual Projections'!G$8,'Redlands Pro Forma'!$B25:$ED25) -> 272364.82 | H25: =SUMIF('Redlands Pro Forma'!$B$8:$ED$8,'Annual Projections'!H$8,'Redlands Pro Forma'!$B25:$ED25) -> 275612.12 | I25: =SUMIF('Redlands Pro Forma'!$B$8:$ED$8,'Annual Projections'!I$8,'Redlands Pro Forma'!$B25:$ED25) -> 278924.36 | J25: =SUMIF('Redlands Pro Forma'!$B$8:$ED$8,'Annual Projections'!J$8,'Redlands Pro Forma'!$B25:$ED25) -> 960119.29 | ... M25: =SUMIF('Redlands Pro Forma'!$B$8:$ED$8,'Annual Projections'!M$8,'Redlands Pro Forma'!$B25:$ED25) -> 1012153.4
A26: Total Other Tenant Revenue | C26: =SUMIF('Redlands Pro Forma'!$B$8:$ED$8,'Annual Projections'!C$8,'Redlands Pro Forma'!$B26:$ED26) -> 260000 | D26: =SUMIF('Redlands Pro Forma'!$B$8:$ED$8,'Annual Projections'!D$8,'Redlands Pro Forma'!$B26:$ED26) -> 263000 | E26: =SUMIF('Redlands Pro Forma'!$B$8:$ED$8,'Annual Projections'!E$8,'Redlands Pro Forma'!$B26:$ED26) -> 266060 | F26: =SUMIF('Redlands Pro Forma'!$B$8:$ED$8,'Annual Projections'!F$8,'Redlands Pro Forma'!$B26:$ED26) -> 269181.2 | G26: =SUMIF('Redlands Pro Forma'!$B$8:$ED$8,'Annual Projections'!G$8,'Redlands Pro Forma'!$B26:$ED26) -> 272364.82 | H26: =SUMIF('Redlands Pro Forma'!$B$8:$ED$8,'Annual Projections'!H$8,'Redlands Pro Forma'!$B26:$ED26) -> 275612.12 | I26: =SUMIF('Redlands Pro Forma'!$B$8:$ED$8,'Annual Projections'!I$8,'Redlands Pro Forma'!$B26:$ED26) -> 278924.36 | J26: =SUMIF('Redlands Pro Forma'!$B$8:$ED$8,'Annual Projections'!J$8,'Redlands Pro Forma'!$B26:$ED26) -> 960119.29 | ... M26: =SUMIF('Redlands Pro Forma'!$B$8:$ED$8,'Annual Projections'!M$8,'Redlands Pro Forma'!$B26:$ED26) -> 1012153.4
C27: =SUMIF('Redlands Pro Forma'!$B$8:$ED$8,'Annual Projections'!C$8,'Redlands Pro Forma'!$B27:$ED27) -> 0 | D27: =SUMIF('Redlands Pro Forma'!$B$8:$ED$8,'Annual Projections'!D$8,'Redlands Pro Forma'!$B27:$ED27) -> 0 | E27: =SUMIF('Redlands Pro Forma'!$B$8:$ED$8,'Annual Projections'!E$8,'Redlands Pro Forma'!$B27:$ED27) -> 0 | F27: =SUMIF('Redlands Pro Forma'!$B$8:$ED$8,'Annual Projections'!F$8,'Redlands Pro Forma'!$B27:$ED27) -> 0 | G27: =SUMIF('Redlands Pro Forma'!$B$8:$ED$8,'Annual Projections'!G$8,'Redlands Pro Forma'!$B27:$ED27) -> 0 | H27: =SUMIF('Redlands Pro Forma'!$B$8:$ED$8,'Annual Projections'!H$8,'Redlands Pro Forma'!$B27:$ED27) -> 0 | I27: =SUMIF('Redlands Pro Forma'!$B$8:$ED$8,'Annual Projections'!I$8,'Redlands Pro Forma'!$B27:$ED27) -> 0 | J27: =SUMIF('Redlands Pro Forma'!$B$8:$ED$8,'Annual Projections'!J$8,'Redlands Pro Forma'!$B27:$ED27) -> 0 | ... M27: =SUMIF('Redlands Pro Forma'!$B$8:$ED$8,'Annual Projections'!M$8,'Redlands Pro Forma'!$B27:$ED27) -> 0
A28: Total Tenant Revenue | C28: =SUMIF('Redlands Pro Forma'!$B$8:$ED$8,'Annual Projections'!C$8,'Redlands Pro Forma'!$B28:$ED28) -> 4159865.7 | D28: =SUMIF('Redlands Pro Forma'!$B$8:$ED$8,'Annual Projections'!D$8,'Redlands Pro Forma'!$B28:$ED28) -> 4240863 | E28: =SUMIF('Redlands Pro Forma'!$B$8:$ED$8,'Annual Projections'!E$8,'Redlands Pro Forma'!$B28:$ED28) -> 4323480.3 | F28: =SUMIF('Redlands Pro Forma'!$B$8:$ED$8,'Annual Projections'!F$8,'Redlands Pro Forma'!$B28:$ED28) -> 4407749.9 | G28: =SUMIF('Redlands Pro Forma'!$B$8:$ED$8,'Annual Projections'!G$8,'Redlands Pro Forma'!$B28:$ED28) -> 4493704.9 | H28: =SUMIF('Redlands Pro Forma'!$B$8:$ED$8,'Annual Projections'!H$8,'Redlands Pro Forma'!$B28:$ED28) -> 4581379 | I28: =SUMIF('Redlands Pro Forma'!$B$8:$ED$8,'Annual Projections'!I$8,'Redlands Pro Forma'!$B28:$ED28) -> 4670806.6 | J28: =SUMIF('Redlands Pro Forma'!$B$8:$ED$8,'Annual Projections'!J$8,'Redlands Pro Forma'!$B28:$ED28) -> 7217423.8 | ... M28: =SUMIF('Redlands Pro Forma'!$B$8:$ED$8,'Annual Projections'!M$8,'Redlands Pro Forma'!$B28:$ED28) -> 7924609.9
A30: Potential Gross Revenue | C30: =SUMIF('Redlands Pro Forma'!$B$8:$ED$8,'Annual Projections'!C$8,'Redlands Pro Forma'!$B30:$ED30) -> 4159865.7 | D30: =SUMIF('Redlands Pro Forma'!$B$8:$ED$8,'Annual Projections'!D$8,'Redlands Pro Forma'!$B30:$ED30) -> 4240863 | E30: =SUMIF('Redlands Pro Forma'!$B$8:$ED$8,'Annual Projections'!E$8,'Redlands Pro Forma'!$B30:$ED30) -> 4323480.3 | F30: =SUMIF('Redlands Pro Forma'!$B$8:$ED$8,'Annual Projections'!F$8,'Redlands Pro Forma'!$B30:$ED30) -> 4407749.9 | G30: =SUMIF('Redlands Pro Forma'!$B$8:$ED$8,'Annual Projections'!G$8,'Redlands Pro Forma'!$B30:$ED30) -> 4493704.9 | H30: =SUMIF('Redlands Pro Forma'!$B$8:$ED$8,'Annual Projections'!H$8,'Redlands Pro Forma'!$B30:$ED30) -> 4581379 | I30: =SUMIF('Redlands Pro Forma'!$B$8:$ED$8,'Annual Projections'!I$8,'Redlands Pro Forma'!$B30:$ED30) -> 4670806.6 | J30: =SUMIF('Redlands Pro Forma'!$B$8:$ED$8,'Annual Projections'!J$8,'Redlands Pro Forma'!$B30:$ED30) -> 7217423.8 | ... M30: =SUMIF('Redlands Pro Forma'!$B$8:$ED$8,'Annual Projections'!M$8,'Redlands Pro Forma'!$B30:$ED30) -> 7924609.9
C31: =SUMIF('Redlands Pro Forma'!$B$8:$ED$8,'Annual Projections'!C$8,'Redlands Pro Forma'!$B31:$ED31) -> 0 | D31: =SUMIF('Redlands Pro Forma'!$B$8:$ED$8,'Annual Projections'!D$8,'Redlands Pro Forma'!$B31:$ED31) -> 0 | E31: =SUMIF('Redlands Pro Forma'!$B$8:$ED$8,'Annual Projections'!E$8,'Redlands Pro Forma'!$B31:$ED31) -> 0 | F31: =SUMIF('Redlands Pro Forma'!$B$8:$ED$8,'Annual Projections'!F$8,'Redlands Pro Forma'!$B31:$ED31) -> 0 | G31: =SUMIF('Redlands Pro Forma'!$B$8:$ED$8,'Annual Projections'!G$8,'Redlands Pro Forma'!$B31:$ED31) -> 0 | H31: =SUMIF('Redlands Pro Forma'!$B$8:$ED$8,'Annual Projections'!H$8,'Redlands Pro Forma'!$B31:$ED31) -> 0 | I31: =SUMIF('Redlands Pro Forma'!$B$8:$ED$8,'Annual Projections'!I$8,'Redlands Pro Forma'!$B31:$ED31) -> 0 | J31: =SUMIF('Redlands Pro Forma'!$B$8:$ED$8,'Annual Projections'!J$8,'Redlands Pro Forma'!$B31:$ED31) -> 0 | ... M31: =SUMIF('Redlands Pro Forma'!$B$8:$ED$8,'Annual Projections'!M$8,'Redlands Pro Forma'!$B31:$ED31) -> 0
A32: Vacancy & Loss to Lease | C32: =SUMIF('Redlands Pro Forma'!$B$8:$ED$8,'Annual Projections'!C$8,'Redlands Pro Forma'!$B32:$ED32) -> 0 | D32: =SUMIF('Redlands Pro Forma'!$B$8:$ED$8,'Annual Projections'!D$8,'Redlands Pro Forma'!$B32:$ED32) -> 0 | E32: =SUMIF('Redlands Pro Forma'!$B$8:$ED$8,'Annual Projections'!E$8,'Redlands Pro Forma'!$B32:$ED32) -> 0 | F32: =SUMIF('Redlands Pro Forma'!$B$8:$ED$8,'Annual Projections'!F$8,'Redlands Pro Forma'!$B32:$ED32) -> 0 | G32: =SUMIF('Redlands Pro Forma'!$B$8:$ED$8,'Annual Projections'!G$8,'Redlands Pro Forma'!$B32:$ED32) -> 0 | H32: =SUMIF('Redlands Pro Forma'!$B$8:$ED$8,'Annual Projections'!H$8,'Redlands Pro Forma'!$B32:$ED32) -> 0 | I32: =SUMIF('Redlands Pro Forma'!$B$8:$ED$8,'Annual Projections'!I$8,'Redlands Pro Forma'!$B32:$ED32) -> 0 | J32: =SUMIF('Redlands Pro Forma'!$B$8:$ED$8,'Annual Projections'!J$8,'Redlands Pro Forma'!$B32:$ED32) -> 0 | ... M32: =SUMIF('Redlands Pro Forma'!$B$8:$ED$8,'Annual Projections'!M$8,'Redlands Pro Forma'!$B32:$ED32) -> 0
A33: Vacancy & L2L | C33: =SUMIF('Redlands Pro Forma'!$B$8:$ED$8,'Annual Projections'!C$8,'Redlands Pro Forma'!$B33:$ED33) -> -415986.57 | D33: =SUMIF('Redlands Pro Forma'!$B$8:$ED$8,'Annual Projections'!D$8,'Redlands Pro Forma'!$B33:$ED33) -> -424086.3 | E33: =SUMIF('Redlands Pro Forma'!$B$8:$ED$8,'Annual Projections'!E$8,'Redlands Pro Forma'!$B33:$ED33) -> -432348.03 | F33: =SUMIF('Redlands Pro Forma'!$B$8:$ED$8,'Annual Projections'!F$8,'Redlands Pro Forma'!$B33:$ED33) -> -440774.99 | G33: =SUMIF('Redlands Pro Forma'!$B$8:$ED$8,'Annual Projections'!G$8,'Redlands Pro Forma'!$B33:$ED33) -> -449370.49 | H33: =SUMIF('Redlands Pro Forma'!$B$8:$ED$8,'Annual Projections'!H$8,'Redlands Pro Forma'!$B33:$ED33) -> -458137.9 | I33: =SUMIF('Redlands Pro Forma'!$B$8:$ED$8,'Annual Projections'!I$8,'Redlands Pro Forma'!$B33:$ED33) -> -467080.66 | J33: =SUMIF('Redlands Pro Forma'!$B$8:$ED$8,'Annual Projections'!J$8,'Redlands Pro Forma'!$B33:$ED33) -> -721742.38 | ... M33: =SUMIF('Redlands Pro Forma'!$B$8:$ED$8,'Annual Projections'!M$8,'Redlands Pro Forma'!$B33:$ED33) -> -792460.99
A34: Total Vacancy & Credit Loss | C34: =SUMIF('Redlands Pro Forma'!$B$8:$ED$8,'Annual Projections'!C$8,'Redlands Pro Forma'!$B34:$ED34) -> -415986.57 | D34: =SUMIF('Redlands Pro Forma'!$B$8:$ED$8,'Annual Projections'!D$8,'Redlands Pro Forma'!$B34:$ED34) -> -424086.3 | E34: =SUMIF('Redlands Pro Forma'!$B$8:$ED$8,'Annual Projections'!E$8,'Redlands Pro Forma'!$B34:$ED34) -> -432348.03 | F34: =SUMIF('Redlands Pro Forma'!$B$8:$ED$8,'Annual Projections'!F$8,'Redlands Pro Forma'!$B34:$ED34) -> -440774.99 | G34: =SUMIF('Redlands Pro Forma'!$B$8:$ED$8,'Annual Projections'!G$8,'Redlands Pro Forma'!$B34:$ED34) -> -449370.49 | H34: =SUMIF('Redlands Pro Forma'!$B$8:$ED$8,'Annual Projections'!H$8,'Redlands Pro Forma'!$B34:$ED34) -> -458137.9 | I34: =SUMIF('Redlands Pro Forma'!$B$8:$ED$8,'Annual Projections'!I$8,'Redlands Pro Forma'!$B34:$ED34) -> -467080.66 | J34: =SUMIF('Redlands Pro Forma'!$B$8:$ED$8,'Annual Projections'!J$8,'Redlands Pro Forma'!$B34:$ED34) -> -721742.38 | ... M34: =SUMIF('Redlands Pro Forma'!$B$8:$ED$8,'Annual Projections'!M$8,'Redlands Pro Forma'!$B34:$ED34) -> -792460.99
A36: Effective Gross Revenue | C36: =SUMIF('Redlands Pro Forma'!$B$8:$ED$8,'Annual Projections'!C$8,'Redlands Pro Forma'!$B36:$ED36) -> 3743879.1 | D36: =SUMIF('Redlands Pro Forma'!$B$8:$ED$8,'Annual Projections'!D$8,'Redlands Pro Forma'!$B36:$ED36) -> 3816776.7 | E36: =SUMIF('Redlands Pro Forma'!$B$8:$ED$8,'Annual Projections'!E$8,'Redlands Pro Forma'!$B36:$ED36) -> 3891132.2 | F36: =SUMIF('Redlands Pro Forma'!$B$8:$ED$8,'Annual Projections'!F$8,'Redlands Pro Forma'!$B36:$ED36) -> 3966974.9 | G36: =SUMIF('Redlands Pro Forma'!$B$8:$ED$8,'Annual Projections'!G$8,'Redlands Pro Forma'!$B36:$ED36) -> 4044334.4 | H36: =SUMIF('Redlands Pro Forma'!$B$8:$ED$8,'Annual Projections'!H$8,'Redlands Pro Forma'!$B36:$ED36) -> 4123241.1 | I36: =SUMIF('Redlands Pro Forma'!$B$8:$ED$8,'Annual Projections'!I$8,'Redlands Pro Forma'!$B36:$ED36) -> 4203725.9 | J36: =SUMIF('Redlands Pro Forma'!$B$8:$ED$8,'Annual Projections'!J$8,'Redlands Pro Forma'!$B36:$ED36) -> 6495681.4 | ... M36: =SUMIF('Redlands Pro Forma'!$B$8:$ED$8,'Annual Projections'!M$8,'Redlands Pro Forma'!$B36:$ED36) -> 7132148.9
A38: Operating Expenses
A39: Utilities | B39: ='Redlands Pro Forma'!$C39*12 -> 45000 | C39: =SUMIF('Redlands Pro Forma'!$B$8:$ED$8,'Annual Projections'!C$8,'Redlands Pro Forma'!$B39:$ED39) -> 45000 | D39: =SUMIF('Redlands Pro Forma'!$B$8:$ED$8,'Annual Projections'!D$8,'Redlands Pro Forma'!$B39:$ED39) -> 46125 | E39: =SUMIF('Redlands Pro Forma'!$B$8:$ED$8,'Annual Projections'!E$8,'Redlands Pro Forma'!$B39:$ED39) -> 47278.125 | F39: =SUMIF('Redlands Pro Forma'!$B$8:$ED$8,'Annual Projections'!F$8,'Redlands Pro Forma'!$B39:$ED39) -> 48460.078 | G39: =SUMIF('Redlands Pro Forma'!$B$8:$ED$8,'Annual Projections'!G$8,'Redlands Pro Forma'!$B39:$ED39) -> 49671.58 | H39: =SUMIF('Redlands Pro Forma'!$B$8:$ED$8,'Annual Projections'!H$8,'Redlands Pro Forma'!$B39:$ED39) -> 50913.37 | I39: =SUMIF('Redlands Pro Forma'!$B$8:$ED$8,'Annual Projections'!I$8,'Redlands Pro Forma'!$B39:$ED39) -> 52186.204 | J39: =SUMIF('Redlands Pro Forma'!$B$8:$ED$8,'Annual Projections'!J$8,'Redlands Pro Forma'!$B39:$ED39) -> 53490.859 | ... M39: =SUMIF('Redlands Pro Forma'!$B$8:$ED$8,'Annual Projections'!M$8,'Redlands Pro Forma'!$B39:$ED39) -> 57603.804
A40: Repairs & Maintenance | B40: ='Redlands Pro Forma'!$C40*12 -> 45000 | C40: =SUMIF('Redlands Pro Forma'!$B$8:$ED$8,'Annual Projections'!C$8,'Redlands Pro Forma'!$B40:$ED40) -> 45000 | D40: =SUMIF('Redlands Pro Forma'!$B$8:$ED$8,'Annual Projections'!D$8,'Redlands Pro Forma'!$B40:$ED40) -> 46125 | E40: =SUMIF('Redlands Pro Forma'!$B$8:$ED$8,'Annual Projections'!E$8,'Redlands Pro Forma'!$B40:$ED40) -> 47278.125 | F40: =SUMIF('Redlands Pro Forma'!$B$8:$ED$8,'Annual Projections'!F$8,'Redlands Pro Forma'!$B40:$ED40) -> 48460.078 | G40: =SUMIF('Redlands Pro Forma'!$B$8:$ED$8,'Annual Projections'!G$8,'Redlands Pro Forma'!$B40:$ED40) -> 49671.58 | H40: =SUMIF('Redlands Pro Forma'!$B$8:$ED$8,'Annual Projections'!H$8,'Redlands Pro Forma'!$B40:$ED40) -> 50913.37 | I40: =SUMIF('Redlands Pro Forma'!$B$8:$ED$8,'Annual Projections'!I$8,'Redlands Pro Forma'!$B40:$ED40) -> 52186.204 | J40: =SUMIF('Redlands Pro Forma'!$B$8:$ED$8,'Annual Projections'!J$8,'Redlands Pro Forma'!$B40:$ED40) -> 53490.859 | ... M40: =SUMIF('Redlands Pro Forma'!$B$8:$ED$8,'Annual Projections'!M$8,'Redlands Pro Forma'!$B40:$ED40) -> 57603.804
A41: Insurance | B41: ='Redlands Pro Forma'!$C41*12 -> 20000 | C41: =SUMIF('Redlands Pro Forma'!$B$8:$ED$8,'Annual Projections'!C$8,'Redlands Pro Forma'!$B41:$ED41) -> 20000 | D41: =SUMIF('Redlands Pro Forma'!$B$8:$ED$8,'Annual Projections'!D$8,'Redlands Pro Forma'!$B41:$ED41) -> 20500 | E41: =SUMIF('Redlands Pro Forma'!$B$8:$ED$8,'Annual Projections'!E$8,'Redlands Pro Forma'!$B41:$ED41) -> 21012.5 | F41: =SUMIF('Redlands Pro Forma'!$B$8:$ED$8,'Annual Projections'!F$8,'Redlands Pro Forma'!$B41:$ED41) -> 21537.812 | G41: =SUMIF('Redlands Pro Forma'!$B$8:$ED$8,'Annual Projections'!G$8,'Redlands Pro Forma'!$B41:$ED41) -> 22076.258 | H41: =SUMIF('Redlands Pro Forma'!$B$8:$ED$8,'Annual Projections'!H$8,'Redlands Pro Forma'!$B41:$ED41) -> 22628.164 | I41: =SUMIF('Redlands Pro Forma'!$B$8:$ED$8,'Annual Projections'!I$8,'Redlands Pro Forma'!$B41:$ED41) -> 23193.868 | J41: =SUMIF('Redlands Pro Forma'!$B$8:$ED$8,'Annual Projections'!J$8,'Redlands Pro Forma'!$B41:$ED41) -> 23773.715 | ... M41: =SUMIF('Redlands Pro Forma'!$B$8:$ED$8,'Annual Projections'!M$8,'Redlands Pro Forma'!$B41:$ED41) -> 25601.691
A42: Property Taxes | B42: ='Redlands Pro Forma'!$C42*12 -> 740080 | C42: =SUMIF('Redlands Pro Forma'!$B$8:$ED$8,'Annual Projections'!C$8,'Redlands Pro Forma'!$B42:$ED42) -> 740080 | D42: =SUMIF('Redlands Pro Forma'!$B$8:$ED$8,'Annual Projections'!D$8,'Redlands Pro Forma'!$B42:$ED42) -> 754881.6 | E42: =SUMIF('Redlands Pro Forma'!$B$8:$ED$8,'Annual Projections'!E$8,'Redlands Pro Forma'!$B42:$ED42) -> 769979.23 | F42: =SUMIF('Redlands Pro Forma'!$B$8:$ED$8,'Annual Projections'!F$8,'Redlands Pro Forma'!$B42:$ED42) -> 785378.82 | G42: =SUMIF('Redlands Pro Forma'!$B$8:$ED$8,'Annual Projections'!G$8,'Redlands Pro Forma'!$B42:$ED42) -> 801086.39 | H42: =SUMIF('Redlands Pro Forma'!$B$8:$ED$8,'Annual Projections'!H$8,'Redlands Pro Forma'!$B42:$ED42) -> 817108.12 | I42: =SUMIF('Redlands Pro Forma'!$B$8:$ED$8,'Annual Projections'!I$8,'Redlands Pro Forma'!$B42:$ED42) -> 833450.28 | J42: =SUMIF('Redlands Pro Forma'!$B$8:$ED$8,'Annual Projections'!J$8,'Redlands Pro Forma'!$B42:$ED42) -> 850119.29 | ... M42: =SUMIF('Redlands Pro Forma'!$B$8:$ED$8,'Annual Projections'!M$8,'Redlands Pro Forma'!$B42:$ED42) -> 902153.39
A43: Management Fee | C43: =SUMIF('Redlands Pro Forma'!$B$8:$ED$8,'Annual Projections'!C$8,'Redlands Pro Forma'!$B43:$ED43) -> 112316.37 | D43: =SUMIF('Redlands Pro Forma'!$B$8:$ED$8,'Annual Projections'!D$8,'Redlands Pro Forma'!$B43:$ED43) -> 114503.3 | E43: =SUMIF('Redlands Pro Forma'!$B$8:$ED$8,'Annual Projections'!E$8,'Redlands Pro Forma'!$B43:$ED43) -> 116733.97 | F43: =SUMIF('Redlands Pro Forma'!$B$8:$ED$8,'Annual Projections'!F$8,'Redlands Pro Forma'!$B43:$ED43) -> 119009.25 | G43: =SUMIF('Redlands Pro Forma'!$B$8:$ED$8,'Annual Projections'!G$8,'Redlands Pro Forma'!$B43:$ED43) -> 121330.03 | H43: =SUMIF('Redlands Pro Forma'!$B$8:$ED$8,'Annual Projections'!H$8,'Redlands Pro Forma'!$B43:$ED43) -> 123697.23 | I43: =SUMIF('Redlands Pro Forma'!$B$8:$ED$8,'Annual Projections'!I$8,'Redlands Pro Forma'!$B43:$ED43) -> 126111.78 | J43: =SUMIF('Redlands Pro Forma'!$B$8:$ED$8,'Annual Projections'!J$8,'Redlands Pro Forma'!$B43:$ED43) -> 194870.44 | ... M43: =SUMIF('Redlands Pro Forma'!$B$8:$ED$8,'Annual Projections'!M$8,'Redlands Pro Forma'!$B43:$ED43) -> 213964.47
A44: Total Operating Expenses | C44: =SUMIF('Redlands Pro Forma'!$B$8:$ED$8,'Annual Projections'!C$8,'Redlands Pro Forma'!$B44:$ED44) -> 962396.37 | D44: =SUMIF('Redlands Pro Forma'!$B$8:$ED$8,'Annual Projections'!D$8,'Redlands Pro Forma'!$B44:$ED44) -> 982134.9 | E44: =SUMIF('Redlands Pro Forma'!$B$8:$ED$8,'Annual Projections'!E$8,'Redlands Pro Forma'!$B44:$ED44) -> 1002281.9 | F44: =SUMIF('Redlands Pro Forma'!$B$8:$ED$8,'Annual Projections'!F$8,'Redlands Pro Forma'!$B44:$ED44) -> 1022846 | G44: =SUMIF('Redlands Pro Forma'!$B$8:$ED$8,'Annual Projections'!G$8,'Redlands Pro Forma'!$B44:$ED44) -> 1043835.8 | H44: =SUMIF('Redlands Pro Forma'!$B$8:$ED$8,'Annual Projections'!H$8,'Redlands Pro Forma'!$B44:$ED44) -> 1065260.3 | I44: =SUMIF('Redlands Pro Forma'!$B$8:$ED$8,'Annual Projections'!I$8,'Redlands Pro Forma'!$B44:$ED44) -> 1087128.3 | J44: =SUMIF('Redlands Pro Forma'!$B$8:$ED$8,'Annual Projections'!J$8,'Redlands Pro Forma'!$B44:$ED44) -> 1175745.2 | ... M44: =SUMIF('Redlands Pro Forma'!$B$8:$ED$8,'Annual Projections'!M$8,'Redlands Pro Forma'!$B44:$ED44) -> 1256927.2
A46: Net Operating Income | C46: =SUMIF('Redlands Pro Forma'!$B$8:$ED$8,'Annual Projections'!C$8,'Redlands Pro Forma'!$B46:$ED46) -> 2959535 | D46: =SUMIF('Redlands Pro Forma'!$B$8:$ED$8,'Annual Projections'!D$8,'Redlands Pro Forma'!$B46:$ED46) -> 3035756 | E46: =SUMIF('Redlands Pro Forma'!$B$8:$ED$8,'Annual Projections'!E$8,'Redlands Pro Forma'!$B46:$ED46) -> 3113933 | F46: =SUMIF('Redlands Pro Forma'!$B$8:$ED$8,'Annual Projections'!F$8,'Redlands Pro Forma'!$B46:$ED46) -> 3194113 | G46: =SUMIF('Redlands Pro Forma'!$B$8:$ED$8,'Annual Projections'!G$8,'Redlands Pro Forma'!$B46:$ED46) -> 3276334 | H46: =SUMIF('Redlands Pro Forma'!$B$8:$ED$8,'Annual Projections'!H$8,'Redlands Pro Forma'!$B46:$ED46) -> 3360666 | I46: =SUMIF('Redlands Pro Forma'!$B$8:$ED$8,'Annual Projections'!I$8,'Redlands Pro Forma'!$B46:$ED46) -> 3446217 | J46: =SUMIF('Redlands Pro Forma'!$B$8:$ED$8,'Annual Projections'!J$8,'Redlands Pro Forma'!$B46:$ED46) -> 4766999 | ... M46: =SUMIF('Redlands Pro Forma'!$B$8:$ED$8,'Annual Projections'!M$8,'Redlands Pro Forma'!$B46:$ED46) -> 6135193
A48: Leasing Costs
A49: Tenant Improvements | C49: =SUMIF('Redlands Pro Forma'!$B$8:$ED$8,'Annual Projections'!C$8,'Redlands Pro Forma'!$B49:$ED49) -> 0 | D49: =SUMIF('Redlands Pro Forma'!$B$8:$ED$8,'Annual Projections'!D$8,'Redlands Pro Forma'!$B49:$ED49) -> 0 | E49: =SUMIF('Redlands Pro Forma'!$B$8:$ED$8,'Annual Projections'!E$8,'Redlands Pro Forma'!$B49:$ED49) -> 0 | F49: =SUMIF('Redlands Pro Forma'!$B$8:$ED$8,'Annual Projections'!F$8,'Redlands Pro Forma'!$B49:$ED49) -> 0 | G49: =SUMIF('Redlands Pro Forma'!$B$8:$ED$8,'Annual Projections'!G$8,'Redlands Pro Forma'!$B49:$ED49) -> 0 | H49: =SUMIF('Redlands Pro Forma'!$B$8:$ED$8,'Annual Projections'!H$8,'Redlands Pro Forma'!$B49:$ED49) -> 0 | I49: =SUMIF('Redlands Pro Forma'!$B$8:$ED$8,'Annual Projections'!I$8,'Redlands Pro Forma'!$B49:$ED49) -> 0 | J49: =SUMIF('Redlands Pro Forma'!$B$8:$ED$8,'Annual Projections'!J$8,'Redlands Pro Forma'!$B49:$ED49) -> 2400000 | ... M49: =SUMIF('Redlands Pro Forma'!$B$8:$ED$8,'Annual Projections'!M$8,'Redlands Pro Forma'!$B49:$ED49) -> 0
...

Sheet Redlands Pro Forma
C1: year 1-5 | D1: year 6-10
A2: Market Rent Inflation | C2: 0.03 | D2: 0.022
A3: Expense Inflation | C3: 0.025
A4: Cash Flow Projections
A5: Redlands Industrial Property
B7: Actuals | C7: Forecast | D7: Forecast | E7: Forecast | F7: Forecast | G7: Forecast | H7: Forecast | I7: Forecast | J7: Forecast | K7: Forecast | L7: Forecast | M7: Forecast | N7: Forecast | O7: Forecast | P7: Forecast | Q7: Forecast | R7: Forecast | S7: Forecast | T7: Forecast | U7: Forecast | V7: Forecast | W7: Forecast | X7: Forecast | Y7: Forecast | Z7: Forecast | AA7: Forecast | AB7: Forecast | AC7: Forecast | AD7: Forecast | AE7: Forecast | AF7: Forecast | AG7: Forecast | AH7: Forecast | AI7: Forecast | AJ7: Forecast | AK7: Forecast | AL7: Forecast | AM7: Forecast | AN7: Forecast | AO7: Forecast | AP7: Forecast | AQ7: Forecast | AR7: Forecast | AS7: Forecast | AT7: Forecast | AU7: Forecast | AV7: Forecast | AW7: Forecast | AX7: Forecast | AY7: Forecast | AZ7: Forecast | BA7: Forecast | BB7: Forecast | BC7: Forecast | BD7: Forecast | BE7: Forecast | BF7: Forecast | BG7: Forecast | BH7: Forecast | BI7: Forecast | BJ7: Forecast | BK7: Forecast | BL7: Forecast | BM7: Forecast | BN7: Forecast | BO7: Forecast | BP7: Forecast | BQ7: Forecast | BR7: Forecast | BS7: Forecast | BT7: Forecast | BU7: Forecast | BV7: Forecast | BW7: Forecast | BX7: Forecast | BY7: Forecast | BZ7: Forecast | CA7: Forecast | CB7: Forecast | CC7: Forecast | CD7: Forecast | CE7: Forecast | CF7: Forecast | CG7: Forecast | CH7: Forecast | CI7: Forecast | CJ7: Forecast | CK7: Forecast | CL7: Forecast | CM7: Forecast | CN7: Forecast | CO7: Forecast | CP7: Forecast | CQ7: Forecast | CR7: Forecast | CS7: Forecast | CT7: Forecast | CU7: Forecast | CV7: Forecast | CW7: Forecast | CX7: Forecast | CY7: Forecast | CZ7: Forecast | DA7: Forecast | DB7: Forecast | DC7: Forecast | DD7: Forecast | DE7: Forecast | DF7: Forecast | DG7: Forecast | DH7: Forecast | DI7: Forecast | DJ7: Forecast | DK7: Forecast | DL7: Forecast | DM7: Forecast | DN7: Forecast | DO7: Forecast | DP7: Forecast | DQ7: Forecast | DR7: Forecast | DS7: Forecast | DT7: Forecast | DU7: Forecast | DV7: Forecast | DW7: Forecast | DX7: Forecast | DY7: Forecast | DZ7: Forecast | EA7: Forecast | EB7: Forecast | EC7: Forecast | ED7: Forecast
B8: =ROUNDUP(B$9/12,0) -> 0 | C8: =ROUNDUP(C$9/12,0) -> 1 | D8: =ROUNDUP(D$9/12,0) -> 1 | E8: =ROUNDUP(E$9/12,0) -> 1 | F8: =ROUNDUP(F$9/12,0) -> 1 | G8: =ROUNDUP(G$9/12,0) -> 1 | H8: =ROUNDUP(H$9/12,0) -> 1 | I8: =ROUNDUP(I$9/12,0) -> 1 | ... ED8: =ROUNDUP(ED$9/12,0) -> 11
C9: {=_xlfn.SEQUENCE(1,('Redlands Inputs'!$D$15+1)*12,1,1)} -> 1 | D9: 2 | E9: 3 | F9: 4 | G9: 5 | H9: 6 | I9: 7 | J9: 8 | K9: 9 | L9: 10 | M9: 11 | N9: 12 | O9: 13 | P9: 14 | Q9: 15 | R9: 16 | S9: 17 | T9: 18 | U9: 19 | V9: 20 | W9: 21 | X9: 22 | Y9: 23 | Z9: 24 | AA9: 25 | AB9: 26 | AC9: 27 | AD9: 28 | AE9: 29 | AF9: 30 | AG9: 31 | AH9: 32 | AI9: 33 | AJ9: 34 | AK9: 35 | AL9: 36 | AM9: 37 | AN9: 38 | AO9: 39 | AP9: 40 | AQ9: 41 | AR9: 42 | AS9: 43 | AT9: 44 | AU9: 45 | AV9: 46 | AW9: 47 | AX9: 48 | AY9: 49 | AZ9: 50 | BA9: 51 | BB9: 52 | BC9: 53 | BD9: 54 | BE9: 55 | BF9: 56 | BG9: 57 | BH9: 58 | BI9: 59 | BJ9: 60 | BK9: 61 | BL9: 62 | BM9: 63 | BN9: 64 | BO9: 65 | BP9: 66 | BQ9: 67 | BR9: 68 | BS9: 69 | BT9: 70 | BU9: 71 | BV9: 72 | BW9: 73 | BX9: 74 | BY9: 75 | BZ9: 76 | CA9: 77 | CB9: 78 | CC9: 79 | CD9: 80 | CE9: 81 | CF9: 82 | CG9: 83 | CH9: 84 | CI9: 85 | CJ9: 86 | CK9: 87 | CL9: 88 | CM9: 89 | CN9: 90 | CO9: 91 | CP9: 92 | CQ9: 93 | CR9: 94 | CS9: 95 | CT9: 96 | CU9: 97 | CV9: 98 | CW9: 99 | CX9: 100 | CY9: 101 | CZ9: 102 | DA9: 103 | DB9: 104 | DC9: 105 | DD9: 106 | DE9: 107 | DF9: 108 | DG9: 109 | DH9: 110 | DI9: 111 | DJ9: 112 | DK9: 113 | DL9: 114 | DM9: 115 | DN9: 116 | DO9: 117 | DP9: 118 | DQ9: 119 | DR9: 120 | DS9: 121 | DT9: 122 | DU9: 123 | DV9: 124 | DW9: 125 | DX9: 126 | DY9: 127 | DZ9: 128 | EA9: 129 | EB9: 130 | EC9: 131 | ED9: 132
A10: Months | B10: =EOMONTH(C10,-12) -> 45322 | C10: =EOMONTH('Redlands Inputs'!D14,0) -> 45688 | D10: =EOMONTH(C10,1) -> 45716 | E10: =EOMONTH(D10,1) -> 45747 | F10: =EOMONTH(E10,1) -> 45777 | G10: =EOMONTH(F10,1) -> 45808 | H10: =EOMONTH(G10,1) -> 45838 | I10: =EOMONTH(H10,1) -> 45869 | J10: =EOMONTH(I10,1) -> 45900 | K10: =EOMONTH(J10,1) -> 45930 | ... ED10: =EOMONTH(EC10,1) -> 49674
A12: Rental Revenue
A13: Base Rent / SF | C13: =(C14/'Redlands Inputs'!$D$7)*12 -> 6.4997762 | D13: =(D14/'Redlands Inputs'!$D$7)*12 -> 6.4997762 | E13: =(E14/'Redlands Inputs'!$D$7)*12 -> 6.4997762 | F13: =(F14/'Redlands Inputs'!$D$7)*12 -> 6.4997762 | G13: =(G14/'Redlands Inputs'!$D$7)*12 -> 6.4997762 | H13: =(H14/'Redlands Inputs'!$D$7)*12 -> 6.4997762 | I13: =(I14/'Redlands Inputs'!$D$7)*12 -> 6.4997762 | J13: =(J14/'Redlands Inputs'!$D$7)*12 -> 6.4997762 | ... ED13: =(ED14/'Redlands Inputs'!$D$7)*12 -> 11.520761
A14: Potential Base Rent | C14: {=_xlfn.IFS('Redlands Inputs'!$G$12="Vacate", _xlfn.IFS(C$9=1,'Redlands Inputs'!$G$22, C$10<='Redlands Inputs'!$H$20,'Redlands Inputs'!$G$22*(1+'Redlands Inputs'!$H$23)^(C$8-1), C$10>'Redlands Inputs'!$H$20,'Redlands Inputs'!$C$26*(1+'Redlands Inputs'!$D$28)^(C$8-1)), 'Redlands Inputs'!$G$12="Market", _xlfn.IFS(C$9=1,'Redlands Inputs'!$G$22, C$10<='Redlands Inputs'!$H$20,'Redlands Inputs'!$G$22*(1+'Redlands Inputs'!$H$23)^(C$8-1), C$10>'Redlands Inputs'!$H$20,(('Redlands Inputs'!$K$17*'Redlands Inputs'!$H$17)/12)*(1+'Redlands Inputs'!$D$28)^(C$8-1)))} -> 324988.81 | D14: {=_xlfn.IFS('Redlands Inputs'!$G$12="Vacate", _xlfn.IFS(D$9=1,'Redlands Inputs'!$G$22, D$10<='Redlands Inputs'!$H$20,'Redlands Inputs'!$G$22*(1+'Redlands Inputs'!$H$23)^(D$8-1), D$10>'Redlands Inputs'!$H$20,'Redlands Inputs'!$C$26*(1+'Redlands Inputs'!$D$28)^(D$8-1)), 'Redlands Inputs'!$G$12="Market", _xlfn.IFS(D$9=1,'Redlands Inputs'!$G$22, D$10<='Redlands Inputs'!$H$20,'Redlands Inputs'!$G$22*(1+'Redlands Inputs'!$H$23)^(D$8-1), D$10>'Redlands Inputs'!$H$20,(('Redlands Inputs'!$K$17*'Redlands Inputs'!$H$17)/12)*(1+'Redlands Inputs'!$D$28)^(D$8-1)))} -> 324988.81 | E14: {=_xlfn.IFS('Redlands Inputs'!$G$12="Vacate", _xlfn.IFS(E$9=1,'Redlands Inputs'!$G$22, E$10<='Redlands Inputs'!$H$20,'Redlands Inputs'!$G$22*(1+'Redlands Inputs'!$H$23)^(E$8-1), E$10>'Redlands Inputs'!$H$20,'Redlands Inputs'!$C$26*(1+'Redlands Inputs'!$D$28)^(E$8-1)), 'Redlands Inputs'!$G$12="Market", _xlfn.IFS(E$9=1,'Redlands Inputs'!$G$22, E$10<='Redlands Inputs'!$H$20,'Redlands Inputs'!$G$22*(1+'Redlands Inputs'!$H$23)^(E$8-1), E$10>'Redlands Inputs'!$H$20,(('Redlands Inputs'!$K$17*'Redlands Inputs'!$H$17)/12)*(1+'Redlands Inputs'!$D$28)^(E$8-1)))} -> 324988.81 | F14: {=_xlfn.IFS('Redlands Inputs'!$G$12="Vacate", _xlfn.IFS(F$9=1,'Redlands Inputs'!$G$22, F$10<='Redlands Inputs'!$H$20,'Redlands Inputs'!$G$22*(1+'Redlands Inputs'!$H$23)^(F$8-1), F$10>'Redlands Inputs'!$H$20,'Redlands Inputs'!$C$26*(1+'Redlands Inputs'!$D$28)^(F$8-1)), 'Redlands Inputs'!$G$12="Market", _xlfn.IFS(F$9=1,'Redlands Inputs'!$G$22, F$10<='Redlands Inputs'!$H$20,'Redlands Inputs'!$G$22*(1+'Redlands Inputs'!$H$23)^(F$8-1), F$10>'Redlands Inputs'!$H$20,(('Redlands Inputs'!$K$17*'Redlands Inputs'!$H$17)/12)*(1+'Redlands Inputs'!$D$28)^(F$8-1)))} -> 324988.81 | G14: {=_xlfn.IFS('Redlands Inputs'!$G$12="Vacate", _xlfn.IFS(G$9=1,'Redlands Inputs'!$G$22, G$10<='Redlands Inputs'!$H$20,'Redlands Inputs'!$G$22*(1+'Redlands Inputs'!$H$23)^(G$8-1), G$10>'Redlands Inputs'!$H$20,'Redlands Inputs'!$C$26*(1+'Redlands Inputs'!$D$28)^(G$8-1)), 'Redlands Inputs'!$G$12="Market", _xlfn.IFS(G$9=1,'Redlands Inputs'!$G$22, G$10<='Redlands Inputs'!$H$20,'Redlands Inputs'!$G$22*(1+'Redlands Inputs'!$H$23)^(G$8-1), G$10>'Redlands Inputs'!$H$20,(('Redlands Inputs'!$K$17*'Redlands Inputs'!$H$17)/12)*(1+'Redlands Inputs'!$D$28)^(G$8-1)))} -> 324988.81 | H14: {=_xlfn.IFS('Redlands Inputs'!$G$12="Vacate", _xlfn.IFS(H$9=1,'Redlands Inputs'!$G$22, H$10<='Redlands Inputs'!$H$20,'Redlands Inputs'!$G$22*(1+'Redlands Inputs'!$H$23)^(H$8-1), H$10>'Redlands Inputs'!$H$20,'Redlands Inputs'!$C$26*(1+'Redlands Inputs'!$D$28)^(H$8-1)), 'Redlands Inputs'!$G$12="Market", _xlfn.IFS(H$9=1,'Redlands Inputs'!$G$22, H$10<='Redlands Inputs'!$H$20,'Redlands Inputs'!$G$22*(1+'Redlands Inputs'!$H$23)^(H$8-1), H$10>'Redlands Inputs'!$H$20,(('Redlands Inputs'!$K$17*'Redlands Inputs'!$H$17)/12)*(1+'Redlands Inputs'!$D$28)^(H$8-1)))} -> 324988.81 | I14: {=_xlfn.IFS('Redlands Inputs'!$G$12="Vacate", _xlfn.IFS(I$9=1,'Redlands Inputs'!$G$22, I$10<='Redlands Inputs'!$H$20,'Redlands Inputs'!$G$22*(1+'Redlands Inputs'!$H$23)^(I$8-1), I$10>'Redlands Inputs'!$H$20,'Redlands Inputs'!$C$26*(1+'Redlands Inputs'!$D$28)^(I$8-1)), 'Redlands Inputs'!$G$12="Market", _xlfn.IFS(I$9=1,'Redlands Inputs'!$G$22, I$10<='Redlands Inputs'!$H$20,'Redlands Inputs'!$G$22*(1+'Redlands Inputs'!$H$23)^(I$8-1), I$10>'Redlands Inputs'!$H$20,(('Redlands Inputs'!$K$17*'Redlands Inputs'!$H$17)/12)*(1+'Redlands Inputs'!$D$28)^(I$8-1)))} -> 324988.81 | J14: {=_xlfn.IFS('Redlands Inputs'!$G$12="Vacate", _xlfn.IFS(J$9=1,'Redlands Inputs'!$G$22, J$10<='Redlands Inputs'!$H$20,'Redlands Inputs'!$G$22*(1+'Redlands Inputs'!$H$23)^(J$8-1), J$10>'Redlands Inputs'!$H$20,'Redlands Inputs'!$C$26*(1+'Redlands Inputs'!$D$28)^(J$8-1)), 'Redlands Inputs'!$G$12="Market", _xlfn.IFS(J$9=1,'Redlands Inputs'!$G$22, J$10<='Redlands Inputs'!$H$20,'Redlands Inputs'!$G$22*(1+'Redlands Inputs'!$H$23)^(J$8-1), J$10>'Redlands Inputs'!$H$20,(('Redlands Inputs'!$K$17*'Redlands Inputs'!$H$17)/12)*(1+'Redlands Inputs'!$D$28)^(J$8-1)))} -> 324988.81 | ... ED14: {=_xlfn.IFS('Redlands Inputs'!$G$12="Vacate", _xlfn.IFS(ED$9=1,'Redlands Inputs'!$G$22, ED$10<='Redlands Inputs'!$H$20,'Redlands Inputs'!$G$22*(1+'Redlands Inputs'!$H$23)^(ED$8-1), ED$10>'Redlands Inputs'!$H$20,'Redlands Inputs'!$C$26*(1+'Redlands Inputs'!$D$28)^(ED$8-1)), 'Redlands Inputs'!$G$12="Market", _xlfn.IFS(ED$9=1,'Redlands Inputs'!$G$22, ED$10<='Redlands Inputs'!$H$20,'Redlands Inputs'!$G$22*(1+'Redlands Inputs'!$H$23)^(ED$8-1), ED$10>'Redlands Inputs'!$H$20,(('Redlands Inputs'!$K$17*'Redlands Inputs'!$H$17)/12)*(1+'Redlands Inputs'!$D$28)^(ED$8-1)))} -> 576038.04
A15: Vacancy & Turnover | C15: {=_xlfn.IFS('Redlands Inputs'!$G$12="Vacate", IF(AND(C10>'Redlands Inputs'!$H$20,C10<'Redlands Inputs'!$D$24)=TRUE,-C$14,0), 'Redlands Inputs'!$G$12="Market", IF(AND(C10>'Redlands Inputs'!$H$20,C10<EOMONTH('Redlands Inputs'!$H$20,'Redlands Inputs'!$K$18))=TRUE,-C$14,0), 'Redlands Inputs'!$G$12="Renew",0)} -> 0 | D15: {=_xlfn.IFS('Redlands Inputs'!$G$12="Vacate", IF(AND(D10>'Redlands Inputs'!$H$20,D10<'Redlands Inputs'!$D$24)=TRUE,-D$14,0), 'Redlands Inputs'!$G$12="Market", IF(AND(D10>'Redlands Inputs'!$H$20,D10<EOMONTH('Redlands Inputs'!$H$20,'Redlands Inputs'!$K$18))=TRUE,-D$14,0), 'Redlands Inputs'!$G$12="Renew",0)} -> 0 | E15: {=_xlfn.IFS('Redlands Inputs'!$G$12="Vacate", IF(AND(E10>'Redlands Inputs'!$H$20,E10<'Redlands Inputs'!$D$24)=TRUE,-E$14,0), 'Redlands Inputs'!$G$12="Market", IF(AND(E10>'Redlands Inputs'!$H$20,E10<EOMONTH('Redlands Inputs'!$H$20,'Redlands Inputs'!$K$18))=TRUE,-E$14,0), 'Redlands Inputs'!$G$12="Renew",0)} -> 0 | F15: {=_xlfn.IFS('Redlands Inputs'!$G$12="Vacate", IF(AND(F10>'Redlands Inputs'!$H$20,F10<'Redlands Inputs'!$D$24)=TRUE,-F$14,0), 'Redlands Inputs'!$G$12="Market", IF(AND(F10>'Redlands Inputs'!$H$20,F10<EOMONTH('Redlands Inputs'!$H$20,'Redlands Inputs'!$K$18))=TRUE,-F$14,0), 'Redlands Inputs'!$G$12="Renew",0)} -> 0 | G15: {=_xlfn.IFS('Redlands Inputs'!$G$12="Vacate", IF(AND(G10>'Redlands Inputs'!$H$20,G10<'Redlands Inputs'!$D$24)=TRUE,-G$14,0), 'Redlands Inputs'!$G$12="Market", IF(AND(G10>'Redlands Inputs'!$H$20,G10<EOMONTH('Redlands Inputs'!$H$20,'Redlands Inputs'!$K$18))=TRUE,-G$14,0), 'Redlands Inputs'!$G$12="Renew",0)} -> 0 | H15: {=_xlfn.IFS('Redlands Inputs'!$G$12="Vacate", IF(AND(H10>'Redlands Inputs'!$H$20,H10<'Redlands Inputs'!$D$24)=TRUE,-H$14,0), 'Redlands Inputs'!$G$12="Market", IF(AND(H10>'Redlands Inputs'!$H$20,H10<EOMONTH('Redlands Inputs'!$H$20,'Redlands Inputs'!$K$18))=TRUE,-H$14,0), 'Redlands Inputs'!$G$12="Renew",0)} -> 0 | I15: {=_xlfn.IFS('Redlands Inputs'!$G$12="Vacate", IF(AND(I10>'Redlands Inputs'!$H$20,I10<'Redlands Inputs'!$D$24)=TRUE,-I$14,0), 'Redlands Inputs'!$G$12="Market", IF(AND(I10>'Redlands Inputs'!$H$20,I10<EOMONTH('Redlands Inputs'!$H$20,'Redlands Inputs'!$K$18))=TRUE,-I$14,0), 'Redlands Inputs'!$G$12="Renew",0)} -> 0 | J15: {=_xlfn.IFS('Redlands Inputs'!$G$12="Vacate", IF(AND(J10>'Redlands Inputs'!$H$20,J10<'Redlands Inputs'!$D$24)=TRUE,-J$14,0), 'Redlands Inputs'!$G$12="Market", IF(AND(J10>'Redlands Inputs'!$H$20,J10<EOMONTH('Redlands Inputs'!$H$20,'Redlands Inputs'!$K$18))=TRUE,-J$14,0), 'Redlands Inputs'!$G$12="Renew",0)} -> 0 | ... ED15: {=_xlfn.IFS('Redlands Inputs'!$G$12="Vacate", IF(AND(ED10>'Redlands Inputs'!$H$20,ED10<'Redlands Inputs'!$D$24)=TRUE,-ED$14,0), 'Redlands Inputs'!$G$12="Market", IF(AND(ED10>'Redlands Inputs'!$H$20,ED10<EOMONTH('Redlands Inputs'!$H$20,'Redlands Inputs'!$K$18))=TRUE,-ED$14,0), 'Redlands Inputs'!$G$12="Renew",0)} -> 0
A16: Free Rent / Concessions
A17: Total Base Rent | C17: =SUM(C14:C16) -> 324988.81 | D17: =SUM(D14:D16) -> 324988.81 | E17: =SUM(E14:E16) -> 324988.81 | F17: =SUM(F14:F16) -> 324988.81 | G17: =SUM(G14:G16) -> 324988.81 | H17: =SUM(H14:H16) -> 324988.81 | I17: =SUM(I14:I16) -> 324988.81 | J17: =SUM(J14:J16) -> 324988.81 | ... ED17: =SUM(ED14:ED16) -> 576038.04
A18: Total Rental Revenue | C18: =C17 -> 324988.81 | D18: =D17 -> 324988.81 | E18: =E17 -> 324988.81 | F18: =F17 -> 324988.81 | G18: =G17 -> 324988.81 | H18: =H17 -> 324988.81 | I18: =I17 -> 324988.81 | J18: =J17 -> 324988.81 | ... ED18: =ED17 -> 576038.04
A20: Other Tenant Revenue
A21: Utilities | C21: =IF(C$15<>0,0,$C39) -> 3750 | D21: =IF(D$15<>0,0,$C39) -> 3750 | E21: =IF(E$15<>0,0,$C39) -> 3750 | F21: =IF(F$15<>0,0,$C39) -> 3750 | G21: =IF(G$15<>0,0,$C39) -> 3750 | H21: =IF(H$15<>0,0,$C39) -> 3750 | I21: =IF(I$15<>0,0,$C39) -> 3750 | J21: =IF(J$15<>0,0,$C39) -> 3750 | ... ED21: =IF(ED$15<>0,0,$C39) -> 3750
A22: Repairs & Maintenance | C22: =IF(C$15<>0,0,$C40) -> 3750 | D22: =IF(D$15<>0,0,$C40) -> 3750 | E22: =IF(E$15<>0,0,$C40) -> 3750 | F22: =IF(F$15<>0,0,$C40) -> 3750 | G22: =IF(G$15<>0,0,$C40) -> 3750 | H22: =IF(H$15<>0,0,$C40) -> 3750 | I22: =IF(I$15<>0,0,$C40) -> 3750 | J22: =IF(J$15<>0,0,$C40) -> 3750 | ... ED22: =IF(ED$15<>0,0,$C40) -> 3750
A23: Insurance | C23: =IF(C$15<>0,0,$C41) -> 1666.6667 | D23: =IF(D$15<>0,0,$C41) -> 1666.6667 | E23: =IF(E$15<>0,0,$C41) -> 1666.6667 | F23: =IF(F$15<>0,0,$C41) -> 1666.6667 | G23: =IF(G$15<>0,0,$C41) -> 1666.6667 | H23: =IF(H$15<>0,0,$C41) -> 1666.6667 | I23: =IF(I$15<>0,0,$C41) -> 1666.6667 | J23: =IF(J$15<>0,0,$C41) -> 1666.6667 | ... ED23: =IF(ED$15<>0,0,$C41) -> 1666.6667
A24: Property Taxes | C24: =IF(C15<>0,0,IF(C$10<'Redlands Inputs'!$H$20,'Redlands Inputs'!$H$7*(1+'Redlands Inputs'!$L$6)^(C$8-1),C$42)) -> 12500 | D24: =IF(D15<>0,0,IF(D$10<'Redlands Inputs'!$H$20,'Redlands Inputs'!$H$7*(1+'Redlands Inputs'!$L$6)^(D$8-1),D$42)) -> 12500 | E24: =IF(E15<>0,0,IF(E$10<'Redlands Inputs'!$H$20,'Redlands Inputs'!$H$7*(1+'Redlands Inputs'!$L$6)^(E$8-1),E$42)) -> 12500 | F24: =IF(F15<>0,0,IF(F$10<'Redlands Inputs'!$H$20,'Redlands Inputs'!$H$7*(1+'Redlands Inputs'!$L$6)^(F$8-1),F$42)) -> 12500 | G24: =IF(G15<>0,0,IF(G$10<'Redlands Inputs'!$H$20,'Redlands Inputs'!$H$7*(1+'Redlands Inputs'!$L$6)^(G$8-1),G$42)) -> 12500 | H24: =IF(H15<>0,0,IF(H$10<'Redlands Inputs'!$H$20,'Redlands Inputs'!$H$7*(1+'Redlands Inputs'!$L$6)^(H$8-1),H$42)) -> 12500 | I24: =IF(I15<>0,0,IF(I$10<'Redlands Inputs'!$H$20,'Redlands Inputs'!$H$7*(1+'Redlands Inputs'!$L$6)^(I$8-1),I$42)) -> 12500 | J24: =IF(J15<>0,0,IF(J$10<'Redlands Inputs'!$H$20,'Redlands Inputs'!$H$7*(1+'Redlands Inputs'!$L$6)^(J$8-1),J$42)) -> 12500 | ... ED24: =IF(ED15<>0,0,IF(ED$10<'Redlands Inputs'!$H$20,'Redlands Inputs'!$H$7*(1+'Redlands Inputs'!$L$6)^(ED$8-1),ED$42)) -> 75179.449
A25: Total Expense Recoveries | C25: =SUM(C21:C24) -> 21666.667 | D25: =SUM(D21:D24) -> 21666.667 | E25: =SUM(E21:E24) -> 21666.667 | F25: =SUM(F21:F24) -> 21666.667 | G25: =SUM(G21:G24) -> 21666.667 | H25: =SUM(H21:H24) -> 21666.667 | I25: =SUM(I21:I24) -> 21666.667 | J25: =SUM(J21:J24) -> 21666.667 | ... ED25: =SUM(ED21:ED24) -> 84346.116
A26: Total Other Tenant Revenue | C26: =SUM(C25) -> 21666.667 | D26: =SUM(D25) -> 21666.667 | E26: =SUM(E25) -> 21666.667 | F26: =SUM(F25) -> 21666.667 | G26: =SUM(G25) -> 21666.667 | H26: =SUM(H25) -> 21666.667 | I26: =SUM(I25) -> 21666.667 | J26: =SUM(J25) -> 21666.667 | ... ED26: =SUM(ED25) -> 84346.116
A28: Total Tenant Revenue | C28: =C18+C26 -> 346655.48 | D28: =D18+D26 -> 346655.48 | E28: =E18+E26 -> 346655.48 | F28: =F18+F26 -> 346655.48 | G28: =G18+G26 -> 346655.48 | H28: =H18+H26 -> 346655.48 | I28: =I18+I26 -> 346655.48 | J28: =J18+J26 -> 346655.48 | ... ED28: =ED18+ED26 -> 660384.16
A30: Potential Gross Revenue | C30: =C28 -> 346655.48 | D30: =D28 -> 346655.48 | E30: =E28 -> 346655.48 | F30: =F28 -> 346655.48 | G30: =G28 -> 346655.48 | H30: =H28 -> 346655.48 | I30: =I28 -> 346655.48 | J30: =J28 -> 346655.48 | ... ED30: =ED28 -> 660384.16
A32: Vacancy & Loss to Lease
A33: Vacancy & L2L | C33: =C30*-'Redlands Inputs'!$D$11 -> -34665.548 | D33: =D30*-'Redlands Inputs'!$D$11 -> -34665.548 | E33: =E30*-'Redlands Inputs'!$D$11 -> -34665.548 | F33: =F30*-'Redlands Inputs'!$D$11 -> -34665.548 | G33: =G30*-'Redlands Inputs'!$D$11 -> -34665.548 | H33: =H30*-'Redlands Inputs'!$D$11 -> -34665.548 | I33: =I30*-'Redlands Inputs'!$D$11 -> -34665.548 | J33: =J30*-'Redlands Inputs'!$D$11 -> -34665.548 | ... ED33: =ED30*-'Redlands Inputs'!$D$11 -> -66038.416
A34: Total Vacancy & Credit Loss | C34: =C33 -> -34665.548 | D34: =D33 -> -34665.548 | E34: =E33 -> -34665.548 | F34: =F33 -> -34665.548 | G34: =G33 -> -34665.548 | H34: =H33 -> -34665.548 | I34: =I33 -> -34665.548 | J34: =J33 -> -34665.548 | ... ED34: =ED33 -> -66038.416
A36: Effective Gross Revenue | C36: =C30+C34 -> 311989.93 | D36: =D30+D34 -> 311989.93 | E36: =E30+E34 -> 311989.93 | F36: =F30+F34 -> 311989.93 | G36: =G30+G34 -> 311989.93 | H36: =H30+H34 -> 311989.93 | I36: =I30+I34 -> 311989.93 | J36: =J30+J34 -> 311989.93 | ... ED36: =ED30+ED34 -> 594345.74
A38: Operating Expenses
A39: Utilities | C39: ='Redlands Inputs'!$H3 -> 3750 | D39: ='Redlands Inputs'!$H3*(1+$C$3)^(D$8-1) -> 3750 | E39: ='Redlands Inputs'!$H3*(1+$C$3)^(E$8-1) -> 3750 | F39: ='Redlands Inputs'!$H3*(1+$C$3)^(F$8-1) -> 3750 | G39: ='Redlands Inputs'!$H3*(1+$C$3)^(G$8-1) -> 3750 | H39: ='Redlands Inputs'!$H3*(1+$C$3)^(H$8-1) -> 3750 | I39: ='Redlands Inputs'!$H3*(1+$C$3)^(I$8-1) -> 3750 | J39: ='Redlands Inputs'!$H3*(1+$C$3)^(J$8-1) -> 3750 | K39: ='Redlands Inputs'!$H3*(1+$C$3)^(K$8-1) -> 3750 | ... ED39: ='Redlands Inputs'!$H3*(1+$C$3)^(ED$8-1) -> 4800.317
A40: Repairs & Maintenance | C40: ='Redlands Inputs'!$H4 -> 3750 | D40: ='Redlands Inputs'!$H4*(1+$C$3)^(D$8-1) -> 3750 | E40: ='Redlands Inputs'!$H4*(1+$C$3)^(E$8-1) -> 3750 | F40: ='Redlands Inputs'!$H4*(1+$C$3)^(F$8-1) -> 3750 | G40: ='Redlands Inputs'!$H4*(1+$C$3)^(G$8-1) -> 3750 | H40: ='Redlands Inputs'!$H4*(1+$C$3)^(H$8-1) -> 3750 | I40: ='Redlands Inputs'!$H4*(1+$C$3)^(I$8-1) -> 3750 | J40: ='Redlands Inputs'!$H4*(1+$C$3)^(J$8-1) -> 3750 | K40: ='Redlands Inputs'!$H4*(1+$C$3)^(K$8-1) -> 3750 | ... ED40: ='Redlands Inputs'!$H4*(1+$C$3)^(ED$8-1) -> 4800.317
A41: Insurance | C41: ='Redlands Inputs'!$H5 -> 1666.6667 | D41: ='Redlands Inputs'!$H5*(1+$C$3)^(D$8-1) -> 1666.6667 | E41: ='Redlands Inputs'!$H5*(1+$C$3)^(E$8-1) -> 1666.6667 | F41: ='Redlands Inputs'!$H5*(1+$C$3)^(F$8-1) -> 1666.6667 | G41: ='Redlands Inputs'!$H5*(1+$C$3)^(G$8-1) -> 1666.6667 | H41: ='Redlands Inputs'!$H5*(1+$C$3)^(H$8-1) -> 1666.6667 | I41: ='Redlands Inputs'!$H5*(1+$C$3)^(I$8-1) -> 1666.6667 | J41: ='Redlands Inputs'!$H5*(1+$C$3)^(J$8-1) -> 1666.6667 | K41: ='Redlands Inputs'!$H5*(1+$C$3)^(K$8-1) -> 1666.6667 | ... ED41: ='Redlands Inputs'!$H5*(1+$C$3)^(ED$8-1) -> 2133.4742
A42: Property Taxes | C42: ='Redlands Inputs'!H6 -> 61673.333 | D42: ='Redlands Inputs'!$H6*(1+'Redlands Inputs'!$L$6)^(D$8-1) -> 61673.333 | E42: ='Redlands Inputs'!$H6*(1+'Redlands Inputs'!$L$6)^(E$8-1) -> 61673.333 | F42: ='Redlands Inputs'!$H6*(1+'Redlands Inputs'!$L$6)^(F$8-1) -> 61673.333 | G42: ='Redlands Inputs'!$H6*(1+'Redlands Inputs'!$L$6)^(G$8-1) -> 61673.333 | H42: ='Redlands Inputs'!$H6*(1+'Redlands Inputs'!$L$6)^(H$8-1) -> 61673.333 | I42: ='Redlands Inputs'!$H6*(1+'Redlands Inputs'!$L$6)^(I$8-1) -> 61673.333 | J42: ='Redlands Inputs'!$H6*(1+'Redlands Inputs'!$L$6)^(J$8-1) -> 61673.333 | K42: ='Redlands Inputs'!$H6*(1+'Redlands Inputs'!$L$6)^(K$8-1) -> 61673.333 | ... ED42: ='Redlands Inputs'!$H6*(1+'Redlands Inputs'!$L$6)^(ED$8-1) -> 75179.449
A43: Management Fee | C43: =C$36*'Redlands Inputs'!$I$8 -> 9359.6978 | D43: =D$36*'Redlands Inputs'!$I$8 -> 9359.6978 | E43: =E$36*'Redlands Inputs'!$I$8 -> 9359.6978 | F43: =F$36*'Redlands Inputs'!$I$8 -> 9359.6978 | G43: =G$36*'Redlands Inputs'!$I$8 -> 9359.6978 | H43: =H$36*'Redlands Inputs'!$I$8 -> 9359.6978 | I43: =I$36*'Redlands Inputs'!$I$8 -> 9359.6978 | J43: =J$36*'Redlands Inputs'!$I$8 -> 9359.6978 | ... ED43: =ED$36*'Redlands Inputs'!$I$8 -> 17830.372
A44: Total Operating Expenses | C44: =+SUM(C39:C43) -> 80199.698 | D44: =+SUM(D39:D43) -> 80199.698 | E44: =+SUM(E39:E43) -> 80199.698 | F44: =+SUM(F39:F43) -> 80199.698 | G44: =+SUM(G39:G43) -> 80199.698 | H44: =+SUM(H39:H43) -> 80199.698 | I44: =+SUM(I39:I43) -> 80199.698 | J44: =+SUM(J39:J43) -> 80199.698 | ... ED44: =+SUM(ED39:ED43) -> 104743.93
A46: Net Operating Income | C46: 246690 | D46: 246690 | E46: 246690 | F46: 246690 | G46: 246690 | H46: 246690 | I46: 246690 | J46: 246690 | K46: 246690 | L46: 246690 | M46: 246690 | N46: 245945 | O46: 253043 | P46: 253043 | Q46: 253043 | R46: 253043 | S46: 253043 | T46: 253043 | U46: 253043 | V46: 253043 | W46: 253043 | X46: 253043 | Y46: 253043 | Z46: 252283 | AA46: 259559 | AB46: 259559 | AC46: 259559 | AD46: 259559 | AE46: 259559 | AF46: 259559 | AG46: 259559 | AH46: 259559 | AI46: 259559 | AJ46: 259559 | AK46: 259559 | AL46: 258784 | AM46: 266242 | AN46: 266242 | AO46: 266242 | AP46: 266242 | AQ46: 266242 | AR46: 266242 | AS46: 266242 | AT46: 266242 | AU46: 266242 | AV46: 266242 | AW46: 266242 | AX46: 265451 | AY46: 273095 | AZ46: 273095 | BA46: 273095 | BB46: 273095 | BC46: 273095 | BD46: 273095 | BE46: 273095 | BF46: 273095 | BG46: 273095 | BH46: 273095 | BI46: 273095 | BJ46: 272289 | BK46: 280124 | BL46: 280124 | BM46: 280124 | BN46: 280124 | BO46: 280124 | BP46: 280124 | BQ46: 280124 | BR46: 280124 | BS46: 280124 | BT46: 280124 | BU46: 280124 | BV46: 279302 | BW46: 287333 | BX46: 287333 | BY46: 287333 | BZ46: 287333 | CA46: 287333 | CB46: 287333 | CC46: 287333 | CD46: 287333 | CE46: 287333 | CF46: 287333 | CG46: 287333 | CH46: 285554 | CI46: -58030 | CJ46: -58030 | CK46: 182680 | CL46: 522255 | CM46: 522255 | CN46: 522255 | CO46: 522255 | CP46: 522255 | CQ46: 522255 | CR46: 522255 | CS46: 522255 | CT46: 522339 | CU46: 522339 | CV46: 522339 | CW46: 536488 | CX46: 536488 | CY46: 536488 | CZ46: 536488 | DA46: 536488 | DB46: 536488 | DC46: 536488 | DD46: 536488 | DE46: 536488 | DF46: 535616 | DG46: 535616 | DH46: 535616 | DI46: 550119 | DJ46: 550119 | DK46: 550119 | DL46: 550119 | DM46: 550119 | DN46: 550119 | DO46: 550119 | DP46: 550119 | DQ46: 550119 | DR46: 549229 | DS46: 498858 | DT46: 498858 | DU46: 513724 | DV46: 513724 | DW46: 513724 | DX46: 513724 | DY46: 513724 | DZ46: 513724 | EA46: 513724 | EB46: 513724 | EC46: 513724 | ED46: 513961
A48: Leasing Costs
A49: Tenant Improvements | C49: =IF(C$10='Redlands Inputs'!$D$24,'Redlands Inputs'!$C$31,0) -> 0 | D49: =IF(D$10='Redlands Inputs'!$D$24,'Redlands Inputs'!$C$31,0) -> 0 | E49: =IF(E$10='Redlands Inputs'!$D$24,'Redlands Inputs'!$C$31,0) -> 0 | F49: =IF(F$10='Redlands Inputs'!$D$24,'Redlands Inputs'!$C$31,0) -> 0 | G49: =IF(G$10='Redlands Inputs'!$D$24,'Redlands Inputs'!$C$31,0) -> 0 | H49: =IF(H$10='Redlands Inputs'!$D$24,'Redlands Inputs'!$C$31,0) -> 0 | I49: =IF(I$10='Redlands Inputs'!$D$24,'Redlands Inputs'!$C$31,0) -> 0 | J49: =IF(J$10='Redlands Inputs'!$D$24,'Redlands Inputs'!$C$31,0) -> 0 | ... ED49: =IF(ED$10='Redlands Inputs'!$D$24,'Redlands Inputs'!$C$31,0) -> 0
A50: Leasing Commissions | C50: =IF(C$10=EDATE('Redlands Inputs'!$D$24,-2),'Redlands Inputs'!$C$34/2,IF(C$10='Redlands Inputs'!$D$24,'Redlands Inputs'!$C$34/2,0)) -> 0 | D50: =IF(D$10=EDATE('Redlands Inputs'!$D$24,-2),'Redlands Inputs'!$C$34/2,IF(D$10='Redlands Inputs'!$D$24,'Redlands Inputs'!$C$34/2,0)) -> 0 | E50: =IF(E$10=EDATE('Redlands Inputs'!$D$24,-2),'Redlands Inputs'!$C$34/2,IF(E$10='Redlands Inputs'!$D$24,'Redlands Inputs'!$C$34/2,0)) -> 0 | F50: =IF(F$10=EDATE('Redlands Inputs'!$D$24,-2),'Redlands Inputs'!$C$34/2,IF(F$10='Redlands Inputs'!$D$24,'Redlands Inputs'!$C$34/2,0)) -> 0 | G50: =IF(G$10=EDATE('Redlands Inputs'!$D$24,-2),'Redlands Inputs'!$C$34/2,IF(G$10='Redlands Inputs'!$D$24,'Redlands Inputs'!$C$34/2,0)) -> 0 | H50: =IF(H$10=EDATE('Redlands Inputs'!$D$24,-2),'Redlands Inputs'!$C$34/2,IF(H$10='Redlands Inputs'!$D$24,'Redlands Inputs'!$C$34/2,0)) -> 0 | I50: =IF(I$10=EDATE('Redlands Inputs'!$D$24,-2),'Redlands Inputs'!$C$34/2,IF(I$10='Redlands Inputs'!$D$24,'Redlands Inputs'!$C$34/2,0)) -> 0 | J50: =IF(J$10=EDATE('Redlands Inputs'!$D$24,-2),'Redlands Inputs'!$C$34/2,IF(J$10='Redlands Inputs'!$D$24,'Redlands Inputs'!$C$34/2,0)) -> 0 | ... ED50: =IF(ED$10=EDATE('Redlands Inputs'!$D$24,-2),'Redlands Inputs'!$C$34/2,IF(ED$10='Redlands Inputs'!$D$24,'Redlands Inputs'!$C$34/2,0)) -> 0
...

Sheet Redlands Inputs
B2: Property | F2: Expenses - Operating | H2: Month 1 | J2: Fixed | K2: Recoverable | L2: Inflation (%)
B3: Address | D3: 2255 W Lugonia. Ave | F3: Utilities | H3: =I3/12 -> 3750 | I3: 45000 | J3: 0.25 | K3: 1 | L3: ='Redlands Pro Forma'!$C$3 -> 0.025
B4: City | D4: Redlands | F4: Repairs & Maintenance | H4: =I4/12 -> 3750 | I4: 45000 | J4: 0.25 | K4: 1 | L4: ='Redlands Pro Forma'!$C$3 -> 0.025
B5: Year Built | D5: 2013 | F5: Insurance | H5: =I5/12 -> 1666.6667 | I5: 20000 | J5: 1 | K5: 1 | L5: ='Redlands Pro Forma'!$C$3 -> 0.025
B6: State | D6: California | F6: Property Taxes | H6: =J6/12 -> 61673.333 | I6: 0.011 | J6: =I6*D8 -> 740080 | K6: 1 | L6: 0.02
B7: Size (RSF) | D7: 600000 | F7: Previous RE Tax | H7: =150000/12 -> 12500
B8: Purchase Price | D8: =ROUND(D16/D10,-4) -> 67280000 | F8: Management Fee | I8: 3.0% | K8: 0
B9: Closing Costs | C9: =D8*D9 -> 1345600 | D9: 0.02 | F9: Expenses - Capital
B10: Entry Cap | D10: 0.0541 | F10: Replacement Reserve | H10: =(I10*D7)/12 -> 50000 | I10: 1 | L10: 0.02
B11: Vacancy | D11: 0.1
B12: Exit Cap | C12: =SUMIF(_xlfn.ANCHORARRAY('Redlands Pro Forma'!$C$9),">120",'Redlands Pro Forma'!$C$46:$ED$46)/'Redlands Inputs'!$D$12 -> 1.103452e+08 | D12: 0.0556 | F12: Upon Expiration | G12: Vacate
B13: Cost of Sales | C13: =C12*D13 -> 2206904 | D13: 0.02
B14: Analysis Start | D14: 45658 | F14: Tenants - Rent Roll
B15: Holding Period | D15: 10 | F15: Name | G15: /mo | H15: Amazon | I15: Recovery Structure | K15: Net
B16: Year 0 NOI | D16: =(3900000-260000) -> 3640000 | F16: Suite | H16: Floor 1 | I16: Upon Expiration | K16: =+G12 -> Vacate
F17: Area | H17: 600000 | I17: Market Blended Rent | K17: =(D22*market_rent)+(H21*(1-D22)) -> 8.1405
F18: Lease Start | H18: 44593 | I18: Blended Months Vacant | K18: =D22*D23+((1-D22)*0) -> 0.7
B19: Market Leasing | F19: Term | H19: 10
B20: Size | C20: Mo | D20: =H17 -> 600000 | F20: Lease Expiry | H20: =EOMONTH(H18,(H19*12)-1) -> 48244
B21: Term Length | D21: 7 | F21: Base Rent | G21: =(H21*H17)/12 -> 306750 | H21: 6.135
B22: Renewal Probability | D22: 0.7 | F22: Current Rent | G22: =(H22*H17)/12 -> 324988.81 | H22: =H21*(1+H23)^(YEARFRAC(H18,D14)) -> 6.4997762
B23: Months Vacant | D23: 1 | F23: Rent Increase | H23: 0.02
B24: Lease Start Date | D24: =EDATE(H20,D23) -> 48273 | F24: Type | H24: Fixed Steps
B25: Base Rent (/sf) | D25: 9
B26: Base Rent | C26: =D26/12 -> 450000 | D26: =market_rent*D20 -> 5400000
B27: Rent Increase Type | D27: Fixed Steps | F27: Recoverable Expenses - NNN | H27: Month 1
B28: Rent Increase (%) | D28: 0.025 | F28: Utilities | H28: ='Redlands Pro Forma'!$C39 -> 3750
B29: Free Rent | D29: 2 | F29: Repairs & Maintenance | H29: ='Redlands Pro Forma'!$C40 -> 3750
B30: Tenant Improvements | F30: Insurance | H30: ='Redlands Pro Forma'!$C41 -> 1666.6667
B31: New | C31: =D31*D20 -> 2400000 | D31: 4 | F31: Property Taxes | H31: ='Redlands Pro Forma'!$C42 -> 61673.333
B32: Renew | D32: 2
B33: Leasing Commissions
B34: New | C34: =(market_rent*D20*D21)*D34 -> 2268000 | D34: 0.06
B35: Renew | D35: 0.03
B36: Security Deposit | C36: =D36*C26 -> 1800000 | D36: 4
B38: Cap Rate
A39: Rent Growth | B39: ='Redlands Pro Forma'!B74 -> 0.075530967 | C39: =D39-2000000 -> 63280000 | D39: =E39-2000000 -> 65280000 | E39: =D8 -> 67280000 | F39: =E39+2000000 -> 69280000 | G39: =F39+2000000 -> 71280000
B40: =B41-0.0025 -> 0.0506 | C40: 0.090119866 | D40: 0.093800363 | E40: 0.093800363 | F40: 0.090119866 | G40: 0.083156732
