Workbook
Name analysis_start: 'Torrance Inputs'!$D$18
Name analysis_start: #REF!
Name market_rent: 'Torrance Inputs'!$D$32
Name market_rent: #REF!

Sheet Annual Pro Forma
A2: Market Rent Inflation
A3: Expense Inflation
A4: Cash Flow Projections
A5: Redlands Industrial Property
B7: Actuals | C7: Forecast | D7: Forecast | E7: Forecast | F7: Forecast | G7: Forecast | H7: Forecast | I7: Forecast | J7: Forecast | K7: Forecast | L7: Forecast | M7: Forward T12
B8: 0 | C8: =B8+1 -> 1 | D8: =C8+1 -> 2 | E8: =D8+1 -> 3 | F8: =E8+1 -> 4 | G8: =F8+1 -> 5 | H8: =G8+1 -> 6 | I8: =H8+1 -> 7 | J8: =I8+1 -> 8 | ... M8: =L8+1 -> 11
B9: =EOMONTH(C9,-12) -> 45322 | C9: =EDATE('Torrance Inputs'!analysis_start,0) -> 45658 | D9: =EOMONTH(C9,12) -> 46053 | E9: =EOMONTH(D9,12) -> 46418 | F9: =EOMONTH(E9,12) -> 46783 | G9: =EOMONTH(F9,12) -> 47149 | H9: =EOMONTH(G9,12) -> 47514 | I9: =EOMONTH(H9,12) -> 47879 | J9: =EOMONTH(I9,12) -> 48244 | K9: =EOMONTH(J9,12) -> 48610 | ... M9: =EOMONTH(L9,12) -> 49340
A10: Months
A12: Rental Revenue
A13: Base Rent / SF / Year | C13: =SUMIF('Torrance Pro Forma'!$B$8:$ED$8,'Annual Pro Forma'!C$8,'Torrance Pro Forma'!$B13:$ED13) -> 48 | D13: =SUMIF('Torrance Pro Forma'!$B$8:$ED$8,'Annual Pro Forma'!D$8,'Torrance Pro Forma'!$B13:$ED13) -> 48.96 | E13: =SUMIF('Torrance Pro Forma'!$B$8:$ED$8,'Annual Pro Forma'!E$8,'Torrance Pro Forma'!$B13:$ED13) -> 49.9392 | F13: =SUMIF('Torrance Pro Forma'!$B$8:$ED$8,'Annual Pro Forma'!F$8,'Torrance Pro Forma'!$B13:$ED13) -> 50.937984 | G13: =SUMIF('Torrance Pro Forma'!$B$8:$ED$8,'Annual Pro Forma'!G$8,'Torrance Pro Forma'!$B13:$ED13) -> 0 | H13: =SUMIF('Torrance Pro Forma'!$B$8:$ED$8,'Annual Pro Forma'!H$8,'Torrance Pro Forma'!$B13:$ED13) -> 212.84272 | I13: =SUMIF('Torrance Pro Forma'!$B$8:$ED$8,'Annual Pro Forma'!I$8,'Torrance Pro Forma'!$B13:$ED13) -> 217.09957 | J13: =SUMIF('Torrance Pro Forma'!$B$8:$ED$8,'Annual Pro Forma'!J$8,'Torrance Pro Forma'!$B13:$ED13) -> 221.44157 | ... M13: =SUMIF('Torrance Pro Forma'!$B$8:$ED$8,'Annual Pro Forma'!M$8,'Torrance Pro Forma'!$B13:$ED13) -> 234.99556
A14: Tenant 1 | C14: =SUMIF('Torrance Pro Forma'!$B$8:$ED$8,'Annual Pro Forma'!C$8,'Torrance Pro Forma'!$B14:$ED14) -> 1100000 | D14: =SUMIF('Torrance Pro Forma'!$B$8:$ED$8,'Annual Pro Forma'!D$8,'Torrance Pro Forma'!$B14:$ED14) -> 1122000 | E14: =SUMIF('Torrance Pro Forma'!$B$8:$ED$8,'Annual Pro Forma'!E$8,'Torrance Pro Forma'!$B14:$ED14) -> 1144440 | F14: =SUMIF('Torrance Pro Forma'!$B$8:$ED$8,'Annual Pro Forma'!F$8,'Torrance Pro Forma'!$B14:$ED14) -> 1167328.8 | G14: =SUMIF('Torrance Pro Forma'!$B$8:$ED$8,'Annual Pro Forma'!G$8,'Torrance Pro Forma'!$B14:$ED14) -> 0 | H14: =SUMIF('Torrance Pro Forma'!$B$8:$ED$8,'Annual Pro Forma'!H$8,'Torrance Pro Forma'!$B14:$ED14) -> 2438822.8 | I14: =SUMIF('Torrance Pro Forma'!$B$8:$ED$8,'Annual Pro Forma'!I$8,'Torrance Pro Forma'!$B14:$ED14) -> 2487599.3 | J14: =SUMIF('Torrance Pro Forma'!$B$8:$ED$8,'Annual Pro Forma'!J$8,'Torrance Pro Forma'!$B14:$ED14) -> 2537351.3 | ... M14: =SUMIF('Torrance Pro Forma'!$B$8:$ED$8,'Annual Pro Forma'!M$8,'Torrance Pro Forma'!$B14:$ED14) -> 2692657.5
A15: Tenant 2 | C15: =SUMIF('Torrance Pro Forma'!$B$8:$ED$8,'Annual Pro Forma'!C$8,'Torrance Pro Forma'!$B15:$ED15) -> 0 | D15: =SUMIF('Torrance Pro Forma'!$B$8:$ED$8,'Annual Pro Forma'!D$8,'Torrance Pro Forma'!$B15:$ED15) -> 0 | E15: =SUMIF('Torrance Pro Forma'!$B$8:$ED$8,'Annual Pro Forma'!E$8,'Torrance Pro Forma'!$B15:$ED15) -> 0 | F15: =SUMIF('Torrance Pro Forma'!$B$8:$ED$8,'Annual Pro Forma'!F$8,'Torrance Pro Forma'!$B15:$ED15) -> 0 | G15: =SUMIF('Torrance Pro Forma'!$B$8:$ED$8,'Annual Pro Forma'!G$8,'Torrance Pro Forma'!$B15:$ED15) -> 0 | H15: =SUMIF('Torrance Pro Forma'!$B$8:$ED$8,'Annual Pro Forma'!H$8,'Torrance Pro Forma'!$B15:$ED15) -> 2438822.8 | I15: =SUMIF('Torrance Pro Forma'!$B$8:$ED$8,'Annual Pro Forma'!I$8,'Torrance Pro Forma'!$B15:$ED15) -> 2487599.3 | J15: =SUMIF('Torrance Pro Forma'!$B$8:$ED$8,'Annual Pro Forma'!J$8,'Torrance Pro Forma'!$B15:$ED15) -> 2537351.3 | ... M15: =SUMIF('Torrance Pro Forma'!$B$8:$ED$8,'Annual Pro Forma'!M$8,'Torrance Pro Forma'!$B15:$ED15) -> 2692657.5
A16: Potential Base Rent | C16: =SUMIF('Torrance Pro Forma'!$B$8:$ED$8,'Annual Pro Forma'!C$8,'Torrance Pro Forma'!$B16:$ED16) -> 1100000 | D16: =SUMIF('Torrance Pro Forma'!$B$8:$ED$8,'Annual Pro Forma'!D$8,'Torrance Pro Forma'!$B16:$ED16) -> 1122000 | E16: =SUMIF('Torrance Pro Forma'!$B$8:$ED$8,'Annual Pro Forma'!E$8,'Torrance Pro Forma'!$B16:$ED16) -> 1144440 | F16: =SUMIF('Torrance Pro Forma'!$B$8:$ED$8,'Annual Pro Forma'!F$8,'Torrance Pro Forma'!$B16:$ED16) -> 1167328.8 | G16: =SUMIF('Torrance Pro Forma'!$B$8:$ED$8,'Annual Pro Forma'!G$8,'Torrance Pro Forma'!$B16:$ED16) -> 0 | H16: =SUMIF('Torrance Pro Forma'!$B$8:$ED$8,'Annual Pro Forma'!H$8,'Torrance Pro Forma'!$B16:$ED16) -> 4877645.7 | I16: =SUMIF('Torrance Pro Forma'!$B$8:$ED$8,'Annual Pro Forma'!I$8,'Torrance Pro Forma'!$B16:$ED16) -> 4975198.6 | J16: =SUMIF('Torrance Pro Forma'!$B$8:$ED$8,'Annual Pro Forma'!J$8,'Torrance Pro Forma'!$B16:$ED16) -> 5074702.6 | ... M16: =SUMIF('Torrance Pro Forma'!$B$8:$ED$8,'Annual Pro Forma'!M$8,'Torrance Pro Forma'!$B16:$ED16) -> 5385314.9
A17: Vacancy / Turnover | C17: =SUMIF('Torrance Pro Forma'!$B$8:$ED$8,'Annual Pro Forma'!C$8,'Torrance Pro Forma'!$B17:$ED17) -> 0 | D17: =SUMIF('Torrance Pro Forma'!$B$8:$ED$8,'Annual Pro Forma'!D$8,'Torrance Pro Forma'!$B17:$ED17) -> 0 | E17: =SUMIF('Torrance Pro Forma'!$B$8:$ED$8,'Annual Pro Forma'!E$8,'Torrance Pro Forma'!$B17:$ED17) -> 0 | F17: =SUMIF('Torrance Pro Forma'!$B$8:$ED$8,'Annual Pro Forma'!F$8,'Torrance Pro Forma'!$B17:$ED17) -> 0 | G17: =SUMIF('Torrance Pro Forma'!$B$8:$ED$8,'Annual Pro Forma'!G$8,'Torrance Pro Forma'!$B17:$ED17) -> 0 | H17: =SUMIF('Torrance Pro Forma'!$B$8:$ED$8,'Annual Pro Forma'!H$8,'Torrance Pro Forma'!$B17:$ED17) -> 0 | I17: =SUMIF('Torrance Pro Forma'!$B$8:$ED$8,'Annual Pro Forma'!I$8,'Torrance Pro Forma'!$B17:$ED17) -> 0 | J17: =SUMIF('Torrance Pro Forma'!$B$8:$ED$8,'Annual Pro Forma'!J$8,'Torrance Pro Forma'!$B17:$ED17) -> 0 | ... M17: =SUMIF('Torrance Pro Forma'!$B$8:$ED$8,'Annual Pro Forma'!M$8,'Torrance Pro Forma'!$B17:$ED17) -> 0
A18: Security Deposit | C18: =SUMIF('Torrance Pro Forma'!$B$8:$ED$8,'Annual Pro Forma'!C$8,'Torrance Pro Forma'!$B18:$ED18) -> 0 | D18: =SUMIF('Torrance Pro Forma'!$B$8:$ED$8,'Annual Pro Forma'!D$8,'Torrance Pro Forma'!$B18:$ED18) -> 0 | E18: =SUMIF('Torrance Pro Forma'!$B$8:$ED$8,'Annual Pro Forma'!E$8,'Torrance Pro Forma'!$B18:$ED18) -> 0 | F18: =SUMIF('Torrance Pro Forma'!$B$8:$ED$8,'Annual Pro Forma'!F$8,'Torrance Pro Forma'!$B18:$ED18) -> 0 | G18: =SUMIF('Torrance Pro Forma'!$B$8:$ED$8,'Annual Pro Forma'!G$8,'Torrance Pro Forma'!$B18:$ED18) -> 0 | H18: =SUMIF('Torrance Pro Forma'!$B$8:$ED$8,'Annual Pro Forma'!H$8,'Torrance Pro Forma'!$B18:$ED18) -> 504166.67 | I18: =SUMIF('Torrance Pro Forma'!$B$8:$ED$8,'Annual Pro Forma'!I$8,'Torrance Pro Forma'!$B18:$ED18) -> 0 | J18: =SUMIF('Torrance Pro Forma'!$B$8:$ED$8,'Annual Pro Forma'!J$8,'Torrance Pro Forma'!$B18:$ED18) -> 0 | ... M18: =SUMIF('Torrance Pro Forma'!$B$8:$ED$8,'Annual Pro Forma'!M$8,'Torrance Pro Forma'!$B18:$ED18) -> 0
A19: Free Rent / Concessions | C19: =SUMIF('Torrance Pro Forma'!$B$8:$ED$8,'Annual Pro Forma'!C$8,'Torrance Pro Forma'!$B19:$ED19) -> 0 | D19: =SUMIF('Torrance Pro Forma'!$B$8:$ED$8,'Annual Pro Forma'!D$8,'Torrance Pro Forma'!$B19:$ED19) -> 0 | E19: =SUMIF('Torrance Pro Forma'!$B$8:$ED$8,'Annual Pro Forma'!E$8,'Torrance Pro Forma'!$B19:$ED19) -> 0 | F19: =SUMIF('Torrance Pro Forma'!$B$8:$ED$8,'Annual Pro Forma'!F$8,'Torrance Pro Forma'!$B19:$ED19) -> 0 | G19: =SUMIF('Torrance Pro Forma'!$B$8:$ED$8,'Annual Pro Forma'!G$8,'Torrance Pro Forma'!$B19:$ED19) -> 0 | H19: =SUMIF('Torrance Pro Forma'!$B$8:$ED$8,'Annual Pro Forma'!H$8,'Torrance Pro Forma'!$B19:$ED19) -> -57614.525 | I19: =SUMIF('Torrance Pro Forma'!$B$8:$ED$8,'Annual Pro Forma'!I$8,'Torrance Pro Forma'!$B19:$ED19) -> -57614.525 | J19: =SUMIF('Torrance Pro Forma'!$B$8:$ED$8,'Annual Pro Forma'!J$8,'Torrance Pro Forma'!$B19:$ED19) -> -57614.525 | ... M19: =SUMIF('Torrance Pro Forma'!$B$8:$ED$8,'Annual Pro Forma'!M$8,'Torrance Pro Forma'!$B19:$ED19) -> -57614.525
A20: Total Base Rent | C20: =SUMIF('Torrance Pro Forma'!$B$8:$ED$8,'Annual Pro Forma'!C$8,'Torrance Pro Forma'!$B20:$ED20) -> 1100000 | D20: =SUMIF('Torrance Pro Forma'!$B$8:$ED$8,'Annual Pro Forma'!D$8,'Torrance Pro Forma'!$B20:$ED20) -> 1122000 | E20: =SUMIF('Torrance Pro Forma'!$B$8:$ED$8,'Annual Pro Forma'!E$8,'Torrance Pro Forma'!$B20:$ED20) -> 1144440 | F20: =SUMIF('Torrance Pro Forma'!$B$8:$ED$8,'Annual Pro Forma'!F$8,'Torrance Pro Forma'!$B20:$ED20) -> 1167328.8 | G20: =SUMIF('Torrance Pro Forma'!$B$8:$ED$8,'Annual Pro Forma'!G$8,'Torrance Pro Forma'!$B20:$ED20) -> 0 | H20: =SUMIF('Torrance Pro Forma'!$B$8:$ED$8,'Annual Pro Forma'!H$8,'Torrance Pro Forma'!$B20:$ED20) -> 5324197.8 | I20: =SUMIF('Torrance Pro Forma'!$B$8:$ED$8,'Annual Pro Forma'!I$8,'Torrance Pro Forma'!$B20:$ED20) -> 4917584.1 | J20: =SUMIF('Torrance Pro Forma'!$B$8:$ED$8,'Annual Pro Forma'!J$8,'Torrance Pro Forma'!$B20:$ED20) -> 5017088 | ... M20: =SUMIF('Torrance Pro Forma'!$B$8:$ED$8,'Annual Pro Forma'!M$8,'Torrance Pro Forma'!$B20:$ED20) -> 5327700.4
A21: Total Rental Revenue | C21: =SUMIF('Torrance Pro Forma'!$B$8:$ED$8,'Annual Pro Forma'!C$8,'Torrance Pro Forma'!$B21:$ED21) -> 1100000 | D21: =SUMIF('Torrance Pro Forma'!$B$8:$ED$8,'Annual Pro Forma'!D$8,'Torrance Pro Forma'!$B21:$ED21) -> 1122000 | E21: =SUMIF('Torrance Pro Forma'!$B$8:$ED$8,'Annual Pro Forma'!E$8,'Torrance Pro Forma'!$B21:$ED21) -> 1144440 | F21: =SUMIF('Torrance Pro Forma'!$B$8:$ED$8,'Annual Pro Forma'!F$8,'Torrance Pro Forma'!$B21:$ED21) -> 1167328.8 | G21: =SUMIF('Torrance Pro Forma'!$B$8:$ED$8,'Annual Pro Forma'!G$8,'Torrance Pro Forma'!$B21:$ED21) -> 0 | H21: =SUMIF('Torrance Pro Forma'!$B$8:$ED$8,'Annual Pro Forma'!H$8,'Torrance Pro Forma'!$B21:$ED21) -> 5324197.8 | I21: =SUMIF('Torrance Pro Forma'!$B$8:$ED$8,'Annual Pro Forma'!I$8,'Torrance Pro Forma'!$B21:$ED21) -> 4917584.1 | J21: =SUMIF('Torrance Pro Forma'!$B$8:$ED$8,'Annual Pro Forma'!J$8,'Torrance Pro Forma'!$B21:$ED21) -> 5017088 | ... M21: =SUMIF('Torrance Pro Forma'!$B$8:$ED$8,'Annual Pro Forma'!M$8,'Torrance Pro Forma'!$B21:$ED21) -> 5327700.4
C22: =SUMIF('Torrance Pro Forma'!$B$8:$ED$8,'Annual Pro Forma'!C$8,'Torrance Pro Forma'!$B22:$ED22) -> 0 | D22: =SUMIF('Torrance Pro Forma'!$B$8:$ED$8,'Annual Pro Forma'!D$8,'Torrance Pro Forma'!$B22:$ED22) -> 0 | E22: =SUMIF('Torrance Pro Forma'!$B$8:$ED$8,'Annual Pro Forma'!E$8,'Torrance Pro Forma'!$B22:$ED22) -> 0 | F22: =SUMIF('Torrance Pro Forma'!$B$8:$ED$8,'Annual Pro Forma'!F$8,'Torrance Pro Forma'!$B22:$ED22) -> 0 | G22: =SUMIF('Torrance Pro Forma'!$B$8:$ED$8,'Annual Pro Forma'!G$8,'Torrance Pro Forma'!$B22:$ED22) -> 0 | H22: =SUMIF('Torrance Pro Forma'!$B$8:$ED$8,'Annual Pro Forma'!H$8,'Torrance Pro Forma'!$B22:$ED22) -> 0 | I22: =SUMIF('Torrance Pro Forma'!$B$8:$ED$8,'Annual Pro Forma'!I$8,'Torrance Pro Forma'!$B22:$ED22) -> 0 | J22: =SUMIF('Torrance Pro Forma'!$B$8:$ED$8,'Annual Pro Forma'!J$8,'Torrance Pro Forma'!$B22:$ED22) -> 0 | ... M22: =SUMIF('Torrance Pro Forma'!$B$8:$ED$8,'Annual Pro Forma'!M$8,'Torrance Pro Forma'!$B22:$ED22) -> 0
A23: Other Tenant Revenue | C23: =SUMIF('Torrance Pro Forma'!$B$8:$ED$8,'Annual Pro Forma'!C$8,'Torrance Pro Forma'!$B23:$ED23) -> 0 | D23: =SUMIF('Torrance Pro Forma'!$B$8:$ED$8,'Annual Pro Forma'!D$8,'Torrance Pro Forma'!$B23:$ED23) -> 0 | E23: =SUMIF('Torrance Pro Forma'!$B$8:$ED$8,'Annual Pro Forma'!E$8,'Torrance Pro Forma'!$B23:$ED23) -> 0 | F23: =SUMIF('Torrance Pro Forma'!$B$8:$ED$8,'Annual Pro Forma'!F$8,'Torrance Pro Forma'!$B23:$ED23) -> 0 | G23: =SUMIF('Torrance Pro Forma'!$B$8:$ED$8,'Annual Pro Forma'!G$8,'Torrance Pro Forma'!$B23:$ED23) -> 0 | H23: =SUMIF('Torrance Pro Forma'!$B$8:$ED$8,'Annual Pro Forma'!H$8,'Torrance Pro Forma'!$B23:$ED23) -> 0 | I23: =SUMIF('Torrance Pro Forma'!$B$8:$ED$8,'Annual Pro Forma'!I$8,'Torrance Pro Forma'!$B23:$ED23) -> 0 | J23: =SUMIF('Torrance Pro Forma'!$B$8:$ED$8,'Annual Pro Forma'!J$8,'Torrance Pro Forma'!$B23:$ED23) -> 0 | ... M23: =SUMIF('Torrance Pro Forma'!$B$8:$ED$8,'Annual Pro Forma'!M$8,'Torrance Pro Forma'!$B23:$ED23) -> 0
A24: Utilities | C24: =SUMIF('Torrance Pro Forma'!$B$8:$ED$8,'Annual Pro Forma'!C$8,'Torrance Pro Forma'!$B24:$ED24) -> 15000 | D24: =SUMIF('Torrance Pro Forma'!$B$8:$ED$8,'Annual Pro Forma'!D$8,'Torrance Pro Forma'!$B24:$ED24) -> 15000 | E24: =SUMIF('Torrance Pro Forma'!$B$8:$ED$8,'Annual Pro Forma'!E$8,'Torrance Pro Forma'!$B24:$ED24) -> 15000 | F24: =SUMIF('Torrance Pro Forma'!$B$8:$ED$8,'Annual Pro Forma'!F$8,'Torrance Pro Forma'!$B24:$ED24) -> 15000 | G24: =SUMIF('Torrance Pro Forma'!$B$8:$ED$8,'Annual Pro Forma'!G$8,'Torrance Pro Forma'!$B24:$ED24) -> 0 | H24: =SUMIF('Torrance Pro Forma'!$B$8:$ED$8,'Annual Pro Forma'!H$8,'Torrance Pro Forma'!$B24:$ED24) -> 15000 | I24: =SUMIF('Torrance Pro Forma'!$B$8:$ED$8,'Annual Pro Forma'!I$8,'Torrance Pro Forma'!$B24:$ED24) -> 15000 | J24: =SUMIF('Torrance Pro Forma'!$B$8:$ED$8,'Annual Pro Forma'!J$8,'Torrance Pro Forma'!$B24:$ED24) -> 15000 | ... M24: =SUMIF('Torrance Pro Forma'!$B$8:$ED$8,'Annual Pro Forma'!M$8,'Torrance Pro Forma'!$B24:$ED24) -> 15000
A25: Repairs & Maintenance | C25: =SUMIF('Torrance Pro Forma'!$B$8:$ED$8,'Annual Pro Forma'!C$8,'Torrance Pro Forma'!$B25:$ED25) -> 15000 | D25: =SUMIF('Torrance Pro Forma'!$B$8:$ED$8,'Annual Pro Forma'!D$8,'Torrance Pro Forma'!$B25:$ED25) -> 15450 | E25: =SUMIF('Torrance Pro Forma'!$B$8:$ED$8,'Annual Pro Forma'!E$8,'Torrance Pro Forma'!$B25:$ED25) -> 15913.5 | F25: =SUMIF('Torrance Pro Forma'!$B$8:$ED$8,'Annual Pro Forma'!F$8,'Torrance Pro Forma'!$B25:$ED25) -> 16390.905 | G25: =SUMIF('Torrance Pro Forma'!$B$8:$ED$8,'Annual Pro Forma'!G$8,'Torrance Pro Forma'!$B25:$ED25) -> 0 | H25: =SUMIF('Torrance Pro Forma'!$B$8:$ED$8,'Annual Pro Forma'!H$8,'Torrance Pro Forma'!$B25:$ED25) -> 17389.111 | I25: =SUMIF('Torrance Pro Forma'!$B$8:$ED$8,'Annual Pro Forma'!I$8,'Torrance Pro Forma'!$B25:$ED25) -> 17910.784 | J25: =SUMIF('Torrance Pro Forma'!$B$8:$ED$8,'Annual Pro Forma'!J$8,'Torrance Pro Forma'!$B25:$ED25) -> 18448.108 | ... M25: =SUMIF('Torrance Pro Forma'!$B$8:$ED$8,'Annual Pro Forma'!M$8,'Torrance Pro Forma'!$B25:$ED25) -> 20158.746
A26: Insurance | C26: =SUMIF('Torrance Pro Forma'!$B$8:$ED$8,'Annual Pro Forma'!C$8,'Torrance Pro Forma'!$B26:$ED26) -> 5000 | D26: =SUMIF('Torrance Pro Forma'!$B$8:$ED$8,'Annual Pro Forma'!D$8,'Torrance Pro Forma'!$B26:$ED26) -> 5150 | E26: =SUMIF('Torrance Pro Forma'!$B$8:$ED$8,'Annual Pro Forma'!E$8,'Torrance Pro Forma'!$B26:$ED26) -> 5304.5 | F26: =SUMIF('Torrance Pro Forma'!$B$8:$ED$8,'Annual Pro Forma'!F$8,'Torrance Pro Forma'!$B26:$ED26) -> 5463.635 | G26: =SUMIF('Torrance Pro Forma'!$B$8:$ED$8,'Annual Pro Forma'!G$8,'Torrance Pro Forma'!$B26:$ED26) -> 0 | H26: =SUMIF('Torrance Pro Forma'!$B$8:$ED$8,'Annual Pro Forma'!H$8,'Torrance Pro Forma'!$B26:$ED26) -> 5796.3704 | I26: =SUMIF('Torrance Pro Forma'!$B$8:$ED$8,'Annual Pro Forma'!I$8,'Torrance Pro Forma'!$B26:$ED26) -> 5970.2615 | J26: =SUMIF('Torrance Pro Forma'!$B$8:$ED$8,'Annual Pro Forma'!J$8,'Torrance Pro Forma'!$B26:$ED26) -> 6149.3693 | ... M26: =SUMIF('Torrance Pro Forma'!$B$8:$ED$8,'Annual Pro Forma'!M$8,'Torrance Pro Forma'!$B26:$ED26) -> 6719.5819
A27: Property Taxes | C27: =SUMIF('Torrance Pro Forma'!$B$8:$ED$8,'Annual Pro Forma'!C$8,'Torrance Pro Forma'!$B27:$ED27) -> 0 | D27: =SUMIF('Torrance Pro Forma'!$B$8:$ED$8,'Annual Pro Forma'!D$8,'Torrance Pro Forma'!$B27:$ED27) -> 0 | E27: =SUMIF('Torrance Pro Forma'!$B$8:$ED$8,'Annual Pro Forma'!E$8,'Torrance Pro Forma'!$B27:$ED27) -> 0 | F27: =SUMIF('Torrance Pro Forma'!$B$8:$ED$8,'Annual Pro Forma'!F$8,'Torrance Pro Forma'!$B27:$ED27) -> 0 | G27: =SUMIF('Torrance Pro Forma'!$B$8:$ED$8,'Annual Pro Forma'!G$8,'Torrance Pro Forma'!$B27:$ED27) -> 0 | H27: =SUMIF('Torrance Pro Forma'!$B$8:$ED$8,'Annual Pro Forma'!H$8,'Torrance Pro Forma'!$B27:$ED27) -> 213175.19 | I27: =SUMIF('Torrance Pro Forma'!$B$8:$ED$8,'Annual Pro Forma'!I$8,'Torrance Pro Forma'!$B27:$ED27) -> 217438.69 | J27: =SUMIF('Torrance Pro Forma'!$B$8:$ED$8,'Annual Pro Forma'!J$8,'Torrance Pro Forma'!$B27:$ED27) -> 221787.46 | ... M27: =SUMIF('Torrance Pro Forma'!$B$8:$ED$8,'Annual Pro Forma'!M$8,'Torrance Pro Forma'!$B27:$ED27) -> 235362.63
A28: Total Expense Recoveries | C28: =SUMIF('Torrance Pro Forma'!$B$8:$ED$8,'Annual Pro Forma'!C$8,'Torrance Pro Forma'!$B28:$ED28) -> 35000 | D28: =SUMIF('Torrance Pro Forma'!$B$8:$ED$8,'Annual Pro Forma'!D$8,'Torrance Pro Forma'!$B28:$ED28) -> 35600 | E28: =SUMIF('Torrance Pro Forma'!$B$8:$ED$8,'Annual Pro Forma'!E$8,'Torrance Pro Forma'!$B28:$ED28) -> 36218 | F28: =SUMIF('Torrance Pro Forma'!$B$8:$ED$8,'Annual Pro Forma'!F$8,'Torrance Pro Forma'!$B28:$ED28) -> 36854.54 | G28: =SUMIF('Torrance Pro Forma'!$B$8:$ED$8,'Annual Pro Forma'!G$8,'Torrance Pro Forma'!$B28:$ED28) -> 0 | H28: =SUMIF('Torrance Pro Forma'!$B$8:$ED$8,'Annual Pro Forma'!H$8,'Torrance Pro Forma'!$B28:$ED28) -> 251360.67 | I28: =SUMIF('Torrance Pro Forma'!$B$8:$ED$8,'Annual Pro Forma'!I$8,'Torrance Pro Forma'!$B28:$ED28) -> 256319.74 | J28: =SUMIF('Torrance Pro Forma'!$B$8:$ED$8,'Annual Pro Forma'!J$8,'Torrance Pro Forma'!$B28:$ED28) -> 261384.94 | ... M28: =SUMIF('Torrance Pro Forma'!$B$8:$ED$8,'Annual Pro Forma'!M$8,'Torrance Pro Forma'!$B28:$ED28) -> 277240.96
A29: Total Other Tenant Revenue | C29: =SUMIF('Torrance Pro Forma'!$B$8:$ED$8,'Annual Pro Forma'!C$8,'Torrance Pro Forma'!$B29:$ED29) -> 35000 | D29: =SUMIF('Torrance Pro Forma'!$B$8:$ED$8,'Annual Pro Forma'!D$8,'Torrance Pro Forma'!$B29:$ED29) -> 35600 | E29: =SUMIF('Torrance Pro Forma'!$B$8:$ED$8,'Annual Pro Forma'!E$8,'Torrance Pro Forma'!$B29:$ED29) -> 36218 | F29: =SUMIF('Torrance Pro Forma'!$B$8:$ED$8,'Annual Pro Forma'!F$8,'Torrance Pro Forma'!$B29:$ED29) -> 36854.54 | G29: =SUMIF('Torrance Pro Forma'!$B$8:$ED$8,'Annual Pro Forma'!G$8,'Torrance Pro Forma'!$B29:$ED29) -> 0 | H29: =SUMIF('Torrance Pro Forma'!$B$8:$ED$8,'Annual Pro Forma'!H$8,'Torrance Pro Forma'!$B29:$ED29) -> 251360.67 | I29: =SUMIF('Torrance Pro Forma'!$B$8:$ED$8,'Annual Pro Forma'!I$8,'Torrance Pro Forma'!$B29:$ED29) -> 256319.74 | J29: =SUMIF('Torrance Pro Forma'!$B$8:$ED$8,'Annual Pro Forma'!J$8,'Torrance Pro Forma'!$B29:$ED29) -> 261384.94 | ... M29: =SUMIF('Torrance Pro Forma'!$B$8:$ED$8,'Annual Pro Forma'!M$8,'Torrance Pro Forma'!$B29:$ED29) -> 277240.96
C30: =SUMIF('Torrance Pro Forma'!$B$8:$ED$8,'Annual Pro Forma'!C$8,'Torrance Pro Forma'!$B30:$ED30) -> 0 | D30: =SUMIF('Torrance Pro Forma'!$B$8:$ED$8,'Annual Pro Forma'!D$8,'Torrance Pro Forma'!$B30:$ED30) -> 0 | E30: =SUMIF('Torrance Pro Forma'!$B$8:$ED$8,'Annual Pro Forma'!E$8,'Torrance Pro Forma'!$B30:$ED30) -> 0 | F30: =SUMIF('Torrance Pro Forma'!$B$8:$ED$8,'Annual Pro Forma'!F$8,'Torrance Pro Forma'!$B30:$ED30) -> 0 | G30: =SUMIF('Torrance Pro Forma'!$B$8:$ED$8,'Annual Pro Forma'!G$8,'Torrance Pro Forma'!$B30:$ED30) -> 0 | H30: =SUMIF('Torrance Pro Forma'!$B$8:$ED$8,'Annual Pro Forma'!H$8,'Torrance Pro Forma'!$B30:$ED30) -> 0 | I30: =SUMIF('Torrance Pro Forma'!$B$8:$ED$8,'Annual Pro Forma'!I$8,'Torrance Pro Forma'!$B30:$ED30) -> 0 | J30: =SUMIF('Torrance Pro Forma'!$B$8:$ED$8,'Annual Pro Forma'!J$8,'Torrance Pro Forma'!$B30:$ED30) -> 0 | ... M30: =SUMIF('Torrance Pro Forma'!$B$8:$ED$8,'Annual Pro Forma'!M$8,'Torrance Pro Forma'!$B30:$ED30) -> 0
A31: Total Tenant Revenue | C31: =SUMIF('Torrance Pro Forma'!$B$8:$ED$8,'Annual Pro Forma'!C$8,'Torrance Pro Forma'!$B31:$ED31) -> 1135000 | D31: =SUMIF('Torrance Pro Forma'!$B$8:$ED$8,'Annual Pro Forma'!D$8,'Torrance Pro Forma'!$B31:$ED31) -> 1157600 | E31: =SUMIF('Torrance Pro Forma'!$B$8:$ED$8,'Annual Pro Forma'!E$8,'Torrance Pro Forma'!$B31:$ED31) -> 1180658 | F31: =SUMIF('Torrance Pro Forma'!$B$8:$ED$8,'Annual Pro Forma'!F$8,'Torrance Pro Forma'!$B31:$ED31) -> 1204183.3 | G31: =SUMIF('Torrance Pro Forma'!$B$8:$ED$8,'Annual Pro Forma'!G$8,'Torrance Pro Forma'!$B31:$ED31) -> 0 | H31: =SUMIF('Torrance Pro Forma'!$B$8:$ED$8,'Annual Pro Forma'!H$8,'Torrance Pro Forma'!$B31:$ED31) -> 5575558.5 | I31: =SUMIF('Torrance Pro Forma'!$B$8:$ED$8,'Annual Pro Forma'!I$8,'Torrance Pro Forma'!$B31:$ED31) -> 5173903.8 | J31: =SUMIF('Torrance Pro Forma'!$B$8:$ED$8,'Annual Pro Forma'!J$8,'Torrance Pro Forma'!$B31:$ED31) -> 5278473 | ... M31: =SUMIF('Torrance Pro Forma'!$B$8:$ED$8,'Annual Pro Forma'!M$8,'Torrance Pro Forma'!$B31:$ED31) -> 5604941.4
C32: =SUMIF('Torrance Pro Forma'!$B$8:$ED$8,'Annual Pro Forma'!C$8,'Torrance Pro Forma'!$B32:$ED32) -> 0 | D32: =SUMIF('Torrance Pro Forma'!$B$8:$ED$8,'Annual Pro Forma'!D$8,'Torrance Pro Forma'!$B32:$ED32) -> 0 | E32: =SUMIF('Torrance Pro Forma'!$B$8:$ED$8,'Annual Pro Forma'!E$8,'Torrance Pro Forma'!$B32:$ED32) -> 0 | F32: =SUMIF('Torrance Pro Forma'!$B$8:$ED$8,'Annual Pro Forma'!F$8,'Torrance Pro Forma'!$B32:$ED32) -> 0 | G32: =SUMIF('Torrance Pro Forma'!$B$8:$ED$8,'Annual Pro Forma'!G$8,'Torrance Pro Forma'!$B32:$ED32) -> 0 | H32: =SUMIF('Torrance Pro Forma'!$B$8:$ED$8,'Annual Pro Forma'!H$8,'Torrance Pro Forma'!$B32:$ED32) -> 0 | I32: =SUMIF('Torrance Pro Forma'!$B$8:$ED$8,'Annual Pro Forma'!I$8,'Torrance Pro Forma'!$B32:$ED32) -> 0 | J32: =SUMIF('Torrance Pro Forma'!$B$8:$ED$8,'Annual Pro Forma'!J$8,'Torrance Pro Forma'!$B32:$ED32) -> 0 | ... M32: =SUMIF('Torrance Pro Forma'!$B$8:$ED$8,'Annual Pro Forma'!M$8,'Torrance Pro Forma'!$B32:$ED32) -> 0
A33: Other Income | C33: =SUMIF('Torrance Pro Forma'!$B$8:$ED$8,'Annual Pro Forma'!C$8,'Torrance Pro Forma'!$B33:$ED33) -> 0 | D33: =SUMIF('Torrance Pro Forma'!$B$8:$ED$8,'Annual Pro Forma'!D$8,'Torrance Pro Forma'!$B33:$ED33) -> 0 | E33: =SUMIF('Torrance Pro Forma'!$B$8:$ED$8,'Annual Pro Forma'!E$8,'Torrance Pro Forma'!$B33:$ED33) -> 0 | F33: =SUMIF('Torrance Pro Forma'!$B$8:$ED$8,'Annual Pro Forma'!F$8,'Torrance Pro Forma'!$B33:$ED33) -> 0 | G33: =SUMIF('Torrance Pro Forma'!$B$8:$ED$8,'Annual Pro Forma'!G$8,'Torrance Pro Forma'!$B33:$ED33) -> 0 | H33: =SUMIF('Torrance Pro Forma'!$B$8:$ED$8,'Annual Pro Forma'!H$8,'Torrance Pro Forma'!$B33:$ED33) -> 0 | I33: =SUMIF('Torrance Pro Forma'!$B$8:$ED$8,'Annual Pro Forma'!I$8,'Torrance Pro Forma'!$B33:$ED33) -> 0 | J33: =SUMIF('Torrance Pro Forma'!$B$8:$ED$8,'Annual Pro Forma'!J$8,'Torrance Pro Forma'!$B33:$ED33) -> 0 | ... M33: =SUMIF('Torrance Pro Forma'!$B$8:$ED$8,'Annual Pro Forma'!M$8,'Torrance Pro Forma'!$B33:$ED33) -> 0
A34: Parking Income | C34: =SUMIF('Torrance Pro Forma'!$B$8:$ED$8,'Annual Pro Forma'!C$8,'Torrance Pro Forma'!$B34:$ED34) -> 190740 | D34: =SUMIF('Torrance Pro Forma'!$B$8:$ED$8,'Annual Pro Forma'!D$8,'Torrance Pro Forma'!$B34:$ED34) -> 194554.8 | E34: =SUMIF('Torrance Pro Forma'!$B$8:$ED$8,'Annual Pro Forma'!E$8,'Torrance Pro Forma'!$B34:$ED34) -> 198445.9 | F34: =SUMIF('Torrance Pro Forma'!$B$8:$ED$8,'Annual Pro Forma'!F$8,'Torrance Pro Forma'!$B34:$ED34) -> 202414.81 | G34: =SUMIF('Torrance Pro Forma'!$B$8:$ED$8,'Annual Pro Forma'!G$8,'Torrance Pro Forma'!$B34:$ED34) -> 0 | H34: =SUMIF('Torrance Pro Forma'!$B$8:$ED$8,'Annual Pro Forma'!H$8,'Torrance Pro Forma'!$B34:$ED34) -> 210592.37 | I34: =SUMIF('Torrance Pro Forma'!$B$8:$ED$8,'Annual Pro Forma'!I$8,'Torrance Pro Forma'!$B34:$ED34) -> 214804.22 | J34: =SUMIF('Torrance Pro Forma'!$B$8:$ED$8,'Annual Pro Forma'!J$8,'Torrance Pro Forma'!$B34:$ED34) -> 219100.3 | ... M34: =SUMIF('Torrance Pro Forma'!$B$8:$ED$8,'Annual Pro Forma'!M$8,'Torrance Pro Forma'!$B34:$ED34) -> 232511
A35: Total Other Income | C35: =SUMIF('Torrance Pro Forma'!$B$8:$ED$8,'Annual Pro Forma'!C$8,'Torrance Pro Forma'!$B35:$ED35) -> 190740 | D35: =SUMIF('Torrance Pro Forma'!$B$8:$ED$8,'Annual Pro Forma'!D$8,'Torrance Pro Forma'!$B35:$ED35) -> 194554.8 | E35: =SUMIF('Torrance Pro Forma'!$B$8:$ED$8,'Annual Pro Forma'!E$8,'Torrance Pro Forma'!$B35:$ED35) -> 198445.9 | F35: =SUMIF('Torrance Pro Forma'!$B$8:$ED$8,'Annual Pro Forma'!F$8,'Torrance Pro Forma'!$B35:$ED35) -> 202414.81 | G35: =SUMIF('Torrance Pro Forma'!$B$8:$ED$8,'Annual Pro Forma'!G$8,'Torrance Pro Forma'!$B35:$ED35) -> 0 | H35: =SUMIF('Torrance Pro Forma'!$B$8:$ED$8,'Annual Pro Forma'!H$8,'Torrance Pro Forma'!$B35:$ED35) -> 210592.37 | I35: =SUMIF('Torrance Pro Forma'!$B$8:$ED$8,'Annual Pro Forma'!I$8,'Torrance Pro Forma'!$B35:$ED35) -> 214804.22 | J35: =SUMIF('Torrance Pro Forma'!$B$8:$ED$8,'Annual Pro Forma'!J$8,'Torrance Pro Forma'!$B35:$ED35) -> 219100.3 | ... M35: =SUMIF('Torrance Pro Forma'!$B$8:$ED$8,'Annual Pro Forma'!M$8,'Torrance Pro Forma'!$B35:$ED35) -> 232511
C36: =SUMIF('Torrance Pro Forma'!$B$8:$ED$8,'Annual Pro Forma'!C$8,'Torrance Pro Forma'!$B36:$ED36) -> 0 | D36: =SUMIF('Torrance Pro Forma'!$B$8:$ED$8,'Annual Pro Forma'!D$8,'Torrance Pro Forma'!$B36:$ED36) -> 0 | E36: =SUMIF('Torrance Pro Forma'!$B$8:$ED$8,'Annual Pro Forma'!E$8,'Torrance Pro Forma'!$B36:$ED36) -> 0 | F36: =SUMIF('Torrance Pro Forma'!$B$8:$ED$8,'Annual Pro Forma'!F$8,'Torrance Pro Forma'!$B36:$ED36) -> 0 | G36: =SUMIF('Torrance Pro Forma'!$B$8:$ED$8,'Annual Pro Forma'!G$8,'Torrance Pro Forma'!$B36:$ED36) -> 0 | H36: =SUMIF('Torrance Pro Forma'!$B$8:$ED$8,'Annual Pro Forma'!H$8,'Torrance Pro Forma'!$B36:$ED36) -> 0 | I36: =SUMIF('Torrance Pro Forma'!$B$8:$ED$8,'Annual Pro Forma'!I$8,'Torrance Pro Forma'!$B36:$ED36) -> 0 | J36: =SUMIF('Torrance Pro Forma'!$B$8:$ED$8,'Annual Pro Forma'!J$8,'Torrance Pro Forma'!$B36:$ED36) -> 0 | ... M36: =SUMIF('Torrance Pro Forma'!$B$8:$ED$8,'Annual Pro Forma'!M$8,'Torrance Pro Forma'!$B36:$ED36) -> 0
A37: Potential Gross Revenue | C37: =SUMIF('Torrance Pro Forma'!$B$8:$ED$8,'Annual Pro Forma'!C$8,'Torrance Pro Forma'!$B37:$ED37) -> 1325740 | D37: =SUMIF('Torrance Pro Forma'!$B$8:$ED$8,'Annual Pro Forma'!D$8,'Torrance Pro Forma'!$B37:$ED37) -> 1352154.8 | E37: =SUMIF('Torrance Pro Forma'!$B$8:$ED$8,'Annual Pro Forma'!E$8,'Torrance Pro Forma'!$B37:$ED37) -> 1379103.9 | F37: =SUMIF('Torrance Pro Forma'!$B$8:$ED$8,'Annual Pro Forma'!F$8,'Torrance Pro Forma'!$B37:$ED37) -> 1406598.2 | G37: =SUMIF('Torrance Pro Forma'!$B$8:$ED$8,'Annual Pro Forma'!G$8,'Torrance Pro Forma'!$B37:$ED37) -> 0 | H37: =SUMIF('Torrance Pro Forma'!$B$8:$ED$8,'Annual Pro Forma'!H$8,'Torrance Pro Forma'!$B37:$ED37) -> 5786150.8 | I37: =SUMIF('Torrance Pro Forma'!$B$8:$ED$8,'Annual Pro Forma'!I$8,'Torrance Pro Forma'!$B37:$ED37) -> 5388708 | J37: =SUMIF('Torrance Pro Forma'!$B$8:$ED$8,'Annual Pro Forma'!J$8,'Torrance Pro Forma'!$B37:$ED37) -> 5497573.3 | ... M37: =SUMIF('Torrance Pro Forma'!$B$8:$ED$8,'Annual Pro Forma'!M$8,'Torrance Pro Forma'!$B37:$ED37) -> 5837452.4
C38: =SUMIF('Torrance Pro Forma'!$B$8:$ED$8,'Annual Pro Forma'!C$8,'Torrance Pro Forma'!$B38:$ED38) -> 0 | D38: =SUMIF('Torrance Pro Forma'!$B$8:$ED$8,'Annual Pro Forma'!D$8,'Torrance Pro Forma'!$B38:$ED38) -> 0 | E38: =SUMIF('Torrance Pro Forma'!$B$8:$ED$8,'Annual Pro Forma'!E$8,'Torrance Pro Forma'!$B38:$ED38) -> 0 | F38: =SUMIF('Torrance Pro Forma'!$B$8:$ED$8,'Annual Pro Forma'!F$8,'Torrance Pro Forma'!$B38:$ED38) -> 0 | G38: =SUMIF('Torrance Pro Forma'!$B$8:$ED$8,'Annual Pro Forma'!G$8,'Torrance Pro Forma'!$B38:$ED38) -> 0 | H38: =SUMIF('Torrance Pro Forma'!$B$8:$ED$8,'Annual Pro Forma'!H$8,'Torrance Pro Forma'!$B38:$ED38) -> 0 | I38: =SUMIF('Torrance Pro Forma'!$B$8:$ED$8,'Annual Pro Forma'!I$8,'Torrance Pro Forma'!$B38:$ED38) -> 0 | J38: =SUMIF('Torrance Pro Forma'!$B$8:$ED$8,'Annual Pro Forma'!J$8,'Torrance Pro Forma'!$B38:$ED38) -> 0 | ... M38: =SUMIF('Torrance Pro Forma'!$B$8:$ED$8,'Annual Pro Forma'!M$8,'Torrance Pro Forma'!$B38:$ED38) -> 0
A39: General Vacancy & Credit Loss | C39: =SUMIF('Torrance Pro Forma'!$B$8:$ED$8,'Annual Pro Forma'!C$8,'Torrance Pro Forma'!$B39:$ED39) -> 0 | D39: =SUMIF('Torrance Pro Forma'!$B$8:$ED$8,'Annual Pro Forma'!D$8,'Torrance Pro Forma'!$B39:$ED39) -> 0 | E39: =SUMIF('Torrance Pro Forma'!$B$8:$ED$8,'Annual Pro Forma'!E$8,'Torrance Pro Forma'!$B39:$ED39) -> 0 | F39: =SUMIF('Torrance Pro Forma'!$B$8:$ED$8,'Annual Pro Forma'!F$8,'Torrance Pro Forma'!$B39:$ED39) -> 0 | G39: =SUMIF('Torrance Pro Forma'!$B$8:$ED$8,'Annual Pro Forma'!G$8,'Torrance Pro Forma'!$B39:$ED39) -> 0 | H39: =SUMIF('Torrance Pro Forma'!$B$8:$ED$8,'Annual Pro Forma'!H$8,'Torrance Pro Forma'!$B39:$ED39) -> 0 | I39: =SUMIF('Torrance Pro Forma'!$B$8:$ED$8,'Annual Pro Forma'!I$8,'Torrance Pro Forma'!$B39:$ED39) -> 0 | J39: =SUMIF('Torrance Pro Forma'!$B$8:$ED$8,'Annual Pro Forma'!J$8,'Torrance Pro Forma'!$B39:$ED39) -> 0 | ... M39: =SUMIF('Torrance Pro Forma'!$B$8:$ED$8,'Annual Pro Forma'!M$8,'Torrance Pro Forma'!$B39:$ED39) -> 0
A40: Vacancy & L2L | C40: =SUMIF('Torrance Pro Forma'!$B$8:$ED$8,'Annual Pro Forma'!C$8,'Torrance Pro Forma'!$B40:$ED40) -> 0 | D40: =SUMIF('Torrance Pro Forma'!$B$8:$ED$8,'Annual Pro Forma'!D$8,'Torrance Pro Forma'!$B40:$ED40) -> 0 | E40: =SUMIF('Torrance Pro Forma'!$B$8:$ED$8,'Annual Pro Forma'!E$8,'Torrance Pro Forma'!$B40:$ED40) -> 0 | F40: =SUMIF('Torrance Pro Forma'!$B$8:$ED$8,'Annual Pro Forma'!F$8,'Torrance Pro Forma'!$B40:$ED40) -> 0 | G40: =SUMIF('Torrance Pro Forma'!$B$8:$ED$8,'Annual Pro Forma'!G$8,'Torrance Pro Forma'!$B40:$ED40) -> 0 | H40: =SUMIF('Torrance Pro Forma'!$B$8:$ED$8,'Annual Pro Forma'!H$8,'Torrance Pro Forma'!$B40:$ED40) -> 0 | I40: =SUMIF('Torrance Pro Forma'!$B$8:$ED$8,'Annual Pro Forma'!I$8,'Torrance Pro Forma'!$B40:$ED40) -> 0 | J40: =SUMIF('Torrance Pro Forma'!$B$8:$ED$8,'Annual Pro Forma'!J$8,'Torrance Pro Forma'!$B40:$ED40) -> 0 | ... M40: =SUMIF('Torrance Pro Forma'!$B$8:$ED$8,'Annual Pro Forma'!M$8,'Torrance Pro Forma'!$B40:$ED40) -> 0
A41: Total Vacancy & Credit Loss | C41: =SUMIF('Torrance Pro Forma'!$B$8:$ED$8,'Annual Pro Forma'!C$8,'Torrance Pro Forma'!$B41:$ED41) -> 0 | D41: =SUMIF('Torrance Pro Forma'!$B$8:$ED$8,'Annual Pro Forma'!D$8,'Torrance Pro Forma'!$B41:$ED41) -> 0 | E41: =SUMIF('Torrance Pro Forma'!$B$8:$ED$8,'Annual Pro Forma'!E$8,'Torrance Pro Forma'!$B41:$ED41) -> 0 | F41: =SUMIF('Torrance Pro Forma'!$B$8:$ED$8,'Annual Pro Forma'!F$8,'Torrance Pro Forma'!$B41:$ED41) -> 0 | G41: =SUMIF('Torrance Pro Forma'!$B$8:$ED$8,'Annual Pro Forma'!G$8,'Torrance Pro Forma'!$B41:$ED41) -> 0 | H41: =SUMIF('Torrance Pro Forma'!$B$8:$ED$8,'Annual Pro Forma'!H$8,'Torrance Pro Forma'!$B41:$ED41) -> 0 | I41: =SUMIF('Torrance Pro Forma'!$B$8:$ED$8,'Annual Pro Forma'!I$8,'Torrance Pro Forma'!$B41:$ED41) -> 0 | J41: =SUMIF('Torrance Pro Forma'!$B$8:$ED$8,'Annual Pro Forma'!J$8,'Torrance Pro Forma'!$B41:$ED41) -> 0 | ... M41: =SUMIF('Torrance Pro Forma'!$B$8:$ED$8,'Annual Pro Forma'!M$8,'Torrance Pro Forma'!$B41:$ED41) -> 0
C42: =SUMIF('Torrance Pro Forma'!$B$8:$ED$8,'Annual Pro Forma'!C$8,'Torrance Pro Forma'!$B42:$ED42) -> 0 | D42: =SUMIF('Torrance Pro Forma'!$B$8:$ED$8,'Annual Pro Forma'!D$8,'Torrance Pro Forma'!$B42:$ED42) -> 0 | E42: =SUMIF('Torrance Pro Forma'!$B$8:$ED$8,'Annual Pro Forma'!E$8,'Torrance Pro Forma'!$B42:$ED42) -> 0 | F42: =SUMIF('Torrance Pro Forma'!$B$8:$ED$8,'Annual Pro Forma'!F$8,'Torrance Pro Forma'!$B42:$ED42) -> 0 | G42: =SUMIF('Torrance Pro Forma'!$B$8:$ED$8,'Annual Pro Forma'!G$8,'Torrance Pro Forma'!$B42:$ED42) -> 0 | H42: =SUMIF('Torrance Pro Forma'!$B$8:$ED$8,'Annual Pro Forma'!H$8,'Torrance Pro Forma'!$B42:$ED42) -> 0 | I42: =SUMIF('Torrance Pro Forma'!$B$8:$ED$8,'Annual Pro Forma'!I$8,'Torrance Pro Forma'!$B42:$ED42) -> 0 | J42: =SUMIF('Torrance Pro Forma'!$B$8:$ED$8,'Annual Pro Forma'!J$8,'Torrance Pro Forma'!$B42:$ED42) -> 0 | ... M42: =SUMIF('Torrance Pro Forma'!$B$8:$ED$8,'Annual Pro Forma'!M$8,'Torrance Pro Forma'!$B42:$ED42) -> 0
A43: Effective Gross Revenue | C43: =SUMIF('Torrance Pro Forma'!$B$8:$ED$8,'Annual Pro Forma'!C$8,'Torrance Pro Forma'!$B43:$ED43) -> 1325740 | D43: =SUMIF('Torrance Pro Forma'!$B$8:$ED$8,'Annual Pro Forma'!D$8,'Torrance Pro Forma'!$B43:$ED43) -> 1352154.8 | E43: =SUMIF('Torrance Pro Forma'!$B$8:$ED$8,'Annual Pro Forma'!E$8,'Torrance Pro Forma'!$B43:$ED43) -> 1379103.9 | F43: =SUMIF('Torrance Pro Forma'!$B$8:$ED$8,'Annual Pro Forma'!F$8,'Torrance Pro Forma'!$B43:$ED43) -> 1406598.2 | G43: =SUMIF('Torrance Pro Forma'!$B$8:$ED$8,'Annual Pro Forma'!G$8,'Torrance Pro Forma'!$B43:$ED43) -> 0 | H43: =SUMIF('Torrance Pro Forma'!$B$8:$ED$8,'Annual Pro Forma'!H$8,'Torrance Pro Forma'!$B43:$ED43) -> 5786150.8 | I43: =SUMIF('Torrance Pro Forma'!$B$8:$ED$8,'Annual Pro Forma'!I$8,'Torrance Pro Forma'!$B43:$ED43) -> 5388708 | J43: =SUMIF('Torrance Pro Forma'!$B$8:$ED$8,'Annual Pro Forma'!J$8,'Torrance Pro Forma'!$B43:$ED43) -> 5497573.3 | ... M43: =SUMIF('Torrance Pro Forma'!$B$8:$ED$8,'Annual Pro Forma'!M$8,'Torrance Pro Forma'!$B43:$ED43) -> 5837452.4
...

Sheet Torrance Pro Forma
C1: year 1-5 | D1: year 6-10
A2: Market Rent Inflation | C2: 0.03 | D2: 0.022
A3: Expense Inflation | C3: 0.03
A4: Cash Flow Projections
A5: Redlands Industrial Property
B7: Actuals | C7: Forecast | D7: Forecast | E7: Forecast | F7: Forecast | G7: Forecast | H7: Forecast | I7: Forecast | J7: Forecast | K7: Forecast | L7: Forecast | M7: Forecast | N7: Forecast | O7: Forecast | P7: Forecast | Q7: Forecast | R7: Forecast | S7: Forecast | T7: Forecast | U7: Forecast | V7: Forecast | W7: Forecast | X7: Forecast | Y7: Forecast | Z7: Forecast | AA7: Forecast | AB7: Forecast | AC7: Forecast | AD7: Forecast | AE7: Forecast | AF7: Forecast | AG7: Forecast | AH7: Forecast | AI7: Forecast | AJ7: Forecast | AK7: Forecast | AL7: Forecast | AM7: Forecast | AN7: Forecast | AO7: Forecast | AP7: Forecast | AQ7: Forecast | AR7: Forecast | AS7: Forecast | AT7: Forecast | AU7: Forecast | AV7: Forecast | AW7: Forecast | AX7: Forecast | AY7: Forecast | AZ7: Forecast | BA7: Forecast | BB7: Forecast | BC7: Forecast | BD7: Forecast | BE7: Forecast | BF7: Forecast | BG7: Forecast | BH7: Forecast | BI7: Forecast | BJ7: Forecast | BK7: Forecast | BL7: Forecast | BM7: Forecast | BN7: Forecast | BO7: Forecast | BP7: Forecast | BQ7: Forecast | BR7: Forecast | BS7: Forecast | BT7: Forecast | BU7: Forecast | BV7: Forecast | BW7: Forecast | BX7: Forecast | BY7: Forecast | BZ7: Forecast | CA7: Forecast | CB7: Forecast | CC7: Forecast | CD7: Forecast | CE7: Forecast | CF7: Forecast | CG7: Forecast | CH7: Forecast | CI7: Forecast | CJ7: Forecast | CK7: Forecast | CL7: Forecast | CM7: Forecast | CN7: Forecast | CO7: Forecast | CP7: Forecast | CQ7: Forecast | CR7: Forecast | CS7: Forecast | CT7: Forecast | CU7: Forecast | CV7: Forecast | CW7: Forecast | CX7: Forecast | CY7: Forecast | CZ7: Forecast | DA7: Forecast | DB7: Forecast | DC7: Forecast | DD7: Forecast | DE7: Forecast | DF7: Forecast | DG7: Forecast | DH7: Forecast | DI7: Forecast | DJ7: Forecast | DK7: Forecast | DL7: Forecast | DM7: Forecast | DN7: Forecast | DO7: Forecast | DP7: Forecast | DQ7: Forecast | DR7: Forecast | DS7: Forecast | DT7: Forecast | DU7: Forecast | DV7: Forecast | DW7: Forecast | DX7: Forecast | DY7: Forecast | DZ7: Forecast | EA7: Forecast | EB7: Forecast | EC7: Forecast | ED7: Forecast
B8: =ROUNDUP(B$9/12,0) -> 0 | C8: =ROUNDUP(C$9/12,0) -> 1 | D8: =ROUNDUP(D$9/12,0) -> 1 | E8: =ROUNDUP(E$9/12,0) -> 1 | F8: =ROUNDUP(F$9/12,0) -> 1 | G8: =ROUNDUP(G$9/12,0) -> 1 | H8: =ROUNDUP(H$9/12,0) -> 1 | I8: =ROUNDUP(I$9/12,0) -> 1 | ... ED8: =ROUNDUP(ED$9/12,0) -> 11
C9: {=_xlfn.SEQUENCE(1,('Torrance Inputs'!$D$20+1)*12,1,1)} -> 1 | D9: 2 | E9: 3 | F9: 4 | G9: 5 | H9: 6 | I9: 7 | J9: 8 | K9: 9 | L9: 10 | M9: 11 | N9: 12 | O9: 13 | P9: 14 | Q9: 15 | R9: 16 | S9: 17 | T9: 18 | U9: 19 | V9: 20 | W9: 21 | X9: 22 | Y9: 23 | Z9: 24 | AA9: 25 | AB9: 26 | AC9: 27 | AD9: 28 | AE9: 29 | AF9: 30 | AG9: 31 | AH9: 32 | AI9: 33 | AJ9: 34 | AK9: 35 | AL9: 36 | AM9: 37 | AN9: 38 | AO9: 39 | AP9: 40 | AQ9: 41 | AR9: 42 | AS9: 43 | AT9: 44 | AU9: 45 | AV9: 46 | AW9: 47 | AX9: 48 | AY9: 49 | AZ9: 50 | BA9: 51 | BB9: 52 | BC9: 53 | BD9: 54 | BE9: 55 | BF9: 56 | BG9: 57 | BH9: 58 | BI9: 59 | BJ9: 60 | BK9: 61 | BL9: 62 | BM9: 63 | BN9: 64 | BO9: 65 | BP9: 66 | BQ9: 67 | BR9: 68 | BS9: 69 | BT9: 70 | BU9: 71 | BV9: 72 | BW9: 73 | BX9: 74 | BY9: 75 | BZ9: 76 | CA9: 77 | CB9: 78 | CC9: 79 | CD9: 80 | CE9: 81 | CF9: 82 | CG9: 83 | CH9: 84 | CI9: 85 | CJ9: 86 | CK9: 87 | CL9: 88 | CM9: 89 | CN9: 90 | CO9: 91 | CP9: 92 | CQ9: 93 | CR9: 94 | CS9: 95 | CT9: 96 | CU9: 97 | CV9: 98 | CW9: 99 | CX9: 100 | CY9: 101 | CZ9: 102 | DA9: 103 | DB9: 104 | DC9: 105 | DD9: 106 | DE9: 107 | DF9: 108 | DG9: 109 | DH9: 110 | DI9: 111 | DJ9: 112 | DK9: 113 | DL9: 114 | DM9: 115 | DN9: 116 | DO9: 117 | DP9: 118 | DQ9: 119 | DR9: 120 | DS9: 121 | DT9: 122 | DU9: 123 | DV9: 124 | DW9: 125 | DX9: 126 | DY9: 127 | DZ9: 128 | EA9: 129 | EB9: 130 | EC9: 131 | ED9: 132
A10: Months | B10: =EDATE(C10,-12) -> 45292 | C10: =EDATE('Torrance Inputs'!analysis_start,0) -> 45658 | D10: =EOMONTH(C10,1) -> 45716 | E10: =EOMONTH(D10,1) -> 45747 | F10: =EOMONTH(E10,1) -> 45777 | G10: =EOMONTH(F10,1) -> 45808 | H10: =EOMONTH(G10,1) -> 45838 | I10: =EOMONTH(H10,1) -> 45869 | J10: =EOMONTH(I10,1) -> 45900 | K10: =EOMONTH(J10,1) -> 45930 | ... ED10: =EOMONTH(EC10,1) -> 49674
A12: Rental Revenue
A13: Base Rent / SF / Year | C13: =(C$16/'Torrance Inputs'!$D$10)*12 -> 4 | D13: =(D$16/'Torrance Inputs'!$D$10)*12 -> 4 | E13: =(E$16/'Torrance Inputs'!$D$10)*12 -> 4 | F13: =(F$16/'Torrance Inputs'!$D$10)*12 -> 4 | G13: =(G$16/'Torrance Inputs'!$D$10)*12 -> 4 | H13: =(H$16/'Torrance Inputs'!$D$10)*12 -> 4 | I13: =(I$16/'Torrance Inputs'!$D$10)*12 -> 4 | J13: =(J$16/'Torrance Inputs'!$D$10)*12 -> 4 | ... ED13: =(ED$16/'Torrance Inputs'!$D$10)*12 -> 19.582963
A14: Tenant 1 | C14: =IF(AND(C$10>='Torrance Inputs'!$N$38,C$10<'Torrance Inputs'!$N$40),'Torrance Inputs'!$M$41*(1+'Torrance Inputs'!$S$39)^('Torrance Pro Forma'!C$8-1),IF(C$10>='Torrance Inputs'!$I$18,'Torrance Inputs'!$H$22*(1+'Torrance Inputs'!$I$23)^(C$8-'Torrance Inputs'!$H$18),IF(C$10>=EDATE('Torrance Inputs'!$D$31,'Torrance Inputs'!$D$30),'Torrance Inputs'!$C$27*(1+'Torrance Inputs'!$D$35)^(ROUNDDOWN((C$9-1)/12,0)),0))) -> 91666.667 | D14: =IF(AND(D$10>='Torrance Inputs'!$N$38,D$10<'Torrance Inputs'!$N$40),'Torrance Inputs'!$M$41*(1+'Torrance Inputs'!$S$39)^('Torrance Pro Forma'!D$8-1),IF(D$10>='Torrance Inputs'!$I$18,'Torrance Inputs'!$H$22*(1+'Torrance Inputs'!$I$23)^(D$8-'Torrance Inputs'!$H$18),IF(D$10>=EDATE('Torrance Inputs'!$D$31,'Torrance Inputs'!$D$30),'Torrance Inputs'!$C$27*(1+'Torrance Inputs'!$D$35)^(ROUNDDOWN((D$9-1)/12,0)),0))) -> 91666.667 | E14: =IF(AND(E$10>='Torrance Inputs'!$N$38,E$10<'Torrance Inputs'!$N$40),'Torrance Inputs'!$M$41*(1+'Torrance Inputs'!$S$39)^('Torrance Pro Forma'!E$8-1),IF(E$10>='Torrance Inputs'!$I$18,'Torrance Inputs'!$H$22*(1+'Torrance Inputs'!$I$23)^(E$8-'Torrance Inputs'!$H$18),IF(E$10>=EDATE('Torrance Inputs'!$D$31,'Torrance Inputs'!$D$30),'Torrance Inputs'!$C$27*(1+'Torrance Inputs'!$D$35)^(ROUNDDOWN((E$9-1)/12,0)),0))) -> 91666.667 | F14: =IF(AND(F$10>='Torrance Inputs'!$N$38,F$10<'Torrance Inputs'!$N$40),'Torrance Inputs'!$M$41*(1+'Torrance Inputs'!$S$39)^('Torrance Pro Forma'!F$8-1),IF(F$10>='Torrance Inputs'!$I$18,'Torrance Inputs'!$H$22*(1+'Torrance Inputs'!$I$23)^(F$8-'Torrance Inputs'!$H$18),IF(F$10>=EDATE('Torrance Inputs'!$D$31,'Torrance Inputs'!$D$30),'Torrance Inputs'!$C$27*(1+'Torrance Inputs'!$D$35)^(ROUNDDOWN((F$9-1)/12,0)),0))) -> 91666.667 | G14: =IF(AND(G$10>='Torrance Inputs'!$N$38,G$10<'Torrance Inputs'!$N$40),'Torrance Inputs'!$M$41*(1+'Torrance Inputs'!$S$39)^('Torrance Pro Forma'!G$8-1),IF(G$10>='Torrance Inputs'!$I$18,'Torrance Inputs'!$H$22*(1+'Torrance Inputs'!$I$23)^(G$8-'Torrance Inputs'!$H$18),IF(G$10>=EDATE('Torrance Inputs'!$D$31,'Torrance Inputs'!$D$30),'Torrance Inputs'!$C$27*(1+'Torrance Inputs'!$D$35)^(ROUNDDOWN((G$9-1)/12,0)),0))) -> 91666.667 | H14: =IF(AND(H$10>='Torrance Inputs'!$N$38,H$10<'Torrance Inputs'!$N$40),'Torrance Inputs'!$M$41*(1+'Torrance Inputs'!$S$39)^('Torrance Pro Forma'!H$8-1),IF(H$10>='Torrance Inputs'!$I$18,'Torrance Inputs'!$H$22*(1+'Torrance Inputs'!$I$23)^(H$8-'Torrance Inputs'!$H$18),IF(H$10>=EDATE('Torrance Inputs'!$D$31,'Torrance Inputs'!$D$30),'Torrance Inputs'!$C$27*(1+'Torrance Inputs'!$D$35)^(ROUNDDOWN((H$9-1)/12,0)),0))) -> 91666.667 | I14: =IF(AND(I$10>='Torrance Inputs'!$N$38,I$10<'Torrance Inputs'!$N$40),'Torrance Inputs'!$M$41*(1+'Torrance Inputs'!$S$39)^('Torrance Pro Forma'!I$8-1),IF(I$10>='Torrance Inputs'!$I$18,'Torrance Inputs'!$H$22*(1+'Torrance Inputs'!$I$23)^(I$8-'Torrance Inputs'!$H$18),IF(I$10>=EDATE('Torrance Inputs'!$D$31,'Torrance Inputs'!$D$30),'Torrance Inputs'!$C$27*(1+'Torrance Inputs'!$D$35)^(ROUNDDOWN((I$9-1)/12,0)),0))) -> 91666.667 | J14: =IF(AND(J$10>='Torrance Inputs'!$N$38,J$10<'Torrance Inputs'!$N$40),'Torrance Inputs'!$M$41*(1+'Torrance Inputs'!$S$39)^('Torrance Pro Forma'!J$8-1),IF(J$10>='Torrance Inputs'!$I$18,'Torrance Inputs'!$H$22*(1+'Torrance Inputs'!$I$23)^(J$8-'Torrance Inputs'!$H$18),IF(J$10>=EDATE('Torrance Inputs'!$D$31,'Torrance Inputs'!$D$30),'Torrance Inputs'!$C$27*(1+'Torrance Inputs'!$D$35)^(ROUNDDOWN((J$9-1)/12,0)),0))) -> 91666.667 | ... ED14: =IF(AND(ED$10>='Torrance Inputs'!$N$38,ED$10<'Torrance Inputs'!$N$40),'Torrance Inputs'!$M$41*(1+'Torrance Inputs'!$S$39)^('Torrance Pro Forma'!ED$8-1),IF(ED$10>='Torrance Inputs'!$I$18,'Torrance Inputs'!$H$22*(1+'Torrance Inputs'!$I$23)^(ED$8-'Torrance Inputs'!$H$18),IF(ED$10>=EDATE('Torrance Inputs'!$D$31,'Torrance Inputs'!$D$30),'Torrance Inputs'!$C$27*(1+'Torrance Inputs'!$D$35)^(ROUNDDOWN((ED$9-1)/12,0)),0))) -> 224388.12
A15: Tenant 2 | C15: =IF(C$10>='Torrance Inputs'!$I$18,'Torrance Inputs'!$H$22*(1+'Torrance Inputs'!$I$23)^(C8-'Torrance Inputs'!$M$18),IF(C$10>=EDATE('Torrance Inputs'!$D$31,'Torrance Inputs'!$D$30),'Torrance Inputs'!$C$27*(1+'Torrance Inputs'!$D$35)^(ROUNDDOWN((C$9-1)/12,0)),0)) -> 0 | D15: =IF(D$10>='Torrance Inputs'!$I$18,'Torrance Inputs'!$H$22*(1+'Torrance Inputs'!$I$23)^(D8-'Torrance Inputs'!$M$18),IF(D$10>=EDATE('Torrance Inputs'!$D$31,'Torrance Inputs'!$D$30),'Torrance Inputs'!$C$27*(1+'Torrance Inputs'!$D$35)^(ROUNDDOWN((D$9-1)/12,0)),0)) -> 0 | E15: =IF(E$10>='Torrance Inputs'!$I$18,'Torrance Inputs'!$H$22*(1+'Torrance Inputs'!$I$23)^(E8-'Torrance Inputs'!$M$18),IF(E$10>=EDATE('Torrance Inputs'!$D$31,'Torrance Inputs'!$D$30),'Torrance Inputs'!$C$27*(1+'Torrance Inputs'!$D$35)^(ROUNDDOWN((E$9-1)/12,0)),0)) -> 0 | F15: =IF(F$10>='Torrance Inputs'!$I$18,'Torrance Inputs'!$H$22*(1+'Torrance Inputs'!$I$23)^(F8-'Torrance Inputs'!$M$18),IF(F$10>=EDATE('Torrance Inputs'!$D$31,'Torrance Inputs'!$D$30),'Torrance Inputs'!$C$27*(1+'Torrance Inputs'!$D$35)^(ROUNDDOWN((F$9-1)/12,0)),0)) -> 0 | G15: =IF(G$10>='Torrance Inputs'!$I$18,'Torrance Inputs'!$H$22*(1+'Torrance Inputs'!$I$23)^(G8-'Torrance Inputs'!$M$18),IF(G$10>=EDATE('Torrance Inputs'!$D$31,'Torrance Inputs'!$D$30),'Torrance Inputs'!$C$27*(1+'Torrance Inputs'!$D$35)^(ROUNDDOWN((G$9-1)/12,0)),0)) -> 0 | H15: =IF(H$10>='Torrance Inputs'!$I$18,'Torrance Inputs'!$H$22*(1+'Torrance Inputs'!$I$23)^(H8-'Torrance Inputs'!$M$18),IF(H$10>=EDATE('Torrance Inputs'!$D$31,'Torrance Inputs'!$D$30),'Torrance Inputs'!$C$27*(1+'Torrance Inputs'!$D$35)^(ROUNDDOWN((H$9-1)/12,0)),0)) -> 0 | I15: =IF(I$10>='Torrance Inputs'!$I$18,'Torrance Inputs'!$H$22*(1+'Torrance Inputs'!$I$23)^(I8-'Torrance Inputs'!$M$18),IF(I$10>=EDATE('Torrance Inputs'!$D$31,'Torrance Inputs'!$D$30),'Torrance Inputs'!$C$27*(1+'Torrance Inputs'!$D$35)^(ROUNDDOWN((I$9-1)/12,0)),0)) -> 0 | J15: =IF(J$10>='Torrance Inputs'!$I$18,'Torrance Inputs'!$H$22*(1+'Torrance Inputs'!$I$23)^(J8-'Torrance Inputs'!$M$18),IF(J$10>=EDATE('Torrance Inputs'!$D$31,'Torrance Inputs'!$D$30),'Torrance Inputs'!$C$27*(1+'Torrance Inputs'!$D$35)^(ROUNDDOWN((J$9-1)/12,0)),0)) -> 0 | ... ED15: =IF(ED$10>='Torrance Inputs'!$I$18,'Torrance Inputs'!$H$22*(1+'Torrance Inputs'!$I$23)^(ED8-'Torrance Inputs'!$M$18),IF(ED$10>=EDATE('Torrance Inputs'!$D$31,'Torrance Inputs'!$D$30),'Torrance Inputs'!$C$27*(1+'Torrance Inputs'!$D$35)^(ROUNDDOWN((ED$9-1)/12,0)),0)) -> 224388.12
A16: Potential Base Rent | C16: =SUM(C14:C15) -> 91666.667 | D16: =SUM(D14:D15) -> 91666.667 | E16: =SUM(E14:E15) -> 91666.667 | F16: =SUM(F14:F15) -> 91666.667 | G16: =SUM(G14:G15) -> 91666.667 | H16: =SUM(H14:H15) -> 91666.667 | I16: =SUM(I14:I15) -> 91666.667 | J16: =SUM(J14:J15) -> 91666.667 | ... ED16: =SUM(ED14:ED15) -> 448776.25
A17: Vacancy / Turnover | C17: =IF(AND(C$10>='Torrance Inputs'!$I$18,C$10<='Torrance Inputs'!$R$18),0,IF(C$10>='Torrance Inputs'!$N$38,0,-C$16)) -> 0 | D17: =IF(AND(D$10>='Torrance Inputs'!$I$18,D$10<='Torrance Inputs'!$R$18),0,IF(D$10>='Torrance Inputs'!$N$38,0,-D$16)) -> 0 | E17: =IF(AND(E$10>='Torrance Inputs'!$I$18,E$10<='Torrance Inputs'!$R$18),0,IF(E$10>='Torrance Inputs'!$N$38,0,-E$16)) -> 0 | F17: =IF(AND(F$10>='Torrance Inputs'!$I$18,F$10<='Torrance Inputs'!$R$18),0,IF(F$10>='Torrance Inputs'!$N$38,0,-F$16)) -> 0 | G17: =IF(AND(G$10>='Torrance Inputs'!$I$18,G$10<='Torrance Inputs'!$R$18),0,IF(G$10>='Torrance Inputs'!$N$38,0,-G$16)) -> 0 | H17: =IF(AND(H$10>='Torrance Inputs'!$I$18,H$10<='Torrance Inputs'!$R$18),0,IF(H$10>='Torrance Inputs'!$N$38,0,-H$16)) -> 0 | I17: =IF(AND(I$10>='Torrance Inputs'!$I$18,I$10<='Torrance Inputs'!$R$18),0,IF(I$10>='Torrance Inputs'!$N$38,0,-I$16)) -> 0 | J17: =IF(AND(J$10>='Torrance Inputs'!$I$18,J$10<='Torrance Inputs'!$R$18),0,IF(J$10>='Torrance Inputs'!$N$38,0,-J$16)) -> 0 | ... ED17: =IF(AND(ED$10>='Torrance Inputs'!$I$18,ED$10<='Torrance Inputs'!$R$18),0,IF(ED$10>='Torrance Inputs'!$N$38,0,-ED$16)) -> 0
A18: Security Deposit | C18: =IF('Torrance Pro Forma'!C$9='Torrance Inputs'!$G$18,'Torrance Inputs'!$C$39,0) -> 0 | D18: =IF('Torrance Pro Forma'!D$9='Torrance Inputs'!$G$18,'Torrance Inputs'!$C$39,0) -> 0 | E18: =IF('Torrance Pro Forma'!E$9='Torrance Inputs'!$G$18,'Torrance Inputs'!$C$39,0) -> 0 | F18: =IF('Torrance Pro Forma'!F$9='Torrance Inputs'!$G$18,'Torrance Inputs'!$C$39,0) -> 0 | G18: =IF('Torrance Pro Forma'!G$9='Torrance Inputs'!$G$18,'Torrance Inputs'!$C$39,0) -> 0 | H18: =IF('Torrance Pro Forma'!H$9='Torrance Inputs'!$G$18,'Torrance Inputs'!$C$39,0) -> 0 | I18: =IF('Torrance Pro Forma'!I$9='Torrance Inputs'!$G$18,'Torrance Inputs'!$C$39,0) -> 0 | J18: =IF('Torrance Pro Forma'!J$9='Torrance Inputs'!$G$18,'Torrance Inputs'!$C$39,0) -> 0 | ... ED18: =IF('Torrance Pro Forma'!ED$9='Torrance Inputs'!$G$18,'Torrance Inputs'!$C$39,0) -> 0
A19: Free Rent / Concessions | C19: =-IF(AND(C$10>='Torrance Inputs'!$I$18,C$10<'Torrance Inputs'!$R$18),('Torrance Inputs'!$D$37*'Torrance Inputs'!$H$22)/DATEDIF('Torrance Inputs'!$I$18,'Torrance Inputs'!$R$18,"m"),0) -> 0 | D19: =-IF(AND(D$10>='Torrance Inputs'!$I$18,D$10<'Torrance Inputs'!$R$18),('Torrance Inputs'!$D$37*'Torrance Inputs'!$H$22)/DATEDIF('Torrance Inputs'!$I$18,'Torrance Inputs'!$R$18,"m"),0) -> 0 | E19: =-IF(AND(E$10>='Torrance Inputs'!$I$18,E$10<'Torrance Inputs'!$R$18),('Torrance Inputs'!$D$37*'Torrance Inputs'!$H$22)/DATEDIF('Torrance Inputs'!$I$18,'Torrance Inputs'!$R$18,"m"),0) -> 0 | F19: =-IF(AND(F$10>='Torrance Inputs'!$I$18,F$10<'Torrance Inputs'!$R$18),('Torrance Inputs'!$D$37*'Torrance Inputs'!$H$22)/DATEDIF('Torrance Inputs'!$I$18,'Torrance Inputs'!$R$18,"m"),0) -> 0 | G19: =-IF(AND(G$10>='Torrance Inputs'!$I$18,G$10<'Torrance Inputs'!$R$18),('Torrance Inputs'!$D$37*'Torrance Inputs'!$H$22)/DATEDIF('Torrance Inputs'!$I$18,'Torrance Inputs'!$R$18,"m"),0) -> 0 | H19: =-IF(AND(H$10>='Torrance Inputs'!$I$18,H$10<'Torrance Inputs'!$R$18),('Torrance Inputs'!$D$37*'Torrance Inputs'!$H$22)/DATEDIF('Torrance Inputs'!$I$18,'Torrance Inputs'!$R$18,"m"),0) -> 0 | I19: =-IF(AND(I$10>='Torrance Inputs'!$I$18,I$10<'Torrance Inputs'!$R$18),('Torrance Inputs'!$D$37*'Torrance Inputs'!$H$22)/DATEDIF('Torrance Inputs'!$I$18,'Torrance Inputs'!$R$18,"m"),0) -> 0 | J19: =-IF(AND(J$10>='Torrance Inputs'!$I$18,J$10<'Torrance Inputs'!$R$18),('Torrance Inputs'!$D$37*'Torrance Inputs'!$H$22)/DATEDIF('Torrance Inputs'!$I$18,'Torrance Inputs'!$R$18,"m"),0) -> 0 | ... ED19: =-IF(AND(ED$10>='Torrance Inputs'!$I$18,ED$10<'Torrance Inputs'!$R$18),('Torrance Inputs'!$D$37*'Torrance Inputs'!$H$22)/DATEDIF('Torrance Inputs'!$I$18,'Torrance Inputs'!$R$18,"m"),0) -> -4801.2104
A20: Total Base Rent | C20: =SUM(C16:C19) -> 91666.667 | D20: =SUM(D16:D19) -> 91666.667 | E20: =SUM(E16:E19) -> 91666.667 | F20: =SUM(F16:F19) -> 91666.667 | G20: =SUM(G16:G19) -> 91666.667 | H20: =SUM(H16:H19) -> 91666.667 | I20: =SUM(I16:I19) -> 91666.667 | J20: =SUM(J16:J19) -> 91666.667 | ... ED20: =SUM(ED16:ED19) -> 443975.04
A21: Total Rental Revenue | C21: =C20 -> 91666.667 | D21: =D20 -> 91666.667 | E21: =E20 -> 91666.667 | F21: =F20 -> 91666.667 | G21: =G20 -> 91666.667 | H21: =H20 -> 91666.667 | I21: =I20 -> 91666.667 | J21: =J20 -> 91666.667 | ... ED21: =ED20 -> 443975.04
A23: Other Tenant Revenue
A24: Utilities | C24: =IF(AND(C$10>='Torrance Inputs'!$N$38,C$10<'Torrance Inputs'!$N$40),'Torrance Inputs'!$Q3*'Torrance Pro Forma'!$C46,IF(C$10>='Torrance Inputs'!$I$18,'Torrance Inputs'!$M$3*'Torrance Pro Forma'!$C46,0)) -> 1250 | D24: =IF(AND(D$10>='Torrance Inputs'!$N$38,D$10<'Torrance Inputs'!$N$40),'Torrance Inputs'!$Q3*'Torrance Pro Forma'!$C46,IF(D$10>='Torrance Inputs'!$I$18,'Torrance Inputs'!$M$3*'Torrance Pro Forma'!$C46,0)) -> 1250 | E24: =IF(AND(E$10>='Torrance Inputs'!$N$38,E$10<'Torrance Inputs'!$N$40),'Torrance Inputs'!$Q3*'Torrance Pro Forma'!$C46,IF(E$10>='Torrance Inputs'!$I$18,'Torrance Inputs'!$M$3*'Torrance Pro Forma'!$C46,0)) -> 1250 | F24: =IF(AND(F$10>='Torrance Inputs'!$N$38,F$10<'Torrance Inputs'!$N$40),'Torrance Inputs'!$Q3*'Torrance Pro Forma'!$C46,IF(F$10>='Torrance Inputs'!$I$18,'Torrance Inputs'!$M$3*'Torrance Pro Forma'!$C46,0)) -> 1250 | G24: =IF(AND(G$10>='Torrance Inputs'!$N$38,G$10<'Torrance Inputs'!$N$40),'Torrance Inputs'!$Q3*'Torrance Pro Forma'!$C46,IF(G$10>='Torrance Inputs'!$I$18,'Torrance Inputs'!$M$3*'Torrance Pro Forma'!$C46,0)) -> 1250 | H24: =IF(AND(H$10>='Torrance Inputs'!$N$38,H$10<'Torrance Inputs'!$N$40),'Torrance Inputs'!$Q3*'Torrance Pro Forma'!$C46,IF(H$10>='Torrance Inputs'!$I$18,'Torrance Inputs'!$M$3*'Torrance Pro Forma'!$C46,0)) -> 1250 | I24: =IF(AND(I$10>='Torrance Inputs'!$N$38,I$10<'Torrance Inputs'!$N$40),'Torrance Inputs'!$Q3*'Torrance Pro Forma'!$C46,IF(I$10>='Torrance Inputs'!$I$18,'Torrance Inputs'!$M$3*'Torrance Pro Forma'!$C46,0)) -> 1250 | J24: =IF(AND(J$10>='Torrance Inputs'!$N$38,J$10<'Torrance Inputs'!$N$40),'Torrance Inputs'!$Q3*'Torrance Pro Forma'!$C46,IF(J$10>='Torrance Inputs'!$I$18,'Torrance Inputs'!$M$3*'Torrance Pro Forma'!$C46,0)) -> 1250 | ... ED24: =IF(AND(ED$10>='Torrance Inputs'!$N$38,ED$10<'Torrance Inputs'!$N$40),'Torrance Inputs'!$Q3*'Torrance Pro Forma'!$C46,IF(ED$10>='Torrance Inputs'!$I$18,'Torrance Inputs'!$M$3*'Torrance Pro Forma'!$C46,0)) -> 1250
A25: Repairs & Maintenance | C25: =IF(AND(C$10>='Torrance Inputs'!$N$38,C$10<'Torrance Inputs'!$N$40),'Torrance Inputs'!$Q4*'Torrance Pro Forma'!C$47,IF(C$10>='Torrance Inputs'!$I$18,'Torrance Inputs'!$M$3*'Torrance Pro Forma'!C$47,0)) -> 1250 | D25: =IF(AND(D$10>='Torrance Inputs'!$N$38,D$10<'Torrance Inputs'!$N$40),'Torrance Inputs'!$Q4*'Torrance Pro Forma'!D$47,IF(D$10>='Torrance Inputs'!$I$18,'Torrance Inputs'!$M$3*'Torrance Pro Forma'!D$47,0)) -> 1250 | E25: =IF(AND(E$10>='Torrance Inputs'!$N$38,E$10<'Torrance Inputs'!$N$40),'Torrance Inputs'!$Q4*'Torrance Pro Forma'!E$47,IF(E$10>='Torrance Inputs'!$I$18,'Torrance Inputs'!$M$3*'Torrance Pro Forma'!E$47,0)) -> 1250 | F25: =IF(AND(F$10>='Torrance Inputs'!$N$38,F$10<'Torrance Inputs'!$N$40),'Torrance Inputs'!$Q4*'Torrance Pro Forma'!F$47,IF(F$10>='Torrance Inputs'!$I$18,'Torrance Inputs'!$M$3*'Torrance Pro Forma'!F$47,0)) -> 1250 | G25: =IF(AND(G$10>='Torrance Inputs'!$N$38,G$10<'Torrance Inputs'!$N$40),'Torrance Inputs'!$Q4*'Torrance Pro Forma'!G$47,IF(G$10>='Torrance Inputs'!$I$18,'Torrance Inputs'!$M$3*'Torrance Pro Forma'!G$47,0)) -> 1250 | H25: =IF(AND(H$10>='Torrance Inputs'!$N$38,H$10<'Torrance Inputs'!$N$40),'Torrance Inputs'!$Q4*'Torrance Pro Forma'!H$47,IF(H$10>='Torrance Inputs'!$I$18,'Torrance Inputs'!$M$3*'Torrance Pro Forma'!H$47,0)) -> 1250 | I25: =IF(AND(I$10>='Torrance Inputs'!$N$38,I$10<'Torrance Inputs'!$N$40),'Torrance Inputs'!$Q4*'Torrance Pro Forma'!I$47,IF(I$10>='Torrance Inputs'!$I$18,'Torrance Inputs'!$M$3*'Torrance Pro Forma'!I$47,0)) -> 1250 | J25: =IF(AND(J$10>='Torrance Inputs'!$N$38,J$10<'Torrance Inputs'!$N$40),'Torrance Inputs'!$Q4*'Torrance Pro Forma'!J$47,IF(J$10>='Torrance Inputs'!$I$18,'Torrance Inputs'!$M$3*'Torrance Pro Forma'!J$47,0)) -> 1250 | ... ED25: =IF(AND(ED$10>='Torrance Inputs'!$N$38,ED$10<'Torrance Inputs'!$N$40),'Torrance Inputs'!$Q4*'Torrance Pro Forma'!ED$47,IF(ED$10>='Torrance Inputs'!$I$18,'Torrance Inputs'!$M$3*'Torrance Pro Forma'!ED$47,0)) -> 1679.8955
A26: Insurance | C26: =IF(AND(C$10>='Torrance Inputs'!$N$38,C$10<'Torrance Inputs'!$N$40),'Torrance Inputs'!$Q5*'Torrance Pro Forma'!C$48,IF(C$10>='Torrance Inputs'!$I$18,'Torrance Inputs'!$M$3*'Torrance Pro Forma'!C$48,0)) -> 416.66667 | D26: =IF(AND(D$10>='Torrance Inputs'!$N$38,D$10<'Torrance Inputs'!$N$40),'Torrance Inputs'!$Q5*'Torrance Pro Forma'!D$48,IF(D$10>='Torrance Inputs'!$I$18,'Torrance Inputs'!$M$3*'Torrance Pro Forma'!D$48,0)) -> 416.66667 | E26: =IF(AND(E$10>='Torrance Inputs'!$N$38,E$10<'Torrance Inputs'!$N$40),'Torrance Inputs'!$Q5*'Torrance Pro Forma'!E$48,IF(E$10>='Torrance Inputs'!$I$18,'Torrance Inputs'!$M$3*'Torrance Pro Forma'!E$48,0)) -> 416.66667 | F26: =IF(AND(F$10>='Torrance Inputs'!$N$38,F$10<'Torrance Inputs'!$N$40),'Torrance Inputs'!$Q5*'Torrance Pro Forma'!F$48,IF(F$10>='Torrance Inputs'!$I$18,'Torrance Inputs'!$M$3*'Torrance Pro Forma'!F$48,0)) -> 416.66667 | G26: =IF(AND(G$10>='Torrance Inputs'!$N$38,G$10<'Torrance Inputs'!$N$40),'Torrance Inputs'!$Q5*'Torrance Pro Forma'!G$48,IF(G$10>='Torrance Inputs'!$I$18,'Torrance Inputs'!$M$3*'Torrance Pro Forma'!G$48,0)) -> 416.66667 | H26: =IF(AND(H$10>='Torrance Inputs'!$N$38,H$10<'Torrance Inputs'!$N$40),'Torrance Inputs'!$Q5*'Torrance Pro Forma'!H$48,IF(H$10>='Torrance Inputs'!$I$18,'Torrance Inputs'!$M$3*'Torrance Pro Forma'!H$48,0)) -> 416.66667 | I26: =IF(AND(I$10>='Torrance Inputs'!$N$38,I$10<'Torrance Inputs'!$N$40),'Torrance Inputs'!$Q5*'Torrance Pro Forma'!I$48,IF(I$10>='Torrance Inputs'!$I$18,'Torrance Inputs'!$M$3*'Torrance Pro Forma'!I$48,0)) -> 416.66667 | J26: =IF(AND(J$10>='Torrance Inputs'!$N$38,J$10<'Torrance Inputs'!$N$40),'Torrance Inputs'!$Q5*'Torrance Pro Forma'!J$48,IF(J$10>='Torrance Inputs'!$I$18,'Torrance Inputs'!$M$3*'Torrance Pro Forma'!J$48,0)) -> 416.66667 | ... ED26: =IF(AND(ED$10>='Torrance Inputs'!$N$38,ED$10<'Torrance Inputs'!$N$40),'Torrance Inputs'!$Q5*'Torrance Pro Forma'!ED$48,IF(ED$10>='Torrance Inputs'!$I$18,'Torrance Inputs'!$M$3*'Torrance Pro Forma'!ED$48,0)) -> 559.96516
A27: Property Taxes | C27: =IF(AND(C$10>='Torrance Inputs'!$N$38,C$10<'Torrance Inputs'!$N$40),'Torrance Inputs'!$Q6*'Torrance Pro Forma'!C$49,IF(C$10>='Torrance Inputs'!$I$18,'Torrance Inputs'!$M$3*'Torrance Pro Forma'!C$49,0)) -> 0 | D27: =IF(AND(D$10>='Torrance Inputs'!$N$38,D$10<'Torrance Inputs'!$N$40),'Torrance Inputs'!$Q6*'Torrance Pro Forma'!D$49,IF(D$10>='Torrance Inputs'!$I$18,'Torrance Inputs'!$M$3*'Torrance Pro Forma'!D$49,0)) -> 0 | E27: =IF(AND(E$10>='Torrance Inputs'!$N$38,E$10<'Torrance Inputs'!$N$40),'Torrance Inputs'!$Q6*'Torrance Pro Forma'!E$49,IF(E$10>='Torrance Inputs'!$I$18,'Torrance Inputs'!$M$3*'Torrance Pro Forma'!E$49,0)) -> 0 | F27: =IF(AND(F$10>='Torrance Inputs'!$N$38,F$10<'Torrance Inputs'!$N$40),'Torrance Inputs'!$Q6*'Torrance Pro Forma'!F$49,IF(F$10>='Torrance Inputs'!$I$18,'Torrance Inputs'!$M$3*'Torrance Pro Forma'!F$49,0)) -> 0 | G27: =IF(AND(G$10>='Torrance Inputs'!$N$38,G$10<'Torrance Inputs'!$N$40),'Torrance Inputs'!$Q6*'Torrance Pro Forma'!G$49,IF(G$10>='Torrance Inputs'!$I$18,'Torrance Inputs'!$M$3*'Torrance Pro Forma'!G$49,0)) -> 0 | H27: =IF(AND(H$10>='Torrance Inputs'!$N$38,H$10<'Torrance Inputs'!$N$40),'Torrance Inputs'!$Q6*'Torrance Pro Forma'!H$49,IF(H$10>='Torrance Inputs'!$I$18,'Torrance Inputs'!$M$3*'Torrance Pro Forma'!H$49,0)) -> 0 | I27: =IF(AND(I$10>='Torrance Inputs'!$N$38,I$10<'Torrance Inputs'!$N$40),'Torrance Inputs'!$Q6*'Torrance Pro Forma'!I$49,IF(I$10>='Torrance Inputs'!$I$18,'Torrance Inputs'!$M$3*'Torrance Pro Forma'!I$49,0)) -> 0 | J27: =IF(AND(J$10>='Torrance Inputs'!$N$38,J$10<'Torrance Inputs'!$N$40),'Torrance Inputs'!$Q6*'Torrance Pro Forma'!J$49,IF(J$10>='Torrance Inputs'!$I$18,'Torrance Inputs'!$M$3*'Torrance Pro Forma'!J$49,0)) -> 0 | ... ED27: =IF(AND(ED$10>='Torrance Inputs'!$N$38,ED$10<'Torrance Inputs'!$N$40),'Torrance Inputs'!$Q6*'Torrance Pro Forma'!ED$49,IF(ED$10>='Torrance Inputs'!$I$18,'Torrance Inputs'!$M$3*'Torrance Pro Forma'!ED$49,0)) -> 19613.552
A28: Total Expense Recoveries | C28: =SUM(C24:C27) -> 2916.6667 | D28: =SUM(D24:D27) -> 2916.6667 | E28: =SUM(E24:E27) -> 2916.6667 | F28: =SUM(F24:F27) -> 2916.6667 | G28: =SUM(G24:G27) -> 2916.6667 | H28: =SUM(H24:H27) -> 2916.6667 | I28: =SUM(I24:I27) -> 2916.6667 | J28: =SUM(J24:J27) -> 2916.6667 | ... ED28: =SUM(ED24:ED27) -> 23103.413
A29: Total Other Tenant Revenue | C29: =SUM(C28) -> 2916.6667 | D29: =SUM(D28) -> 2916.6667 | E29: =SUM(E28) -> 2916.6667 | F29: =SUM(F28) -> 2916.6667 | G29: =SUM(G28) -> 2916.6667 | H29: =SUM(H28) -> 2916.6667 | I29: =SUM(I28) -> 2916.6667 | J29: =SUM(J28) -> 2916.6667 | ... ED29: =SUM(ED28) -> 23103.413
A31: Total Tenant Revenue | C31: =C21+C29 -> 94583.333 | D31: =D21+D29 -> 94583.333 | E31: =E21+E29 -> 94583.333 | F31: =F21+F29 -> 94583.333 | G31: =G21+G29 -> 94583.333 | H31: =H21+H29 -> 94583.333 | I31: =I21+I29 -> 94583.333 | J31: =J21+J29 -> 94583.333 | ... ED31: =ED21+ED29 -> 467078.45
A33: Other Income
A34: Parking Income | C34: =IF(AND(C$14=0,C$15=0),0,'Torrance Inputs'!$R$24*(1+'Torrance Inputs'!$T$22)^('Torrance Pro Forma'!C$8-1)) -> 15895 | D34: =IF(AND(D$14=0,D$15=0),0,'Torrance Inputs'!$R$24*(1+'Torrance Inputs'!$T$22)^('Torrance Pro Forma'!D$8-1)) -> 15895 | E34: =IF(AND(E$14=0,E$15=0),0,'Torrance Inputs'!$R$24*(1+'Torrance Inputs'!$T$22)^('Torrance Pro Forma'!E$8-1)) -> 15895 | F34: =IF(AND(F$14=0,F$15=0),0,'Torrance Inputs'!$R$24*(1+'Torrance Inputs'!$T$22)^('Torrance Pro Forma'!F$8-1)) -> 15895 | G34: =IF(AND(G$14=0,G$15=0),0,'Torrance Inputs'!$R$24*(1+'Torrance Inputs'!$T$22)^('Torrance Pro Forma'!G$8-1)) -> 15895 | H34: =IF(AND(H$14=0,H$15=0),0,'Torrance Inputs'!$R$24*(1+'Torrance Inputs'!$T$22)^('Torrance Pro Forma'!H$8-1)) -> 15895 | I34: =IF(AND(I$14=0,I$15=0),0,'Torrance Inputs'!$R$24*(1+'Torrance Inputs'!$T$22)^('Torrance Pro Forma'!I$8-1)) -> 15895 | J34: =IF(AND(J$14=0,J$15=0),0,'Torrance Inputs'!$R$24*(1+'Torrance Inputs'!$T$22)^('Torrance Pro Forma'!J$8-1)) -> 15895 | ... ED34: =IF(AND(ED$14=0,ED$15=0),0,'Torrance Inputs'!$R$24*(1+'Torrance Inputs'!$T$22)^('Torrance Pro Forma'!ED$8-1)) -> 19375.916
A35: Total Other Income | C35: =C34 -> 15895 | D35: =D34 -> 15895 | E35: =E34 -> 15895 | F35: =F34 -> 15895 | G35: =G34 -> 15895 | H35: =H34 -> 15895 | I35: =I34 -> 15895 | J35: =J34 -> 15895 | ... ED35: =ED34 -> 19375.916
A37: Potential Gross Revenue | C37: =C35+C31 -> 110478.33 | D37: =D35+D31 -> 110478.33 | E37: =E35+E31 -> 110478.33 | F37: =F35+F31 -> 110478.33 | G37: =G35+G31 -> 110478.33 | H37: =H35+H31 -> 110478.33 | I37: =I35+I31 -> 110478.33 | J37: =J35+J31 -> 110478.33 | ... ED37: =ED35+ED31 -> 486454.36
A39: General Vacancy & Credit Loss
A40: Vacancy & L2L
A41: Total Vacancy & Credit Loss | C41: =C40 -> 0 | D41: =D40 -> 0 | E41: =E40 -> 0 | F41: =F40 -> 0 | G41: =G40 -> 0 | H41: =H40 -> 0 | I41: =I40 -> 0 | J41: =J40 -> 0 | ... ED41: =ED40 -> 0
A43: Effective Gross Revenue | C43: =C37+C41 -> 110478.33 | D43: =D37+D41 -> 110478.33 | E43: =E37+E41 -> 110478.33 | F43: =F37+F41 -> 110478.33 | G43: =G37+G41 -> 110478.33 | H43: =H37+H41 -> 110478.33 | I43: =I37+I41 -> 110478.33 | J43: =J37+J41 -> 110478.33 | ... ED43: =ED37+ED41 -> 486454.36
A45: Operating Expenses
